[2025-10-05T00:00:28.697+0000] {processor.py:186} INFO - Started process (PID=1122) to work on /opt/airflow/dags/device_config_dag.py
[2025-10-05T00:00:28.701+0000] {processor.py:914} INFO - Processing file /opt/airflow/dags/device_config_dag.py for tasks to queue
[2025-10-05T00:00:28.707+0000] {logging_mixin.py:190} INFO - [2025-10-05T00:00:28.706+0000] {dagbag.py:588} INFO - Filling up the DagBag from /opt/airflow/dags/device_config_dag.py
[2025-10-05T00:00:30.036+0000] {logging_mixin.py:190} INFO - [2025-10-05T00:00:29.968+0000] {dagbag.py:387} ERROR - Failed to import: /opt/airflow/dags/device_config_dag.py
Traceback (most recent call last):
  File "/home/airflow/.local/lib/python3.12/site-packages/airflow/models/dagbag.py", line 383, in parse
    loader.exec_module(new_module)
  File "<frozen importlib._bootstrap_external>", line 999, in exec_module
  File "<frozen importlib._bootstrap>", line 488, in _call_with_frames_removed
  File "/opt/airflow/dags/device_config_dag.py", line 7, in <module>
    from dags.tasks.load import IcebergStorage
  File "/opt/airflow/dags/tasks/load.py", line 7, in <module>
    from dags.tasks.config.settings import ICEBERG_STORAGE, BYTES_SIZE, TARGET_FILE_SIZE_MB
ImportError: cannot import name 'ICEBERG_STORAGE' from 'dags.tasks.config.settings' (/opt/airflow/dags/tasks/config/settings.py)
[2025-10-05T00:00:30.042+0000] {processor.py:927} WARNING - No viable dags retrieved from /opt/airflow/dags/device_config_dag.py
[2025-10-05T00:00:30.201+0000] {processor.py:208} INFO - Processing /opt/airflow/dags/device_config_dag.py took 1.529 seconds
[2025-10-05T00:01:01.022+0000] {processor.py:186} INFO - Started process (PID=1149) to work on /opt/airflow/dags/device_config_dag.py
[2025-10-05T00:01:01.026+0000] {processor.py:914} INFO - Processing file /opt/airflow/dags/device_config_dag.py for tasks to queue
[2025-10-05T00:01:01.031+0000] {logging_mixin.py:190} INFO - [2025-10-05T00:01:01.030+0000] {dagbag.py:588} INFO - Filling up the DagBag from /opt/airflow/dags/device_config_dag.py
[2025-10-05T00:01:03.150+0000] {logging_mixin.py:190} INFO - [2025-10-05T00:01:03.079+0000] {dagbag.py:387} ERROR - Failed to import: /opt/airflow/dags/device_config_dag.py
Traceback (most recent call last):
  File "/home/airflow/.local/lib/python3.12/site-packages/airflow/models/dagbag.py", line 383, in parse
    loader.exec_module(new_module)
  File "<frozen importlib._bootstrap_external>", line 999, in exec_module
  File "<frozen importlib._bootstrap>", line 488, in _call_with_frames_removed
  File "/opt/airflow/dags/device_config_dag.py", line 7, in <module>
    from dags.tasks.load import IcebergStorage
  File "/opt/airflow/dags/tasks/load.py", line 7, in <module>
    from dags.tasks.config.settings import ICEBERG_STORAGE, BYTES_SIZE, TARGET_FILE_SIZE_MB
ImportError: cannot import name 'ICEBERG_STORAGE' from 'dags.tasks.config.settings' (/opt/airflow/dags/tasks/config/settings.py)
[2025-10-05T00:01:03.161+0000] {processor.py:927} WARNING - No viable dags retrieved from /opt/airflow/dags/device_config_dag.py
[2025-10-05T00:01:03.591+0000] {processor.py:208} INFO - Processing /opt/airflow/dags/device_config_dag.py took 2.604 seconds
[2025-10-05T00:01:34.059+0000] {processor.py:186} INFO - Started process (PID=1176) to work on /opt/airflow/dags/device_config_dag.py
[2025-10-05T00:01:34.062+0000] {processor.py:914} INFO - Processing file /opt/airflow/dags/device_config_dag.py for tasks to queue
[2025-10-05T00:01:34.066+0000] {logging_mixin.py:190} INFO - [2025-10-05T00:01:34.065+0000] {dagbag.py:588} INFO - Filling up the DagBag from /opt/airflow/dags/device_config_dag.py
[2025-10-05T00:01:35.229+0000] {logging_mixin.py:190} INFO - [2025-10-05T00:01:35.208+0000] {dagbag.py:387} ERROR - Failed to import: /opt/airflow/dags/device_config_dag.py
Traceback (most recent call last):
  File "/home/airflow/.local/lib/python3.12/site-packages/airflow/models/dagbag.py", line 383, in parse
    loader.exec_module(new_module)
  File "<frozen importlib._bootstrap_external>", line 999, in exec_module
  File "<frozen importlib._bootstrap>", line 488, in _call_with_frames_removed
  File "/opt/airflow/dags/device_config_dag.py", line 7, in <module>
    from dags.tasks.load import IcebergStorage
  File "/opt/airflow/dags/tasks/load.py", line 7, in <module>
    from dags.tasks.config.settings import ICEBERG_STORAGE, BYTES_SIZE, TARGET_FILE_SIZE_MB
ImportError: cannot import name 'ICEBERG_STORAGE' from 'dags.tasks.config.settings' (/opt/airflow/dags/tasks/config/settings.py)
[2025-10-05T00:01:35.234+0000] {processor.py:927} WARNING - No viable dags retrieved from /opt/airflow/dags/device_config_dag.py
[2025-10-05T00:01:35.283+0000] {processor.py:208} INFO - Processing /opt/airflow/dags/device_config_dag.py took 1.242 seconds
[2025-10-05T00:02:05.418+0000] {processor.py:186} INFO - Started process (PID=1203) to work on /opt/airflow/dags/device_config_dag.py
[2025-10-05T00:02:05.421+0000] {processor.py:914} INFO - Processing file /opt/airflow/dags/device_config_dag.py for tasks to queue
[2025-10-05T00:02:05.425+0000] {logging_mixin.py:190} INFO - [2025-10-05T00:02:05.424+0000] {dagbag.py:588} INFO - Filling up the DagBag from /opt/airflow/dags/device_config_dag.py
[2025-10-05T00:02:06.587+0000] {logging_mixin.py:190} INFO - [2025-10-05T00:02:06.565+0000] {dagbag.py:387} ERROR - Failed to import: /opt/airflow/dags/device_config_dag.py
Traceback (most recent call last):
  File "/home/airflow/.local/lib/python3.12/site-packages/airflow/models/dagbag.py", line 383, in parse
    loader.exec_module(new_module)
  File "<frozen importlib._bootstrap_external>", line 999, in exec_module
  File "<frozen importlib._bootstrap>", line 488, in _call_with_frames_removed
  File "/opt/airflow/dags/device_config_dag.py", line 7, in <module>
    from dags.tasks.load import IcebergStorage
  File "/opt/airflow/dags/tasks/load.py", line 7, in <module>
    from dags.tasks.config.settings import ICEBERG_STORAGE, BYTES_SIZE, TARGET_FILE_SIZE_MB
ImportError: cannot import name 'ICEBERG_STORAGE' from 'dags.tasks.config.settings' (/opt/airflow/dags/tasks/config/settings.py)
[2025-10-05T00:02:06.593+0000] {processor.py:927} WARNING - No viable dags retrieved from /opt/airflow/dags/device_config_dag.py
[2025-10-05T00:02:06.652+0000] {processor.py:208} INFO - Processing /opt/airflow/dags/device_config_dag.py took 1.251 seconds
[2025-10-05T00:02:37.348+0000] {processor.py:186} INFO - Started process (PID=1230) to work on /opt/airflow/dags/device_config_dag.py
[2025-10-05T00:02:37.351+0000] {processor.py:914} INFO - Processing file /opt/airflow/dags/device_config_dag.py for tasks to queue
[2025-10-05T00:02:37.354+0000] {logging_mixin.py:190} INFO - [2025-10-05T00:02:37.353+0000] {dagbag.py:588} INFO - Filling up the DagBag from /opt/airflow/dags/device_config_dag.py
[2025-10-05T00:02:38.403+0000] {logging_mixin.py:190} INFO - [2025-10-05T00:02:38.385+0000] {dagbag.py:387} ERROR - Failed to import: /opt/airflow/dags/device_config_dag.py
Traceback (most recent call last):
  File "/home/airflow/.local/lib/python3.12/site-packages/airflow/models/dagbag.py", line 383, in parse
    loader.exec_module(new_module)
  File "<frozen importlib._bootstrap_external>", line 999, in exec_module
  File "<frozen importlib._bootstrap>", line 488, in _call_with_frames_removed
  File "/opt/airflow/dags/device_config_dag.py", line 7, in <module>
    from dags.tasks.load import IcebergStorage
  File "/opt/airflow/dags/tasks/load.py", line 7, in <module>
    from dags.tasks.config.settings import ICEBERG_STORAGE, BYTES_SIZE, TARGET_FILE_SIZE_MB
ImportError: cannot import name 'ICEBERG_STORAGE' from 'dags.tasks.config.settings' (/opt/airflow/dags/tasks/config/settings.py)
[2025-10-05T00:02:38.408+0000] {processor.py:927} WARNING - No viable dags retrieved from /opt/airflow/dags/device_config_dag.py
[2025-10-05T00:02:38.446+0000] {processor.py:208} INFO - Processing /opt/airflow/dags/device_config_dag.py took 1.115 seconds
[2025-10-05T00:03:08.720+0000] {processor.py:186} INFO - Started process (PID=1257) to work on /opt/airflow/dags/device_config_dag.py
[2025-10-05T00:03:08.722+0000] {processor.py:914} INFO - Processing file /opt/airflow/dags/device_config_dag.py for tasks to queue
[2025-10-05T00:03:08.726+0000] {logging_mixin.py:190} INFO - [2025-10-05T00:03:08.725+0000] {dagbag.py:588} INFO - Filling up the DagBag from /opt/airflow/dags/device_config_dag.py
[2025-10-05T00:03:07.896+0000] {logging_mixin.py:190} INFO - [2025-10-05T00:03:09.073+0000] {dagbag.py:387} ERROR - Failed to import: /opt/airflow/dags/device_config_dag.py
Traceback (most recent call last):
  File "/home/airflow/.local/lib/python3.12/site-packages/airflow/models/dagbag.py", line 383, in parse
    loader.exec_module(new_module)
  File "<frozen importlib._bootstrap_external>", line 999, in exec_module
  File "<frozen importlib._bootstrap>", line 488, in _call_with_frames_removed
  File "/opt/airflow/dags/device_config_dag.py", line 7, in <module>
    from dags.tasks.load import IcebergStorage
  File "/opt/airflow/dags/tasks/load.py", line 7, in <module>
    from dags.tasks.config.settings import ICEBERG_STORAGE, BYTES_SIZE, TARGET_FILE_SIZE_MB
ImportError: cannot import name 'ICEBERG_STORAGE' from 'dags.tasks.config.settings' (/opt/airflow/dags/tasks/config/settings.py)
[2025-10-05T00:03:07.902+0000] {processor.py:927} WARNING - No viable dags retrieved from /opt/airflow/dags/device_config_dag.py
[2025-10-05T00:03:07.943+0000] {processor.py:208} INFO - Processing /opt/airflow/dags/device_config_dag.py took 0.982 seconds
[2025-10-05T00:03:38.175+0000] {processor.py:186} INFO - Started process (PID=1284) to work on /opt/airflow/dags/device_config_dag.py
[2025-10-05T00:03:38.178+0000] {processor.py:914} INFO - Processing file /opt/airflow/dags/device_config_dag.py for tasks to queue
[2025-10-05T00:03:38.181+0000] {logging_mixin.py:190} INFO - [2025-10-05T00:03:38.180+0000] {dagbag.py:588} INFO - Filling up the DagBag from /opt/airflow/dags/device_config_dag.py
[2025-10-05T00:03:39.110+0000] {logging_mixin.py:190} INFO - [2025-10-05T00:03:39.094+0000] {dagbag.py:387} ERROR - Failed to import: /opt/airflow/dags/device_config_dag.py
Traceback (most recent call last):
  File "/home/airflow/.local/lib/python3.12/site-packages/airflow/models/dagbag.py", line 383, in parse
    loader.exec_module(new_module)
  File "<frozen importlib._bootstrap_external>", line 999, in exec_module
  File "<frozen importlib._bootstrap>", line 488, in _call_with_frames_removed
  File "/opt/airflow/dags/device_config_dag.py", line 7, in <module>
    from dags.tasks.load import IcebergStorage
  File "/opt/airflow/dags/tasks/load.py", line 7, in <module>
    from dags.tasks.config.settings import ICEBERG_STORAGE, BYTES_SIZE, TARGET_FILE_SIZE_MB
ImportError: cannot import name 'ICEBERG_STORAGE' from 'dags.tasks.config.settings' (/opt/airflow/dags/tasks/config/settings.py)
[2025-10-05T00:03:39.114+0000] {processor.py:927} WARNING - No viable dags retrieved from /opt/airflow/dags/device_config_dag.py
[2025-10-05T00:03:39.155+0000] {processor.py:208} INFO - Processing /opt/airflow/dags/device_config_dag.py took 0.993 seconds
[2025-10-05T00:04:09.546+0000] {processor.py:186} INFO - Started process (PID=1311) to work on /opt/airflow/dags/device_config_dag.py
[2025-10-05T00:04:09.549+0000] {processor.py:914} INFO - Processing file /opt/airflow/dags/device_config_dag.py for tasks to queue
[2025-10-05T00:04:09.553+0000] {logging_mixin.py:190} INFO - [2025-10-05T00:04:09.551+0000] {dagbag.py:588} INFO - Filling up the DagBag from /opt/airflow/dags/device_config_dag.py
[2025-10-05T00:04:10.604+0000] {logging_mixin.py:190} INFO - [2025-10-05T00:04:10.586+0000] {dagbag.py:387} ERROR - Failed to import: /opt/airflow/dags/device_config_dag.py
Traceback (most recent call last):
  File "/home/airflow/.local/lib/python3.12/site-packages/airflow/models/dagbag.py", line 383, in parse
    loader.exec_module(new_module)
  File "<frozen importlib._bootstrap_external>", line 999, in exec_module
  File "<frozen importlib._bootstrap>", line 488, in _call_with_frames_removed
  File "/opt/airflow/dags/device_config_dag.py", line 7, in <module>
    from dags.tasks.load import IcebergStorage
  File "/opt/airflow/dags/tasks/load.py", line 7, in <module>
    from dags.tasks.config.settings import ICEBERG_STORAGE, BYTES_SIZE, TARGET_FILE_SIZE_MB
ImportError: cannot import name 'ICEBERG_STORAGE' from 'dags.tasks.config.settings' (/opt/airflow/dags/tasks/config/settings.py)
[2025-10-05T00:04:10.609+0000] {processor.py:927} WARNING - No viable dags retrieved from /opt/airflow/dags/device_config_dag.py
[2025-10-05T00:04:10.649+0000] {processor.py:208} INFO - Processing /opt/airflow/dags/device_config_dag.py took 1.119 seconds
[2025-10-05T00:04:40.835+0000] {processor.py:186} INFO - Started process (PID=1338) to work on /opt/airflow/dags/device_config_dag.py
[2025-10-05T00:04:40.838+0000] {processor.py:914} INFO - Processing file /opt/airflow/dags/device_config_dag.py for tasks to queue
[2025-10-05T00:04:40.840+0000] {logging_mixin.py:190} INFO - [2025-10-05T00:04:40.840+0000] {dagbag.py:588} INFO - Filling up the DagBag from /opt/airflow/dags/device_config_dag.py
[2025-10-05T00:04:41.810+0000] {logging_mixin.py:190} INFO - [2025-10-05T00:04:41.792+0000] {dagbag.py:387} ERROR - Failed to import: /opt/airflow/dags/device_config_dag.py
Traceback (most recent call last):
  File "/home/airflow/.local/lib/python3.12/site-packages/airflow/models/dagbag.py", line 383, in parse
    loader.exec_module(new_module)
  File "<frozen importlib._bootstrap_external>", line 999, in exec_module
  File "<frozen importlib._bootstrap>", line 488, in _call_with_frames_removed
  File "/opt/airflow/dags/device_config_dag.py", line 7, in <module>
    from dags.tasks.load import IcebergStorage
  File "/opt/airflow/dags/tasks/load.py", line 7, in <module>
    from dags.tasks.config.settings import ICEBERG_STORAGE, BYTES_SIZE, TARGET_FILE_SIZE_MB
ImportError: cannot import name 'ICEBERG_STORAGE' from 'dags.tasks.config.settings' (/opt/airflow/dags/tasks/config/settings.py)
[2025-10-05T00:04:41.816+0000] {processor.py:927} WARNING - No viable dags retrieved from /opt/airflow/dags/device_config_dag.py
[2025-10-05T00:04:41.859+0000] {processor.py:208} INFO - Processing /opt/airflow/dags/device_config_dag.py took 1.039 seconds
[2025-10-05T00:05:12.691+0000] {processor.py:186} INFO - Started process (PID=1365) to work on /opt/airflow/dags/device_config_dag.py
[2025-10-05T00:05:12.696+0000] {processor.py:914} INFO - Processing file /opt/airflow/dags/device_config_dag.py for tasks to queue
[2025-10-05T00:05:12.700+0000] {logging_mixin.py:190} INFO - [2025-10-05T00:05:12.699+0000] {dagbag.py:588} INFO - Filling up the DagBag from /opt/airflow/dags/device_config_dag.py
[2025-10-05T00:05:13.740+0000] {logging_mixin.py:190} INFO - [2025-10-05T00:05:13.718+0000] {dagbag.py:387} ERROR - Failed to import: /opt/airflow/dags/device_config_dag.py
Traceback (most recent call last):
  File "/home/airflow/.local/lib/python3.12/site-packages/airflow/models/dagbag.py", line 383, in parse
    loader.exec_module(new_module)
  File "<frozen importlib._bootstrap_external>", line 999, in exec_module
  File "<frozen importlib._bootstrap>", line 488, in _call_with_frames_removed
  File "/opt/airflow/dags/device_config_dag.py", line 7, in <module>
    from dags.tasks.load import IcebergStorage
  File "/opt/airflow/dags/tasks/load.py", line 7, in <module>
    from dags.tasks.config.settings import ICEBERG_STORAGE, BYTES_SIZE, TARGET_FILE_SIZE_MB
ImportError: cannot import name 'ICEBERG_STORAGE' from 'dags.tasks.config.settings' (/opt/airflow/dags/tasks/config/settings.py)
[2025-10-05T00:05:13.747+0000] {processor.py:927} WARNING - No viable dags retrieved from /opt/airflow/dags/device_config_dag.py
[2025-10-05T00:05:13.793+0000] {processor.py:208} INFO - Processing /opt/airflow/dags/device_config_dag.py took 1.120 seconds
[2025-10-05T00:05:44.002+0000] {processor.py:186} INFO - Started process (PID=1392) to work on /opt/airflow/dags/device_config_dag.py
[2025-10-05T00:05:44.005+0000] {processor.py:914} INFO - Processing file /opt/airflow/dags/device_config_dag.py for tasks to queue
[2025-10-05T00:05:44.008+0000] {logging_mixin.py:190} INFO - [2025-10-05T00:05:44.008+0000] {dagbag.py:588} INFO - Filling up the DagBag from /opt/airflow/dags/device_config_dag.py
[2025-10-05T00:05:45.041+0000] {logging_mixin.py:190} INFO - [2025-10-05T00:05:44.985+0000] {dagbag.py:387} ERROR - Failed to import: /opt/airflow/dags/device_config_dag.py
Traceback (most recent call last):
  File "/home/airflow/.local/lib/python3.12/site-packages/airflow/models/dagbag.py", line 383, in parse
    loader.exec_module(new_module)
  File "<frozen importlib._bootstrap_external>", line 999, in exec_module
  File "<frozen importlib._bootstrap>", line 488, in _call_with_frames_removed
  File "/opt/airflow/dags/device_config_dag.py", line 7, in <module>
    from dags.tasks.load import IcebergStorage
  File "/opt/airflow/dags/tasks/load.py", line 7, in <module>
    from dags.tasks.config.settings import ICEBERG_STORAGE, BYTES_SIZE, TARGET_FILE_SIZE_MB
ImportError: cannot import name 'ICEBERG_STORAGE' from 'dags.tasks.config.settings' (/opt/airflow/dags/tasks/config/settings.py)
[2025-10-05T00:05:45.047+0000] {processor.py:927} WARNING - No viable dags retrieved from /opt/airflow/dags/device_config_dag.py
[2025-10-05T00:05:45.095+0000] {processor.py:208} INFO - Processing /opt/airflow/dags/device_config_dag.py took 1.109 seconds
[2025-10-05T00:06:15.307+0000] {processor.py:186} INFO - Started process (PID=1419) to work on /opt/airflow/dags/device_config_dag.py
[2025-10-05T00:06:15.309+0000] {processor.py:914} INFO - Processing file /opt/airflow/dags/device_config_dag.py for tasks to queue
[2025-10-05T00:06:15.313+0000] {logging_mixin.py:190} INFO - [2025-10-05T00:06:15.312+0000] {dagbag.py:588} INFO - Filling up the DagBag from /opt/airflow/dags/device_config_dag.py
[2025-10-05T00:06:16.318+0000] {logging_mixin.py:190} INFO - [2025-10-05T00:06:16.300+0000] {dagbag.py:387} ERROR - Failed to import: /opt/airflow/dags/device_config_dag.py
Traceback (most recent call last):
  File "/home/airflow/.local/lib/python3.12/site-packages/airflow/models/dagbag.py", line 383, in parse
    loader.exec_module(new_module)
  File "<frozen importlib._bootstrap_external>", line 999, in exec_module
  File "<frozen importlib._bootstrap>", line 488, in _call_with_frames_removed
  File "/opt/airflow/dags/device_config_dag.py", line 7, in <module>
    from dags.tasks.load import IcebergStorage
  File "/opt/airflow/dags/tasks/load.py", line 7, in <module>
    from dags.tasks.config.settings import ICEBERG_STORAGE, BYTES_SIZE, TARGET_FILE_SIZE_MB
ImportError: cannot import name 'ICEBERG_STORAGE' from 'dags.tasks.config.settings' (/opt/airflow/dags/tasks/config/settings.py)
[2025-10-05T00:06:16.323+0000] {processor.py:927} WARNING - No viable dags retrieved from /opt/airflow/dags/device_config_dag.py
[2025-10-05T00:06:16.395+0000] {processor.py:208} INFO - Processing /opt/airflow/dags/device_config_dag.py took 1.102 seconds
[2025-10-05T00:06:46.597+0000] {processor.py:186} INFO - Started process (PID=1446) to work on /opt/airflow/dags/device_config_dag.py
[2025-10-05T00:06:46.600+0000] {processor.py:914} INFO - Processing file /opt/airflow/dags/device_config_dag.py for tasks to queue
[2025-10-05T00:06:46.606+0000] {logging_mixin.py:190} INFO - [2025-10-05T00:06:46.604+0000] {dagbag.py:588} INFO - Filling up the DagBag from /opt/airflow/dags/device_config_dag.py
[2025-10-05T00:06:47.773+0000] {logging_mixin.py:190} INFO - [2025-10-05T00:06:47.717+0000] {dagbag.py:387} ERROR - Failed to import: /opt/airflow/dags/device_config_dag.py
Traceback (most recent call last):
  File "/home/airflow/.local/lib/python3.12/site-packages/airflow/models/dagbag.py", line 383, in parse
    loader.exec_module(new_module)
  File "<frozen importlib._bootstrap_external>", line 999, in exec_module
  File "<frozen importlib._bootstrap>", line 488, in _call_with_frames_removed
  File "/opt/airflow/dags/device_config_dag.py", line 7, in <module>
    from dags.tasks.load import IcebergStorage
  File "/opt/airflow/dags/tasks/load.py", line 7, in <module>
    from dags.tasks.config.settings import ICEBERG_STORAGE, BYTES_SIZE, TARGET_FILE_SIZE_MB
ImportError: cannot import name 'ICEBERG_STORAGE' from 'dags.tasks.config.settings' (/opt/airflow/dags/tasks/config/settings.py)
[2025-10-05T00:06:47.780+0000] {processor.py:927} WARNING - No viable dags retrieved from /opt/airflow/dags/device_config_dag.py
[2025-10-05T00:06:47.847+0000] {processor.py:208} INFO - Processing /opt/airflow/dags/device_config_dag.py took 1.271 seconds
[2025-10-05T00:07:18.905+0000] {processor.py:186} INFO - Started process (PID=1473) to work on /opt/airflow/dags/device_config_dag.py
[2025-10-05T00:07:18.907+0000] {processor.py:914} INFO - Processing file /opt/airflow/dags/device_config_dag.py for tasks to queue
[2025-10-05T00:07:18.911+0000] {logging_mixin.py:190} INFO - [2025-10-05T00:07:18.910+0000] {dagbag.py:588} INFO - Filling up the DagBag from /opt/airflow/dags/device_config_dag.py
[2025-10-05T00:07:19.864+0000] {logging_mixin.py:190} INFO - [2025-10-05T00:07:19.843+0000] {dagbag.py:387} ERROR - Failed to import: /opt/airflow/dags/device_config_dag.py
Traceback (most recent call last):
  File "/home/airflow/.local/lib/python3.12/site-packages/airflow/models/dagbag.py", line 383, in parse
    loader.exec_module(new_module)
  File "<frozen importlib._bootstrap_external>", line 999, in exec_module
  File "<frozen importlib._bootstrap>", line 488, in _call_with_frames_removed
  File "/opt/airflow/dags/device_config_dag.py", line 7, in <module>
    from dags.tasks.load import IcebergStorage
  File "/opt/airflow/dags/tasks/load.py", line 7, in <module>
    from dags.tasks.config.settings import ICEBERG_STORAGE, BYTES_SIZE, TARGET_FILE_SIZE_MB
ImportError: cannot import name 'ICEBERG_STORAGE' from 'dags.tasks.config.settings' (/opt/airflow/dags/tasks/config/settings.py)
[2025-10-05T00:07:19.885+0000] {processor.py:927} WARNING - No viable dags retrieved from /opt/airflow/dags/device_config_dag.py
[2025-10-05T00:07:19.937+0000] {processor.py:208} INFO - Processing /opt/airflow/dags/device_config_dag.py took 1.049 seconds
[2025-10-05T00:07:50.150+0000] {processor.py:186} INFO - Started process (PID=1500) to work on /opt/airflow/dags/device_config_dag.py
[2025-10-05T00:07:50.153+0000] {processor.py:914} INFO - Processing file /opt/airflow/dags/device_config_dag.py for tasks to queue
[2025-10-05T00:07:50.156+0000] {logging_mixin.py:190} INFO - [2025-10-05T00:07:50.155+0000] {dagbag.py:588} INFO - Filling up the DagBag from /opt/airflow/dags/device_config_dag.py
[2025-10-05T00:07:51.197+0000] {logging_mixin.py:190} INFO - [2025-10-05T00:07:51.180+0000] {dagbag.py:387} ERROR - Failed to import: /opt/airflow/dags/device_config_dag.py
Traceback (most recent call last):
  File "/home/airflow/.local/lib/python3.12/site-packages/airflow/models/dagbag.py", line 383, in parse
    loader.exec_module(new_module)
  File "<frozen importlib._bootstrap_external>", line 999, in exec_module
  File "<frozen importlib._bootstrap>", line 488, in _call_with_frames_removed
  File "/opt/airflow/dags/device_config_dag.py", line 7, in <module>
    from dags.tasks.load import IcebergStorage
  File "/opt/airflow/dags/tasks/load.py", line 7, in <module>
    from dags.tasks.config.settings import ICEBERG_STORAGE, BYTES_SIZE, TARGET_FILE_SIZE_MB
ImportError: cannot import name 'ICEBERG_STORAGE' from 'dags.tasks.config.settings' (/opt/airflow/dags/tasks/config/settings.py)
[2025-10-05T00:07:51.201+0000] {processor.py:927} WARNING - No viable dags retrieved from /opt/airflow/dags/device_config_dag.py
[2025-10-05T00:07:51.242+0000] {processor.py:208} INFO - Processing /opt/airflow/dags/device_config_dag.py took 1.106 seconds
[2025-10-05T00:08:21.785+0000] {processor.py:186} INFO - Started process (PID=1527) to work on /opt/airflow/dags/device_config_dag.py
[2025-10-05T00:08:21.788+0000] {processor.py:914} INFO - Processing file /opt/airflow/dags/device_config_dag.py for tasks to queue
[2025-10-05T00:08:21.792+0000] {logging_mixin.py:190} INFO - [2025-10-05T00:08:21.790+0000] {dagbag.py:588} INFO - Filling up the DagBag from /opt/airflow/dags/device_config_dag.py
[2025-10-05T00:08:22.711+0000] {logging_mixin.py:190} INFO - [2025-10-05T00:08:22.692+0000] {dagbag.py:387} ERROR - Failed to import: /opt/airflow/dags/device_config_dag.py
Traceback (most recent call last):
  File "/home/airflow/.local/lib/python3.12/site-packages/airflow/models/dagbag.py", line 383, in parse
    loader.exec_module(new_module)
  File "<frozen importlib._bootstrap_external>", line 999, in exec_module
  File "<frozen importlib._bootstrap>", line 488, in _call_with_frames_removed
  File "/opt/airflow/dags/device_config_dag.py", line 7, in <module>
    from dags.tasks.load import IcebergStorage
  File "/opt/airflow/dags/tasks/load.py", line 7, in <module>
    from dags.tasks.config.settings import ICEBERG_STORAGE, BYTES_SIZE, TARGET_FILE_SIZE_MB
ImportError: cannot import name 'ICEBERG_STORAGE' from 'dags.tasks.config.settings' (/opt/airflow/dags/tasks/config/settings.py)
[2025-10-05T00:08:22.716+0000] {processor.py:927} WARNING - No viable dags retrieved from /opt/airflow/dags/device_config_dag.py
[2025-10-05T00:08:22.763+0000] {processor.py:208} INFO - Processing /opt/airflow/dags/device_config_dag.py took 0.994 seconds
[2025-10-05T00:08:52.921+0000] {processor.py:186} INFO - Started process (PID=1554) to work on /opt/airflow/dags/device_config_dag.py
[2025-10-05T00:08:52.924+0000] {processor.py:914} INFO - Processing file /opt/airflow/dags/device_config_dag.py for tasks to queue
[2025-10-05T00:08:52.927+0000] {logging_mixin.py:190} INFO - [2025-10-05T00:08:52.927+0000] {dagbag.py:588} INFO - Filling up the DagBag from /opt/airflow/dags/device_config_dag.py
[2025-10-05T00:08:53.946+0000] {logging_mixin.py:190} INFO - [2025-10-05T00:08:53.918+0000] {dagbag.py:387} ERROR - Failed to import: /opt/airflow/dags/device_config_dag.py
Traceback (most recent call last):
  File "/home/airflow/.local/lib/python3.12/site-packages/airflow/models/dagbag.py", line 383, in parse
    loader.exec_module(new_module)
  File "<frozen importlib._bootstrap_external>", line 999, in exec_module
  File "<frozen importlib._bootstrap>", line 488, in _call_with_frames_removed
  File "/opt/airflow/dags/device_config_dag.py", line 7, in <module>
    from dags.tasks.load import IcebergStorage
  File "/opt/airflow/dags/tasks/load.py", line 7, in <module>
    from dags.tasks.config.settings import ICEBERG_STORAGE, BYTES_SIZE, TARGET_FILE_SIZE_MB
ImportError: cannot import name 'ICEBERG_STORAGE' from 'dags.tasks.config.settings' (/opt/airflow/dags/tasks/config/settings.py)
[2025-10-05T00:08:53.952+0000] {processor.py:927} WARNING - No viable dags retrieved from /opt/airflow/dags/device_config_dag.py
[2025-10-05T00:08:54.192+0000] {processor.py:208} INFO - Processing /opt/airflow/dags/device_config_dag.py took 1.285 seconds
[2025-10-05T00:09:24.583+0000] {processor.py:186} INFO - Started process (PID=1581) to work on /opt/airflow/dags/device_config_dag.py
[2025-10-05T00:09:24.587+0000] {processor.py:914} INFO - Processing file /opt/airflow/dags/device_config_dag.py for tasks to queue
[2025-10-05T00:09:24.590+0000] {logging_mixin.py:190} INFO - [2025-10-05T00:09:24.589+0000] {dagbag.py:588} INFO - Filling up the DagBag from /opt/airflow/dags/device_config_dag.py
[2025-10-05T00:09:25.579+0000] {logging_mixin.py:190} INFO - [2025-10-05T00:09:25.563+0000] {dagbag.py:387} ERROR - Failed to import: /opt/airflow/dags/device_config_dag.py
Traceback (most recent call last):
  File "/home/airflow/.local/lib/python3.12/site-packages/airflow/models/dagbag.py", line 383, in parse
    loader.exec_module(new_module)
  File "<frozen importlib._bootstrap_external>", line 999, in exec_module
  File "<frozen importlib._bootstrap>", line 488, in _call_with_frames_removed
  File "/opt/airflow/dags/device_config_dag.py", line 7, in <module>
    from dags.tasks.load import IcebergStorage
  File "/opt/airflow/dags/tasks/load.py", line 7, in <module>
    from dags.tasks.config.settings import ICEBERG_STORAGE, BYTES_SIZE, TARGET_FILE_SIZE_MB
ImportError: cannot import name 'ICEBERG_STORAGE' from 'dags.tasks.config.settings' (/opt/airflow/dags/tasks/config/settings.py)
[2025-10-05T00:09:25.583+0000] {processor.py:927} WARNING - No viable dags retrieved from /opt/airflow/dags/device_config_dag.py
[2025-10-05T00:09:25.652+0000] {processor.py:208} INFO - Processing /opt/airflow/dags/device_config_dag.py took 1.089 seconds
[2025-10-05T00:09:55.911+0000] {processor.py:186} INFO - Started process (PID=1608) to work on /opt/airflow/dags/device_config_dag.py
[2025-10-05T00:09:55.914+0000] {processor.py:914} INFO - Processing file /opt/airflow/dags/device_config_dag.py for tasks to queue
[2025-10-05T00:09:55.919+0000] {logging_mixin.py:190} INFO - [2025-10-05T00:09:55.918+0000] {dagbag.py:588} INFO - Filling up the DagBag from /opt/airflow/dags/device_config_dag.py
[2025-10-05T00:09:57.209+0000] {logging_mixin.py:190} INFO - [2025-10-05T00:09:57.181+0000] {dagbag.py:387} ERROR - Failed to import: /opt/airflow/dags/device_config_dag.py
Traceback (most recent call last):
  File "/home/airflow/.local/lib/python3.12/site-packages/airflow/models/dagbag.py", line 383, in parse
    loader.exec_module(new_module)
  File "<frozen importlib._bootstrap_external>", line 999, in exec_module
  File "<frozen importlib._bootstrap>", line 488, in _call_with_frames_removed
  File "/opt/airflow/dags/device_config_dag.py", line 7, in <module>
    from dags.tasks.load import IcebergStorage
  File "/opt/airflow/dags/tasks/load.py", line 7, in <module>
    from dags.tasks.config.settings import ICEBERG_STORAGE, BYTES_SIZE, TARGET_FILE_SIZE_MB
ImportError: cannot import name 'ICEBERG_STORAGE' from 'dags.tasks.config.settings' (/opt/airflow/dags/tasks/config/settings.py)
[2025-10-05T00:09:57.215+0000] {processor.py:927} WARNING - No viable dags retrieved from /opt/airflow/dags/device_config_dag.py
[2025-10-05T00:09:57.297+0000] {processor.py:208} INFO - Processing /opt/airflow/dags/device_config_dag.py took 1.404 seconds
[2025-10-05T00:10:27.483+0000] {processor.py:186} INFO - Started process (PID=1635) to work on /opt/airflow/dags/device_config_dag.py
[2025-10-05T00:10:27.486+0000] {processor.py:914} INFO - Processing file /opt/airflow/dags/device_config_dag.py for tasks to queue
[2025-10-05T00:10:27.489+0000] {logging_mixin.py:190} INFO - [2025-10-05T00:10:27.488+0000] {dagbag.py:588} INFO - Filling up the DagBag from /opt/airflow/dags/device_config_dag.py
[2025-10-05T00:10:28.532+0000] {logging_mixin.py:190} INFO - [2025-10-05T00:10:28.516+0000] {dagbag.py:387} ERROR - Failed to import: /opt/airflow/dags/device_config_dag.py
Traceback (most recent call last):
  File "/home/airflow/.local/lib/python3.12/site-packages/airflow/models/dagbag.py", line 383, in parse
    loader.exec_module(new_module)
  File "<frozen importlib._bootstrap_external>", line 999, in exec_module
  File "<frozen importlib._bootstrap>", line 488, in _call_with_frames_removed
  File "/opt/airflow/dags/device_config_dag.py", line 7, in <module>
    from dags.tasks.load import IcebergStorage
  File "/opt/airflow/dags/tasks/load.py", line 7, in <module>
    from dags.tasks.config.settings import ICEBERG_STORAGE, BYTES_SIZE, TARGET_FILE_SIZE_MB
ImportError: cannot import name 'ICEBERG_STORAGE' from 'dags.tasks.config.settings' (/opt/airflow/dags/tasks/config/settings.py)
[2025-10-05T00:10:28.537+0000] {processor.py:927} WARNING - No viable dags retrieved from /opt/airflow/dags/device_config_dag.py
[2025-10-05T00:10:28.605+0000] {processor.py:208} INFO - Processing /opt/airflow/dags/device_config_dag.py took 1.139 seconds
[2025-10-05T00:10:59.656+0000] {processor.py:186} INFO - Started process (PID=1662) to work on /opt/airflow/dags/device_config_dag.py
[2025-10-05T00:10:59.658+0000] {processor.py:914} INFO - Processing file /opt/airflow/dags/device_config_dag.py for tasks to queue
[2025-10-05T00:10:59.662+0000] {logging_mixin.py:190} INFO - [2025-10-05T00:10:59.661+0000] {dagbag.py:588} INFO - Filling up the DagBag from /opt/airflow/dags/device_config_dag.py
[2025-10-05T00:11:00.814+0000] {logging_mixin.py:190} INFO - [2025-10-05T00:11:00.793+0000] {dagbag.py:387} ERROR - Failed to import: /opt/airflow/dags/device_config_dag.py
Traceback (most recent call last):
  File "/home/airflow/.local/lib/python3.12/site-packages/airflow/models/dagbag.py", line 383, in parse
    loader.exec_module(new_module)
  File "<frozen importlib._bootstrap_external>", line 999, in exec_module
  File "<frozen importlib._bootstrap>", line 488, in _call_with_frames_removed
  File "/opt/airflow/dags/device_config_dag.py", line 7, in <module>
    from dags.tasks.load import IcebergStorage
  File "/opt/airflow/dags/tasks/load.py", line 7, in <module>
    from dags.tasks.config.settings import ICEBERG_STORAGE, BYTES_SIZE, TARGET_FILE_SIZE_MB
ImportError: cannot import name 'ICEBERG_STORAGE' from 'dags.tasks.config.settings' (/opt/airflow/dags/tasks/config/settings.py)
[2025-10-05T00:11:00.820+0000] {processor.py:927} WARNING - No viable dags retrieved from /opt/airflow/dags/device_config_dag.py
[2025-10-05T00:11:01.057+0000] {processor.py:208} INFO - Processing /opt/airflow/dags/device_config_dag.py took 1.416 seconds
[2025-10-05T00:11:31.213+0000] {processor.py:186} INFO - Started process (PID=1689) to work on /opt/airflow/dags/device_config_dag.py
[2025-10-05T00:11:31.216+0000] {processor.py:914} INFO - Processing file /opt/airflow/dags/device_config_dag.py for tasks to queue
[2025-10-05T00:11:31.220+0000] {logging_mixin.py:190} INFO - [2025-10-05T00:11:31.219+0000] {dagbag.py:588} INFO - Filling up the DagBag from /opt/airflow/dags/device_config_dag.py
[2025-10-05T00:11:33.125+0000] {logging_mixin.py:190} INFO - [2025-10-05T00:11:33.039+0000] {dagbag.py:387} ERROR - Failed to import: /opt/airflow/dags/device_config_dag.py
Traceback (most recent call last):
  File "/home/airflow/.local/lib/python3.12/site-packages/airflow/models/dagbag.py", line 383, in parse
    loader.exec_module(new_module)
  File "<frozen importlib._bootstrap_external>", line 999, in exec_module
  File "<frozen importlib._bootstrap>", line 488, in _call_with_frames_removed
  File "/opt/airflow/dags/device_config_dag.py", line 7, in <module>
    from dags.tasks.load import IcebergStorage
  File "/opt/airflow/dags/tasks/load.py", line 7, in <module>
    from dags.tasks.config.settings import ICEBERG_STORAGE, BYTES_SIZE, TARGET_FILE_SIZE_MB
ImportError: cannot import name 'ICEBERG_STORAGE' from 'dags.tasks.config.settings' (/opt/airflow/dags/tasks/config/settings.py)
[2025-10-05T00:11:33.132+0000] {processor.py:927} WARNING - No viable dags retrieved from /opt/airflow/dags/device_config_dag.py
[2025-10-05T00:11:33.321+0000] {processor.py:208} INFO - Processing /opt/airflow/dags/device_config_dag.py took 2.126 seconds
[2025-10-05T00:12:03.879+0000] {processor.py:186} INFO - Started process (PID=1716) to work on /opt/airflow/dags/device_config_dag.py
[2025-10-05T00:12:03.881+0000] {processor.py:914} INFO - Processing file /opt/airflow/dags/device_config_dag.py for tasks to queue
[2025-10-05T00:12:03.884+0000] {logging_mixin.py:190} INFO - [2025-10-05T00:12:03.883+0000] {dagbag.py:588} INFO - Filling up the DagBag from /opt/airflow/dags/device_config_dag.py
[2025-10-05T00:12:04.820+0000] {logging_mixin.py:190} INFO - [2025-10-05T00:12:04.801+0000] {dagbag.py:387} ERROR - Failed to import: /opt/airflow/dags/device_config_dag.py
Traceback (most recent call last):
  File "/home/airflow/.local/lib/python3.12/site-packages/airflow/models/dagbag.py", line 383, in parse
    loader.exec_module(new_module)
  File "<frozen importlib._bootstrap_external>", line 999, in exec_module
  File "<frozen importlib._bootstrap>", line 488, in _call_with_frames_removed
  File "/opt/airflow/dags/device_config_dag.py", line 7, in <module>
    from dags.tasks.load import IcebergStorage
  File "/opt/airflow/dags/tasks/load.py", line 7, in <module>
    from dags.tasks.config.settings import ICEBERG_STORAGE, BYTES_SIZE, TARGET_FILE_SIZE_MB
ImportError: cannot import name 'ICEBERG_STORAGE' from 'dags.tasks.config.settings' (/opt/airflow/dags/tasks/config/settings.py)
[2025-10-05T00:12:04.825+0000] {processor.py:927} WARNING - No viable dags retrieved from /opt/airflow/dags/device_config_dag.py
[2025-10-05T00:12:04.895+0000] {processor.py:208} INFO - Processing /opt/airflow/dags/device_config_dag.py took 1.031 seconds
[2025-10-05T00:12:35.446+0000] {processor.py:186} INFO - Started process (PID=1743) to work on /opt/airflow/dags/device_config_dag.py
[2025-10-05T00:12:35.449+0000] {processor.py:914} INFO - Processing file /opt/airflow/dags/device_config_dag.py for tasks to queue
[2025-10-05T00:12:35.453+0000] {logging_mixin.py:190} INFO - [2025-10-05T00:12:35.452+0000] {dagbag.py:588} INFO - Filling up the DagBag from /opt/airflow/dags/device_config_dag.py
[2025-10-05T00:12:36.416+0000] {logging_mixin.py:190} INFO - [2025-10-05T00:12:36.400+0000] {dagbag.py:387} ERROR - Failed to import: /opt/airflow/dags/device_config_dag.py
Traceback (most recent call last):
  File "/home/airflow/.local/lib/python3.12/site-packages/airflow/models/dagbag.py", line 383, in parse
    loader.exec_module(new_module)
  File "<frozen importlib._bootstrap_external>", line 999, in exec_module
  File "<frozen importlib._bootstrap>", line 488, in _call_with_frames_removed
  File "/opt/airflow/dags/device_config_dag.py", line 7, in <module>
    from dags.tasks.load import IcebergStorage
  File "/opt/airflow/dags/tasks/load.py", line 7, in <module>
    from dags.tasks.config.settings import ICEBERG_STORAGE, BYTES_SIZE, TARGET_FILE_SIZE_MB
ImportError: cannot import name 'ICEBERG_STORAGE' from 'dags.tasks.config.settings' (/opt/airflow/dags/tasks/config/settings.py)
[2025-10-05T00:12:36.425+0000] {processor.py:927} WARNING - No viable dags retrieved from /opt/airflow/dags/device_config_dag.py
[2025-10-05T00:12:36.497+0000] {processor.py:208} INFO - Processing /opt/airflow/dags/device_config_dag.py took 1.066 seconds
[2025-10-05T00:13:07.278+0000] {processor.py:186} INFO - Started process (PID=1770) to work on /opt/airflow/dags/device_config_dag.py
[2025-10-05T00:13:07.282+0000] {processor.py:914} INFO - Processing file /opt/airflow/dags/device_config_dag.py for tasks to queue
[2025-10-05T00:13:07.287+0000] {logging_mixin.py:190} INFO - [2025-10-05T00:13:07.286+0000] {dagbag.py:588} INFO - Filling up the DagBag from /opt/airflow/dags/device_config_dag.py
[2025-10-05T00:13:08.233+0000] {logging_mixin.py:190} INFO - [2025-10-05T00:13:08.208+0000] {dagbag.py:387} ERROR - Failed to import: /opt/airflow/dags/device_config_dag.py
Traceback (most recent call last):
  File "/home/airflow/.local/lib/python3.12/site-packages/airflow/models/dagbag.py", line 383, in parse
    loader.exec_module(new_module)
  File "<frozen importlib._bootstrap_external>", line 999, in exec_module
  File "<frozen importlib._bootstrap>", line 488, in _call_with_frames_removed
  File "/opt/airflow/dags/device_config_dag.py", line 7, in <module>
    from dags.tasks.load import IcebergStorage
  File "/opt/airflow/dags/tasks/load.py", line 7, in <module>
    from dags.tasks.config.settings import ICEBERG_STORAGE, BYTES_SIZE, TARGET_FILE_SIZE_MB
ImportError: cannot import name 'ICEBERG_STORAGE' from 'dags.tasks.config.settings' (/opt/airflow/dags/tasks/config/settings.py)
[2025-10-05T00:13:08.240+0000] {processor.py:927} WARNING - No viable dags retrieved from /opt/airflow/dags/device_config_dag.py
[2025-10-05T00:13:08.282+0000] {processor.py:208} INFO - Processing /opt/airflow/dags/device_config_dag.py took 1.024 seconds
[2025-10-05T00:13:39.146+0000] {processor.py:186} INFO - Started process (PID=1797) to work on /opt/airflow/dags/device_config_dag.py
[2025-10-05T00:13:39.149+0000] {processor.py:914} INFO - Processing file /opt/airflow/dags/device_config_dag.py for tasks to queue
[2025-10-05T00:13:39.152+0000] {logging_mixin.py:190} INFO - [2025-10-05T00:13:39.151+0000] {dagbag.py:588} INFO - Filling up the DagBag from /opt/airflow/dags/device_config_dag.py
[2025-10-05T00:13:41.612+0000] {logging_mixin.py:190} INFO - [2025-10-05T00:13:41.533+0000] {dagbag.py:387} ERROR - Failed to import: /opt/airflow/dags/device_config_dag.py
Traceback (most recent call last):
  File "/home/airflow/.local/lib/python3.12/site-packages/airflow/models/dagbag.py", line 383, in parse
    loader.exec_module(new_module)
  File "<frozen importlib._bootstrap_external>", line 999, in exec_module
  File "<frozen importlib._bootstrap>", line 488, in _call_with_frames_removed
  File "/opt/airflow/dags/device_config_dag.py", line 7, in <module>
    from dags.tasks.load import IcebergStorage
  File "/opt/airflow/dags/tasks/load.py", line 7, in <module>
    from dags.tasks.config.settings import ICEBERG_STORAGE, BYTES_SIZE, TARGET_FILE_SIZE_MB
ImportError: cannot import name 'ICEBERG_STORAGE' from 'dags.tasks.config.settings' (/opt/airflow/dags/tasks/config/settings.py)
[2025-10-05T00:13:41.622+0000] {processor.py:927} WARNING - No viable dags retrieved from /opt/airflow/dags/device_config_dag.py
[2025-10-05T00:13:41.931+0000] {processor.py:208} INFO - Processing /opt/airflow/dags/device_config_dag.py took 2.800 seconds
[2025-10-05T00:14:13.542+0000] {processor.py:186} INFO - Started process (PID=1824) to work on /opt/airflow/dags/device_config_dag.py
[2025-10-05T00:14:13.545+0000] {processor.py:914} INFO - Processing file /opt/airflow/dags/device_config_dag.py for tasks to queue
[2025-10-05T00:14:13.549+0000] {logging_mixin.py:190} INFO - [2025-10-05T00:14:13.549+0000] {dagbag.py:588} INFO - Filling up the DagBag from /opt/airflow/dags/device_config_dag.py
[2025-10-05T00:14:14.603+0000] {logging_mixin.py:190} INFO - [2025-10-05T00:14:14.583+0000] {dagbag.py:387} ERROR - Failed to import: /opt/airflow/dags/device_config_dag.py
Traceback (most recent call last):
  File "/home/airflow/.local/lib/python3.12/site-packages/airflow/models/dagbag.py", line 383, in parse
    loader.exec_module(new_module)
  File "<frozen importlib._bootstrap_external>", line 999, in exec_module
  File "<frozen importlib._bootstrap>", line 488, in _call_with_frames_removed
  File "/opt/airflow/dags/device_config_dag.py", line 7, in <module>
    from dags.tasks.load import IcebergStorage
  File "/opt/airflow/dags/tasks/load.py", line 7, in <module>
    from dags.tasks.config.settings import ICEBERG_STORAGE, BYTES_SIZE, TARGET_FILE_SIZE_MB
ImportError: cannot import name 'ICEBERG_STORAGE' from 'dags.tasks.config.settings' (/opt/airflow/dags/tasks/config/settings.py)
[2025-10-05T00:14:14.607+0000] {processor.py:927} WARNING - No viable dags retrieved from /opt/airflow/dags/device_config_dag.py
[2025-10-05T00:14:14.649+0000] {processor.py:208} INFO - Processing /opt/airflow/dags/device_config_dag.py took 1.120 seconds
[2025-10-05T00:14:45.138+0000] {processor.py:186} INFO - Started process (PID=1851) to work on /opt/airflow/dags/device_config_dag.py
[2025-10-05T00:14:45.145+0000] {processor.py:914} INFO - Processing file /opt/airflow/dags/device_config_dag.py for tasks to queue
[2025-10-05T00:14:45.165+0000] {logging_mixin.py:190} INFO - [2025-10-05T00:14:45.163+0000] {dagbag.py:588} INFO - Filling up the DagBag from /opt/airflow/dags/device_config_dag.py
[2025-10-05T00:14:47.683+0000] {logging_mixin.py:190} INFO - [2025-10-05T00:14:47.548+0000] {dagbag.py:387} ERROR - Failed to import: /opt/airflow/dags/device_config_dag.py
Traceback (most recent call last):
  File "/home/airflow/.local/lib/python3.12/site-packages/airflow/models/dagbag.py", line 383, in parse
    loader.exec_module(new_module)
  File "<frozen importlib._bootstrap_external>", line 999, in exec_module
  File "<frozen importlib._bootstrap>", line 488, in _call_with_frames_removed
  File "/opt/airflow/dags/device_config_dag.py", line 7, in <module>
    from dags.tasks.load import IcebergStorage
  File "/opt/airflow/dags/tasks/load.py", line 7, in <module>
    from dags.tasks.config.settings import ICEBERG_STORAGE, BYTES_SIZE, TARGET_FILE_SIZE_MB
ImportError: cannot import name 'ICEBERG_STORAGE' from 'dags.tasks.config.settings' (/opt/airflow/dags/tasks/config/settings.py)
[2025-10-05T00:14:47.690+0000] {processor.py:927} WARNING - No viable dags retrieved from /opt/airflow/dags/device_config_dag.py
[2025-10-05T00:14:47.867+0000] {processor.py:208} INFO - Processing /opt/airflow/dags/device_config_dag.py took 2.755 seconds
[2025-10-05T00:15:18.172+0000] {processor.py:186} INFO - Started process (PID=1878) to work on /opt/airflow/dags/device_config_dag.py
[2025-10-05T00:15:18.174+0000] {processor.py:914} INFO - Processing file /opt/airflow/dags/device_config_dag.py for tasks to queue
[2025-10-05T00:15:18.178+0000] {logging_mixin.py:190} INFO - [2025-10-05T00:15:18.177+0000] {dagbag.py:588} INFO - Filling up the DagBag from /opt/airflow/dags/device_config_dag.py
[2025-10-05T00:15:19.229+0000] {logging_mixin.py:190} INFO - [2025-10-05T00:15:19.212+0000] {dagbag.py:387} ERROR - Failed to import: /opt/airflow/dags/device_config_dag.py
Traceback (most recent call last):
  File "/home/airflow/.local/lib/python3.12/site-packages/airflow/models/dagbag.py", line 383, in parse
    loader.exec_module(new_module)
  File "<frozen importlib._bootstrap_external>", line 999, in exec_module
  File "<frozen importlib._bootstrap>", line 488, in _call_with_frames_removed
  File "/opt/airflow/dags/device_config_dag.py", line 7, in <module>
    from dags.tasks.load import IcebergStorage
  File "/opt/airflow/dags/tasks/load.py", line 7, in <module>
    from dags.tasks.config.settings import ICEBERG_STORAGE, BYTES_SIZE, TARGET_FILE_SIZE_MB
ImportError: cannot import name 'ICEBERG_STORAGE' from 'dags.tasks.config.settings' (/opt/airflow/dags/tasks/config/settings.py)
[2025-10-05T00:15:19.234+0000] {processor.py:927} WARNING - No viable dags retrieved from /opt/airflow/dags/device_config_dag.py
[2025-10-05T00:15:19.274+0000] {processor.py:208} INFO - Processing /opt/airflow/dags/device_config_dag.py took 1.119 seconds
[2025-10-05T00:15:49.776+0000] {processor.py:186} INFO - Started process (PID=1905) to work on /opt/airflow/dags/device_config_dag.py
[2025-10-05T00:15:49.785+0000] {processor.py:914} INFO - Processing file /opt/airflow/dags/device_config_dag.py for tasks to queue
[2025-10-05T00:15:49.789+0000] {logging_mixin.py:190} INFO - [2025-10-05T00:15:49.788+0000] {dagbag.py:588} INFO - Filling up the DagBag from /opt/airflow/dags/device_config_dag.py
[2025-10-05T00:15:51.799+0000] {logging_mixin.py:190} INFO - [2025-10-05T00:15:51.578+0000] {dagbag.py:387} ERROR - Failed to import: /opt/airflow/dags/device_config_dag.py
Traceback (most recent call last):
  File "/home/airflow/.local/lib/python3.12/site-packages/airflow/models/dagbag.py", line 383, in parse
    loader.exec_module(new_module)
  File "<frozen importlib._bootstrap_external>", line 999, in exec_module
  File "<frozen importlib._bootstrap>", line 488, in _call_with_frames_removed
  File "/opt/airflow/dags/device_config_dag.py", line 7, in <module>
    from dags.tasks.load import IcebergStorage
  File "/opt/airflow/dags/tasks/load.py", line 7, in <module>
    from dags.tasks.config.settings import ICEBERG_STORAGE, BYTES_SIZE, TARGET_FILE_SIZE_MB
ImportError: cannot import name 'ICEBERG_STORAGE' from 'dags.tasks.config.settings' (/opt/airflow/dags/tasks/config/settings.py)
[2025-10-05T00:15:51.807+0000] {processor.py:927} WARNING - No viable dags retrieved from /opt/airflow/dags/device_config_dag.py
[2025-10-05T00:15:52.327+0000] {processor.py:208} INFO - Processing /opt/airflow/dags/device_config_dag.py took 4.342 seconds
[2025-10-05T00:16:23.178+0000] {processor.py:186} INFO - Started process (PID=1932) to work on /opt/airflow/dags/device_config_dag.py
[2025-10-05T00:16:23.181+0000] {processor.py:914} INFO - Processing file /opt/airflow/dags/device_config_dag.py for tasks to queue
[2025-10-05T00:16:23.187+0000] {logging_mixin.py:190} INFO - [2025-10-05T00:16:23.185+0000] {dagbag.py:588} INFO - Filling up the DagBag from /opt/airflow/dags/device_config_dag.py
[2025-10-05T00:16:25.161+0000] {logging_mixin.py:190} INFO - [2025-10-05T00:16:25.139+0000] {dagbag.py:387} ERROR - Failed to import: /opt/airflow/dags/device_config_dag.py
Traceback (most recent call last):
  File "/home/airflow/.local/lib/python3.12/site-packages/airflow/models/dagbag.py", line 383, in parse
    loader.exec_module(new_module)
  File "<frozen importlib._bootstrap_external>", line 999, in exec_module
  File "<frozen importlib._bootstrap>", line 488, in _call_with_frames_removed
  File "/opt/airflow/dags/device_config_dag.py", line 7, in <module>
    from dags.tasks.load import IcebergStorage
  File "/opt/airflow/dags/tasks/load.py", line 7, in <module>
    from dags.tasks.config.settings import ICEBERG_STORAGE, BYTES_SIZE, TARGET_FILE_SIZE_MB
ImportError: cannot import name 'ICEBERG_STORAGE' from 'dags.tasks.config.settings' (/opt/airflow/dags/tasks/config/settings.py)
[2025-10-05T00:16:25.168+0000] {processor.py:927} WARNING - No viable dags retrieved from /opt/airflow/dags/device_config_dag.py
[2025-10-05T00:16:25.244+0000] {processor.py:208} INFO - Processing /opt/airflow/dags/device_config_dag.py took 2.097 seconds
[2025-10-05T00:16:55.988+0000] {processor.py:186} INFO - Started process (PID=1959) to work on /opt/airflow/dags/device_config_dag.py
[2025-10-05T00:16:55.992+0000] {processor.py:914} INFO - Processing file /opt/airflow/dags/device_config_dag.py for tasks to queue
[2025-10-05T00:16:55.999+0000] {logging_mixin.py:190} INFO - [2025-10-05T00:16:55.996+0000] {dagbag.py:588} INFO - Filling up the DagBag from /opt/airflow/dags/device_config_dag.py
[2025-10-05T00:16:58.387+0000] {logging_mixin.py:190} INFO - [2025-10-05T00:16:58.361+0000] {dagbag.py:387} ERROR - Failed to import: /opt/airflow/dags/device_config_dag.py
Traceback (most recent call last):
  File "/home/airflow/.local/lib/python3.12/site-packages/airflow/models/dagbag.py", line 383, in parse
    loader.exec_module(new_module)
  File "<frozen importlib._bootstrap_external>", line 999, in exec_module
  File "<frozen importlib._bootstrap>", line 488, in _call_with_frames_removed
  File "/opt/airflow/dags/device_config_dag.py", line 7, in <module>
    from dags.tasks.load import IcebergStorage
  File "/opt/airflow/dags/tasks/load.py", line 7, in <module>
    from dags.tasks.config.settings import ICEBERG_STORAGE, BYTES_SIZE, TARGET_FILE_SIZE_MB
ImportError: cannot import name 'ICEBERG_STORAGE' from 'dags.tasks.config.settings' (/opt/airflow/dags/tasks/config/settings.py)
[2025-10-05T00:16:58.393+0000] {processor.py:927} WARNING - No viable dags retrieved from /opt/airflow/dags/device_config_dag.py
[2025-10-05T00:16:58.475+0000] {processor.py:208} INFO - Processing /opt/airflow/dags/device_config_dag.py took 2.516 seconds
[2025-10-05T00:17:29.201+0000] {processor.py:186} INFO - Started process (PID=1986) to work on /opt/airflow/dags/device_config_dag.py
[2025-10-05T00:17:29.203+0000] {processor.py:914} INFO - Processing file /opt/airflow/dags/device_config_dag.py for tasks to queue
[2025-10-05T00:17:29.209+0000] {logging_mixin.py:190} INFO - [2025-10-05T00:17:29.208+0000] {dagbag.py:588} INFO - Filling up the DagBag from /opt/airflow/dags/device_config_dag.py
[2025-10-05T00:17:30.398+0000] {logging_mixin.py:190} INFO - [2025-10-05T00:17:30.373+0000] {dagbag.py:387} ERROR - Failed to import: /opt/airflow/dags/device_config_dag.py
Traceback (most recent call last):
  File "/home/airflow/.local/lib/python3.12/site-packages/airflow/models/dagbag.py", line 383, in parse
    loader.exec_module(new_module)
  File "<frozen importlib._bootstrap_external>", line 999, in exec_module
  File "<frozen importlib._bootstrap>", line 488, in _call_with_frames_removed
  File "/opt/airflow/dags/device_config_dag.py", line 7, in <module>
    from dags.tasks.load import IcebergStorage
  File "/opt/airflow/dags/tasks/load.py", line 7, in <module>
    from dags.tasks.config.settings import ICEBERG_STORAGE, BYTES_SIZE, TARGET_FILE_SIZE_MB
ImportError: cannot import name 'ICEBERG_STORAGE' from 'dags.tasks.config.settings' (/opt/airflow/dags/tasks/config/settings.py)
[2025-10-05T00:17:30.402+0000] {processor.py:927} WARNING - No viable dags retrieved from /opt/airflow/dags/device_config_dag.py
[2025-10-05T00:17:30.484+0000] {processor.py:208} INFO - Processing /opt/airflow/dags/device_config_dag.py took 1.301 seconds
[2025-10-05T00:18:01.535+0000] {processor.py:186} INFO - Started process (PID=2022) to work on /opt/airflow/dags/device_config_dag.py
[2025-10-05T00:18:01.539+0000] {processor.py:914} INFO - Processing file /opt/airflow/dags/device_config_dag.py for tasks to queue
[2025-10-05T00:18:01.542+0000] {logging_mixin.py:190} INFO - [2025-10-05T00:18:01.541+0000] {dagbag.py:588} INFO - Filling up the DagBag from /opt/airflow/dags/device_config_dag.py
[2025-10-05T00:18:02.845+0000] {logging_mixin.py:190} INFO - [2025-10-05T00:18:02.826+0000] {dagbag.py:387} ERROR - Failed to import: /opt/airflow/dags/device_config_dag.py
Traceback (most recent call last):
  File "/home/airflow/.local/lib/python3.12/site-packages/airflow/models/dagbag.py", line 383, in parse
    loader.exec_module(new_module)
  File "<frozen importlib._bootstrap_external>", line 999, in exec_module
  File "<frozen importlib._bootstrap>", line 488, in _call_with_frames_removed
  File "/opt/airflow/dags/device_config_dag.py", line 7, in <module>
    from dags.tasks.load import IcebergStorage
  File "/opt/airflow/dags/tasks/load.py", line 7, in <module>
    from dags.tasks.config.settings import ICEBERG_STORAGE, BYTES_SIZE, TARGET_FILE_SIZE_MB
ImportError: cannot import name 'ICEBERG_STORAGE' from 'dags.tasks.config.settings' (/opt/airflow/dags/tasks/config/settings.py)
[2025-10-05T00:18:02.851+0000] {processor.py:927} WARNING - No viable dags retrieved from /opt/airflow/dags/device_config_dag.py
[2025-10-05T00:18:02.888+0000] {processor.py:208} INFO - Processing /opt/airflow/dags/device_config_dag.py took 1.419 seconds
[2025-10-05T00:18:33.428+0000] {processor.py:186} INFO - Started process (PID=2042) to work on /opt/airflow/dags/device_config_dag.py
[2025-10-05T00:18:33.431+0000] {processor.py:914} INFO - Processing file /opt/airflow/dags/device_config_dag.py for tasks to queue
[2025-10-05T00:18:33.435+0000] {logging_mixin.py:190} INFO - [2025-10-05T00:18:33.434+0000] {dagbag.py:588} INFO - Filling up the DagBag from /opt/airflow/dags/device_config_dag.py
[2025-10-05T00:18:34.632+0000] {logging_mixin.py:190} INFO - [2025-10-05T00:18:34.605+0000] {dagbag.py:387} ERROR - Failed to import: /opt/airflow/dags/device_config_dag.py
Traceback (most recent call last):
  File "/home/airflow/.local/lib/python3.12/site-packages/airflow/models/dagbag.py", line 383, in parse
    loader.exec_module(new_module)
  File "<frozen importlib._bootstrap_external>", line 999, in exec_module
  File "<frozen importlib._bootstrap>", line 488, in _call_with_frames_removed
  File "/opt/airflow/dags/device_config_dag.py", line 7, in <module>
    from dags.tasks.load import IcebergStorage
  File "/opt/airflow/dags/tasks/load.py", line 7, in <module>
    from dags.tasks.config.settings import ICEBERG_STORAGE, BYTES_SIZE, TARGET_FILE_SIZE_MB
ImportError: cannot import name 'ICEBERG_STORAGE' from 'dags.tasks.config.settings' (/opt/airflow/dags/tasks/config/settings.py)
[2025-10-05T00:18:34.639+0000] {processor.py:927} WARNING - No viable dags retrieved from /opt/airflow/dags/device_config_dag.py
[2025-10-05T00:18:34.674+0000] {processor.py:208} INFO - Processing /opt/airflow/dags/device_config_dag.py took 1.270 seconds
[2025-10-05T00:19:04.982+0000] {processor.py:186} INFO - Started process (PID=2067) to work on /opt/airflow/dags/device_config_dag.py
[2025-10-05T00:19:04.985+0000] {processor.py:914} INFO - Processing file /opt/airflow/dags/device_config_dag.py for tasks to queue
[2025-10-05T00:19:04.988+0000] {logging_mixin.py:190} INFO - [2025-10-05T00:19:04.987+0000] {dagbag.py:588} INFO - Filling up the DagBag from /opt/airflow/dags/device_config_dag.py
[2025-10-05T00:19:06.803+0000] {logging_mixin.py:190} INFO - [2025-10-05T00:19:06.787+0000] {dagbag.py:387} ERROR - Failed to import: /opt/airflow/dags/device_config_dag.py
Traceback (most recent call last):
  File "/home/airflow/.local/lib/python3.12/site-packages/airflow/models/dagbag.py", line 383, in parse
    loader.exec_module(new_module)
  File "<frozen importlib._bootstrap_external>", line 999, in exec_module
  File "<frozen importlib._bootstrap>", line 488, in _call_with_frames_removed
  File "/opt/airflow/dags/device_config_dag.py", line 7, in <module>
    from dags.tasks.load import IcebergStorage
  File "/opt/airflow/dags/tasks/load.py", line 7, in <module>
    from dags.tasks.config.settings import ICEBERG_STORAGE, BYTES_SIZE, TARGET_FILE_SIZE_MB
ImportError: cannot import name 'ICEBERG_STORAGE' from 'dags.tasks.config.settings' (/opt/airflow/dags/tasks/config/settings.py)
[2025-10-05T00:19:06.809+0000] {processor.py:927} WARNING - No viable dags retrieved from /opt/airflow/dags/device_config_dag.py
[2025-10-05T00:19:06.883+0000] {processor.py:208} INFO - Processing /opt/airflow/dags/device_config_dag.py took 1.914 seconds
[2025-10-05T00:19:38.038+0000] {processor.py:186} INFO - Started process (PID=2094) to work on /opt/airflow/dags/device_config_dag.py
[2025-10-05T00:19:38.041+0000] {processor.py:914} INFO - Processing file /opt/airflow/dags/device_config_dag.py for tasks to queue
[2025-10-05T00:19:38.047+0000] {logging_mixin.py:190} INFO - [2025-10-05T00:19:38.047+0000] {dagbag.py:588} INFO - Filling up the DagBag from /opt/airflow/dags/device_config_dag.py
[2025-10-05T00:19:39.215+0000] {logging_mixin.py:190} INFO - [2025-10-05T00:19:39.196+0000] {dagbag.py:387} ERROR - Failed to import: /opt/airflow/dags/device_config_dag.py
Traceback (most recent call last):
  File "/home/airflow/.local/lib/python3.12/site-packages/airflow/models/dagbag.py", line 383, in parse
    loader.exec_module(new_module)
  File "<frozen importlib._bootstrap_external>", line 999, in exec_module
  File "<frozen importlib._bootstrap>", line 488, in _call_with_frames_removed
  File "/opt/airflow/dags/device_config_dag.py", line 7, in <module>
    from dags.tasks.load import IcebergStorage
  File "/opt/airflow/dags/tasks/load.py", line 7, in <module>
    from dags.tasks.config.settings import ICEBERG_STORAGE, BYTES_SIZE, TARGET_FILE_SIZE_MB
ImportError: cannot import name 'ICEBERG_STORAGE' from 'dags.tasks.config.settings' (/opt/airflow/dags/tasks/config/settings.py)
[2025-10-05T00:19:39.222+0000] {processor.py:927} WARNING - No viable dags retrieved from /opt/airflow/dags/device_config_dag.py
[2025-10-05T00:19:39.281+0000] {processor.py:208} INFO - Processing /opt/airflow/dags/device_config_dag.py took 1.264 seconds
[2025-10-05T00:20:09.660+0000] {processor.py:186} INFO - Started process (PID=2121) to work on /opt/airflow/dags/device_config_dag.py
[2025-10-05T00:20:09.663+0000] {processor.py:914} INFO - Processing file /opt/airflow/dags/device_config_dag.py for tasks to queue
[2025-10-05T00:20:09.667+0000] {logging_mixin.py:190} INFO - [2025-10-05T00:20:09.666+0000] {dagbag.py:588} INFO - Filling up the DagBag from /opt/airflow/dags/device_config_dag.py
[2025-10-05T00:20:10.607+0000] {logging_mixin.py:190} INFO - [2025-10-05T00:20:10.590+0000] {dagbag.py:387} ERROR - Failed to import: /opt/airflow/dags/device_config_dag.py
Traceback (most recent call last):
  File "/home/airflow/.local/lib/python3.12/site-packages/airflow/models/dagbag.py", line 383, in parse
    loader.exec_module(new_module)
  File "<frozen importlib._bootstrap_external>", line 999, in exec_module
  File "<frozen importlib._bootstrap>", line 488, in _call_with_frames_removed
  File "/opt/airflow/dags/device_config_dag.py", line 7, in <module>
    from dags.tasks.load import IcebergStorage
  File "/opt/airflow/dags/tasks/load.py", line 7, in <module>
    from dags.tasks.config.settings import ICEBERG_STORAGE, BYTES_SIZE, TARGET_FILE_SIZE_MB
ImportError: cannot import name 'ICEBERG_STORAGE' from 'dags.tasks.config.settings' (/opt/airflow/dags/tasks/config/settings.py)
[2025-10-05T00:20:10.611+0000] {processor.py:927} WARNING - No viable dags retrieved from /opt/airflow/dags/device_config_dag.py
[2025-10-05T00:20:10.666+0000] {processor.py:208} INFO - Processing /opt/airflow/dags/device_config_dag.py took 1.025 seconds
[2025-10-05T00:20:41.112+0000] {processor.py:186} INFO - Started process (PID=2148) to work on /opt/airflow/dags/device_config_dag.py
[2025-10-05T00:20:41.114+0000] {processor.py:914} INFO - Processing file /opt/airflow/dags/device_config_dag.py for tasks to queue
[2025-10-05T00:20:41.117+0000] {logging_mixin.py:190} INFO - [2025-10-05T00:20:41.116+0000] {dagbag.py:588} INFO - Filling up the DagBag from /opt/airflow/dags/device_config_dag.py
[2025-10-05T00:20:43.273+0000] {logging_mixin.py:190} INFO - [2025-10-05T00:20:43.250+0000] {dagbag.py:387} ERROR - Failed to import: /opt/airflow/dags/device_config_dag.py
Traceback (most recent call last):
  File "/home/airflow/.local/lib/python3.12/site-packages/airflow/models/dagbag.py", line 383, in parse
    loader.exec_module(new_module)
  File "<frozen importlib._bootstrap_external>", line 999, in exec_module
  File "<frozen importlib._bootstrap>", line 488, in _call_with_frames_removed
  File "/opt/airflow/dags/device_config_dag.py", line 7, in <module>
    from dags.tasks.load import IcebergStorage
  File "/opt/airflow/dags/tasks/load.py", line 7, in <module>
    from dags.tasks.config.settings import ICEBERG_STORAGE, BYTES_SIZE, TARGET_FILE_SIZE_MB
ImportError: cannot import name 'ICEBERG_STORAGE' from 'dags.tasks.config.settings' (/opt/airflow/dags/tasks/config/settings.py)
[2025-10-05T00:20:43.278+0000] {processor.py:927} WARNING - No viable dags retrieved from /opt/airflow/dags/device_config_dag.py
[2025-10-05T00:20:43.483+0000] {processor.py:208} INFO - Processing /opt/airflow/dags/device_config_dag.py took 2.385 seconds
[2025-10-05T00:21:14.019+0000] {processor.py:186} INFO - Started process (PID=2175) to work on /opt/airflow/dags/device_config_dag.py
[2025-10-05T00:21:14.022+0000] {processor.py:914} INFO - Processing file /opt/airflow/dags/device_config_dag.py for tasks to queue
[2025-10-05T00:21:14.028+0000] {logging_mixin.py:190} INFO - [2025-10-05T00:21:14.025+0000] {dagbag.py:588} INFO - Filling up the DagBag from /opt/airflow/dags/device_config_dag.py
[2025-10-05T00:21:16.441+0000] {logging_mixin.py:190} INFO - [2025-10-05T00:21:16.420+0000] {dagbag.py:387} ERROR - Failed to import: /opt/airflow/dags/device_config_dag.py
Traceback (most recent call last):
  File "/home/airflow/.local/lib/python3.12/site-packages/airflow/models/dagbag.py", line 383, in parse
    loader.exec_module(new_module)
  File "<frozen importlib._bootstrap_external>", line 999, in exec_module
  File "<frozen importlib._bootstrap>", line 488, in _call_with_frames_removed
  File "/opt/airflow/dags/device_config_dag.py", line 7, in <module>
    from dags.tasks.load import IcebergStorage
  File "/opt/airflow/dags/tasks/load.py", line 7, in <module>
    from dags.tasks.config.settings import ICEBERG_STORAGE, BYTES_SIZE, TARGET_FILE_SIZE_MB
ImportError: cannot import name 'ICEBERG_STORAGE' from 'dags.tasks.config.settings' (/opt/airflow/dags/tasks/config/settings.py)
[2025-10-05T00:21:16.451+0000] {processor.py:927} WARNING - No viable dags retrieved from /opt/airflow/dags/device_config_dag.py
[2025-10-05T00:21:16.527+0000] {processor.py:208} INFO - Processing /opt/airflow/dags/device_config_dag.py took 2.527 seconds
[2025-10-05T00:21:46.910+0000] {processor.py:186} INFO - Started process (PID=2202) to work on /opt/airflow/dags/device_config_dag.py
[2025-10-05T00:21:46.914+0000] {processor.py:914} INFO - Processing file /opt/airflow/dags/device_config_dag.py for tasks to queue
[2025-10-05T00:21:46.919+0000] {logging_mixin.py:190} INFO - [2025-10-05T00:21:46.917+0000] {dagbag.py:588} INFO - Filling up the DagBag from /opt/airflow/dags/device_config_dag.py
[2025-10-05T00:21:48.227+0000] {logging_mixin.py:190} INFO - [2025-10-05T00:21:48.200+0000] {dagbag.py:387} ERROR - Failed to import: /opt/airflow/dags/device_config_dag.py
Traceback (most recent call last):
  File "/home/airflow/.local/lib/python3.12/site-packages/airflow/models/dagbag.py", line 383, in parse
    loader.exec_module(new_module)
  File "<frozen importlib._bootstrap_external>", line 999, in exec_module
  File "<frozen importlib._bootstrap>", line 488, in _call_with_frames_removed
  File "/opt/airflow/dags/device_config_dag.py", line 7, in <module>
    from dags.tasks.load import IcebergStorage
  File "/opt/airflow/dags/tasks/load.py", line 7, in <module>
    from dags.tasks.config.settings import ICEBERG_STORAGE, BYTES_SIZE, TARGET_FILE_SIZE_MB
ImportError: cannot import name 'ICEBERG_STORAGE' from 'dags.tasks.config.settings' (/opt/airflow/dags/tasks/config/settings.py)
[2025-10-05T00:21:48.236+0000] {processor.py:927} WARNING - No viable dags retrieved from /opt/airflow/dags/device_config_dag.py
[2025-10-05T00:21:48.341+0000] {processor.py:208} INFO - Processing /opt/airflow/dags/device_config_dag.py took 1.452 seconds
[2025-10-05T00:22:18.647+0000] {processor.py:186} INFO - Started process (PID=2230) to work on /opt/airflow/dags/device_config_dag.py
[2025-10-05T00:22:18.651+0000] {processor.py:914} INFO - Processing file /opt/airflow/dags/device_config_dag.py for tasks to queue
[2025-10-05T00:22:18.656+0000] {logging_mixin.py:190} INFO - [2025-10-05T00:22:18.654+0000] {dagbag.py:588} INFO - Filling up the DagBag from /opt/airflow/dags/device_config_dag.py
[2025-10-05T00:22:20.739+0000] {processor.py:925} INFO - DAG(s) 'device_config_pipeline' retrieved from /opt/airflow/dags/device_config_dag.py
[2025-10-05T00:22:22.244+0000] {logging_mixin.py:190} INFO - [2025-10-05T00:22:22.237+0000] {dag.py:3239} INFO - Sync 1 DAGs
[2025-10-05T00:22:30.599+0000] {logging_mixin.py:190} INFO - [2025-10-05T00:22:30.591+0000] {dag.py:4180} INFO - Setting next_dagrun for device_config_pipeline to 2025-03-15 18:30:00+00:00, run_after=2025-03-22 18:30:00+00:00
[2025-10-05T00:22:30.733+0000] {processor.py:208} INFO - Processing /opt/airflow/dags/device_config_dag.py took 14.059 seconds
[2025-10-05T00:23:02.331+0000] {processor.py:186} INFO - Started process (PID=2260) to work on /opt/airflow/dags/device_config_dag.py
[2025-10-05T00:23:02.360+0000] {processor.py:914} INFO - Processing file /opt/airflow/dags/device_config_dag.py for tasks to queue
[2025-10-05T00:23:02.411+0000] {logging_mixin.py:190} INFO - [2025-10-05T00:23:02.387+0000] {dagbag.py:588} INFO - Filling up the DagBag from /opt/airflow/dags/device_config_dag.py
[2025-10-05T00:26:48.109+0000] {logging_mixin.py:190} INFO - [2025-10-05T00:26:48.104+0000] {timeout.py:68} ERROR - Process timed out, PID: 2260
[2025-10-05T00:26:48.443+0000] {logging_mixin.py:190} INFO - [2025-10-05T00:26:48.115+0000] {dagbag.py:387} ERROR - Failed to import: /opt/airflow/dags/device_config_dag.py
Traceback (most recent call last):
  File "/home/airflow/.local/lib/python3.12/site-packages/airflow/models/dagbag.py", line 383, in parse
    loader.exec_module(new_module)
  File "<frozen importlib._bootstrap_external>", line 999, in exec_module
  File "<frozen importlib._bootstrap>", line 488, in _call_with_frames_removed
  File "/opt/airflow/dags/device_config_dag.py", line 4, in <module>
    from tasks.ingest import Ingestion
  File "/opt/airflow/dags/tasks/ingest.py", line 4, in <module>
    import pandas as pd
  File "/home/airflow/.local/lib/python3.12/site-packages/pandas/__init__.py", line 23, in <module>
    from pandas.compat import (
  File "/home/airflow/.local/lib/python3.12/site-packages/pandas/compat/__init__.py", line 27, in <module>
    from pandas.compat.pyarrow import (
  File "/home/airflow/.local/lib/python3.12/site-packages/pandas/compat/pyarrow.py", line 8, in <module>
    import pyarrow as pa
  File "/home/airflow/.local/lib/python3.12/site-packages/pyarrow/__init__.py", line 65, in <module>
    import pyarrow.lib as _lib
  File "<frozen importlib._bootstrap>", line 645, in parent
  File "/home/airflow/.local/lib/python3.12/site-packages/airflow/utils/timeout.py", line 69, in handle_timeout
    raise AirflowTaskTimeout(self.error_message)
airflow.exceptions.AirflowTaskTimeout: DagBag import timeout for /opt/airflow/dags/device_config_dag.py after 30.0s.
Please take a look at these docs to improve your DAG import time:
* https://airflow.apache.org/docs/apache-airflow/2.10.4/best-practices.html#top-level-python-code
* https://airflow.apache.org/docs/apache-airflow/2.10.4/best-practices.html#reducing-dag-complexity, PID: 2260
[2025-10-05T00:26:48.474+0000] {processor.py:927} WARNING - No viable dags retrieved from /opt/airflow/dags/device_config_dag.py
[2025-10-05T00:27:19.396+0000] {processor.py:186} INFO - Started process (PID=2273) to work on /opt/airflow/dags/device_config_dag.py
[2025-10-05T00:27:19.399+0000] {processor.py:914} INFO - Processing file /opt/airflow/dags/device_config_dag.py for tasks to queue
[2025-10-05T00:27:19.402+0000] {logging_mixin.py:190} INFO - [2025-10-05T00:27:19.401+0000] {dagbag.py:588} INFO - Filling up the DagBag from /opt/airflow/dags/device_config_dag.py
[2025-10-05T00:27:21.261+0000] {processor.py:925} INFO - DAG(s) 'device_config_pipeline' retrieved from /opt/airflow/dags/device_config_dag.py
[2025-10-05T00:27:21.785+0000] {logging_mixin.py:190} INFO - [2025-10-05T00:27:21.783+0000] {dag.py:3239} INFO - Sync 1 DAGs
[2025-10-05T00:27:22.171+0000] {processor.py:208} INFO - Processing /opt/airflow/dags/device_config_dag.py took 4.236 seconds
[2025-10-05T00:27:52.565+0000] {processor.py:186} INFO - Started process (PID=2300) to work on /opt/airflow/dags/device_config_dag.py
[2025-10-05T00:27:52.569+0000] {processor.py:914} INFO - Processing file /opt/airflow/dags/device_config_dag.py for tasks to queue
[2025-10-05T00:27:52.573+0000] {logging_mixin.py:190} INFO - [2025-10-05T00:27:52.572+0000] {dagbag.py:588} INFO - Filling up the DagBag from /opt/airflow/dags/device_config_dag.py
[2025-10-05T00:27:56.529+0000] {processor.py:925} INFO - DAG(s) 'device_config_pipeline' retrieved from /opt/airflow/dags/device_config_dag.py
[2025-10-05T00:27:57.382+0000] {logging_mixin.py:190} INFO - [2025-10-05T00:27:57.365+0000] {dag.py:3239} INFO - Sync 1 DAGs
[2025-10-05T00:27:57.641+0000] {processor.py:208} INFO - Processing /opt/airflow/dags/device_config_dag.py took 5.103 seconds
[2025-10-05T00:28:28.088+0000] {processor.py:186} INFO - Started process (PID=2327) to work on /opt/airflow/dags/device_config_dag.py
[2025-10-05T00:28:28.102+0000] {processor.py:914} INFO - Processing file /opt/airflow/dags/device_config_dag.py for tasks to queue
[2025-10-05T00:28:28.132+0000] {logging_mixin.py:190} INFO - [2025-10-05T00:28:28.114+0000] {dagbag.py:588} INFO - Filling up the DagBag from /opt/airflow/dags/device_config_dag.py
[2025-10-05T00:28:32.425+0000] {processor.py:925} INFO - DAG(s) 'device_config_pipeline' retrieved from /opt/airflow/dags/device_config_dag.py
[2025-10-05T00:28:32.968+0000] {logging_mixin.py:190} INFO - [2025-10-05T00:28:32.957+0000] {dag.py:3239} INFO - Sync 1 DAGs
[2025-10-05T00:28:33.266+0000] {processor.py:208} INFO - Processing /opt/airflow/dags/device_config_dag.py took 5.325 seconds
[2025-10-05T00:29:03.854+0000] {processor.py:186} INFO - Started process (PID=2354) to work on /opt/airflow/dags/device_config_dag.py
[2025-10-05T00:29:03.859+0000] {processor.py:914} INFO - Processing file /opt/airflow/dags/device_config_dag.py for tasks to queue
[2025-10-05T00:29:03.870+0000] {logging_mixin.py:190} INFO - [2025-10-05T00:29:03.863+0000] {dagbag.py:588} INFO - Filling up the DagBag from /opt/airflow/dags/device_config_dag.py
[2025-10-05T00:29:08.048+0000] {processor.py:925} INFO - DAG(s) 'device_config_pipeline' retrieved from /opt/airflow/dags/device_config_dag.py
[2025-10-05T00:29:08.469+0000] {logging_mixin.py:190} INFO - [2025-10-05T00:29:08.455+0000] {dag.py:3239} INFO - Sync 1 DAGs
[2025-10-05T00:29:08.653+0000] {processor.py:208} INFO - Processing /opt/airflow/dags/device_config_dag.py took 4.853 seconds
[2025-10-05T00:29:39.294+0000] {processor.py:186} INFO - Started process (PID=2381) to work on /opt/airflow/dags/device_config_dag.py
[2025-10-05T00:29:39.299+0000] {processor.py:914} INFO - Processing file /opt/airflow/dags/device_config_dag.py for tasks to queue
[2025-10-05T00:29:39.311+0000] {logging_mixin.py:190} INFO - [2025-10-05T00:29:39.304+0000] {dagbag.py:588} INFO - Filling up the DagBag from /opt/airflow/dags/device_config_dag.py
[2025-10-05T00:29:44.012+0000] {processor.py:925} INFO - DAG(s) 'device_config_pipeline' retrieved from /opt/airflow/dags/device_config_dag.py
[2025-10-05T00:29:44.589+0000] {logging_mixin.py:190} INFO - [2025-10-05T00:29:44.579+0000] {dag.py:3239} INFO - Sync 1 DAGs
[2025-10-05T00:29:48.077+0000] {processor.py:208} INFO - Processing /opt/airflow/dags/device_config_dag.py took 9.610 seconds
[2025-10-05T00:30:18.876+0000] {processor.py:186} INFO - Started process (PID=2408) to work on /opt/airflow/dags/device_config_dag.py
[2025-10-05T00:30:18.883+0000] {processor.py:914} INFO - Processing file /opt/airflow/dags/device_config_dag.py for tasks to queue
[2025-10-05T00:30:18.895+0000] {logging_mixin.py:190} INFO - [2025-10-05T00:30:18.888+0000] {dagbag.py:588} INFO - Filling up the DagBag from /opt/airflow/dags/device_config_dag.py
[2025-10-05T00:30:22.559+0000] {processor.py:925} INFO - DAG(s) 'device_config_pipeline' retrieved from /opt/airflow/dags/device_config_dag.py
[2025-10-05T00:30:22.935+0000] {logging_mixin.py:190} INFO - [2025-10-05T00:30:22.926+0000] {dag.py:3239} INFO - Sync 1 DAGs
[2025-10-05T00:30:23.088+0000] {processor.py:208} INFO - Processing /opt/airflow/dags/device_config_dag.py took 4.268 seconds
[2025-10-05T00:30:53.783+0000] {processor.py:186} INFO - Started process (PID=2435) to work on /opt/airflow/dags/device_config_dag.py
[2025-10-05T00:30:53.794+0000] {processor.py:914} INFO - Processing file /opt/airflow/dags/device_config_dag.py for tasks to queue
[2025-10-05T00:30:53.805+0000] {logging_mixin.py:190} INFO - [2025-10-05T00:30:53.799+0000] {dagbag.py:588} INFO - Filling up the DagBag from /opt/airflow/dags/device_config_dag.py
[2025-10-05T00:30:57.975+0000] {processor.py:925} INFO - DAG(s) 'device_config_pipeline' retrieved from /opt/airflow/dags/device_config_dag.py
[2025-10-05T00:30:58.500+0000] {logging_mixin.py:190} INFO - [2025-10-05T00:30:58.480+0000] {dag.py:3239} INFO - Sync 1 DAGs
[2025-10-05T00:30:58.743+0000] {processor.py:208} INFO - Processing /opt/airflow/dags/device_config_dag.py took 5.000 seconds
[2025-10-05T00:31:29.447+0000] {processor.py:186} INFO - Started process (PID=2462) to work on /opt/airflow/dags/device_config_dag.py
[2025-10-05T00:31:29.453+0000] {processor.py:914} INFO - Processing file /opt/airflow/dags/device_config_dag.py for tasks to queue
[2025-10-05T00:31:29.468+0000] {logging_mixin.py:190} INFO - [2025-10-05T00:31:29.459+0000] {dagbag.py:588} INFO - Filling up the DagBag from /opt/airflow/dags/device_config_dag.py
[2025-10-05T00:31:33.983+0000] {processor.py:925} INFO - DAG(s) 'device_config_pipeline' retrieved from /opt/airflow/dags/device_config_dag.py
[2025-10-05T00:31:34.367+0000] {logging_mixin.py:190} INFO - [2025-10-05T00:31:34.357+0000] {dag.py:3239} INFO - Sync 1 DAGs
[2025-10-05T00:31:34.525+0000] {processor.py:208} INFO - Processing /opt/airflow/dags/device_config_dag.py took 5.126 seconds
[2025-10-05T00:32:05.375+0000] {processor.py:186} INFO - Started process (PID=2493) to work on /opt/airflow/dags/device_config_dag.py
[2025-10-05T00:32:05.382+0000] {processor.py:914} INFO - Processing file /opt/airflow/dags/device_config_dag.py for tasks to queue
[2025-10-05T00:32:05.394+0000] {logging_mixin.py:190} INFO - [2025-10-05T00:32:05.388+0000] {dagbag.py:588} INFO - Filling up the DagBag from /opt/airflow/dags/device_config_dag.py
[2025-10-05T02:49:28.328+0000] {logging_mixin.py:190} INFO - [2025-10-05T02:49:27.728+0000] {timeout.py:68} ERROR - Process timed out, PID: 2493
[2025-10-05T02:49:28.887+0000] {logging_mixin.py:190} INFO - [2025-10-05T02:49:28.388+0000] {dagbag.py:387} ERROR - Failed to import: /opt/airflow/dags/device_config_dag.py
Traceback (most recent call last):
  File "/home/airflow/.local/lib/python3.12/site-packages/airflow/models/dagbag.py", line 383, in parse
    loader.exec_module(new_module)
  File "<frozen importlib._bootstrap_external>", line 999, in exec_module
  File "<frozen importlib._bootstrap>", line 488, in _call_with_frames_removed
  File "/opt/airflow/dags/device_config_dag.py", line 4, in <module>
    from tasks.ingest import Ingestion
  File "/opt/airflow/dags/tasks/ingest.py", line 4, in <module>
    import pandas as pd
  File "/home/airflow/.local/lib/python3.12/site-packages/pandas/__init__.py", line 46, in <module>
    from pandas.core.api import (
  File "/home/airflow/.local/lib/python3.12/site-packages/pandas/core/api.py", line 28, in <module>
    from pandas.core.arrays import Categorical
  File "/home/airflow/.local/lib/python3.12/site-packages/pandas/core/arrays/__init__.py", line 1, in <module>
    from pandas.core.arrays.arrow import ArrowExtensionArray
  File "/home/airflow/.local/lib/python3.12/site-packages/pandas/core/arrays/arrow/__init__.py", line 1, in <module>
    from pandas.core.arrays.arrow.array import ArrowExtensionArray
  File "/home/airflow/.local/lib/python3.12/site-packages/pandas/core/arrays/arrow/array.py", line 52, in <module>
    from pandas.core.arrays._arrow_string_mixins import ArrowStringArrayMixin
  File "/home/airflow/.local/lib/python3.12/site-packages/pandas/core/arrays/_arrow_string_mixins.py", line 11, in <module>
    import pyarrow.compute as pc
  File "/home/airflow/.local/lib/python3.12/site-packages/pyarrow/compute.py", line 18, in <module>
    from pyarrow._compute import (  # noqa
  File "pyarrow/_compute.pyx", line 1513, in init pyarrow._compute
  File "pyarrow/_compute.pyx", line 837, in pyarrow._compute._min_count_doc
  File "/home/airflow/.local/lib/python3.12/site-packages/airflow/utils/timeout.py", line 69, in handle_timeout
    raise AirflowTaskTimeout(self.error_message)
airflow.exceptions.AirflowTaskTimeout: DagBag import timeout for /opt/airflow/dags/device_config_dag.py after 30.0s.
Please take a look at these docs to improve your DAG import time:
* https://airflow.apache.org/docs/apache-airflow/2.10.4/best-practices.html#top-level-python-code
* https://airflow.apache.org/docs/apache-airflow/2.10.4/best-practices.html#reducing-dag-complexity, PID: 2493
[2025-10-05T02:49:29.070+0000] {processor.py:927} WARNING - No viable dags retrieved from /opt/airflow/dags/device_config_dag.py
[2025-10-05T02:49:31.095+0000] {processor.py:208} INFO - Processing /opt/airflow/dags/device_config_dag.py took 237.444 seconds
[2025-10-05T02:50:02.775+0000] {processor.py:186} INFO - Started process (PID=2506) to work on /opt/airflow/dags/device_config_dag.py
[2025-10-05T02:50:02.780+0000] {processor.py:914} INFO - Processing file /opt/airflow/dags/device_config_dag.py for tasks to queue
[2025-10-05T02:50:02.792+0000] {logging_mixin.py:190} INFO - [2025-10-05T02:50:02.785+0000] {dagbag.py:588} INFO - Filling up the DagBag from /opt/airflow/dags/device_config_dag.py
[2025-10-05T02:50:08.353+0000] {processor.py:925} INFO - DAG(s) 'device_config_pipeline' retrieved from /opt/airflow/dags/device_config_dag.py
[2025-10-05T02:50:09.843+0000] {logging_mixin.py:190} INFO - [2025-10-05T02:50:09.832+0000] {dag.py:3239} INFO - Sync 1 DAGs
[2025-10-05T02:50:11.172+0000] {processor.py:208} INFO - Processing /opt/airflow/dags/device_config_dag.py took 8.465 seconds
[2025-10-05T03:01:00.414+0000] {processor.py:186} INFO - Started process (PID=2535) to work on /opt/airflow/dags/device_config_dag.py
[2025-10-05T03:01:00.420+0000] {processor.py:914} INFO - Processing file /opt/airflow/dags/device_config_dag.py for tasks to queue
[2025-10-05T03:01:00.429+0000] {logging_mixin.py:190} INFO - [2025-10-05T03:01:00.427+0000] {dagbag.py:588} INFO - Filling up the DagBag from /opt/airflow/dags/device_config_dag.py
[2025-10-05T03:01:03.290+0000] {processor.py:925} INFO - DAG(s) 'device_config_pipeline' retrieved from /opt/airflow/dags/device_config_dag.py
[2025-10-05T03:01:03.664+0000] {logging_mixin.py:190} INFO - [2025-10-05T03:01:03.647+0000] {dag.py:3239} INFO - Sync 1 DAGs
[2025-10-05T03:01:03.948+0000] {processor.py:208} INFO - Processing /opt/airflow/dags/device_config_dag.py took 5.232 seconds
[2025-10-05T03:01:34.586+0000] {processor.py:186} INFO - Started process (PID=2562) to work on /opt/airflow/dags/device_config_dag.py
[2025-10-05T03:01:34.589+0000] {processor.py:914} INFO - Processing file /opt/airflow/dags/device_config_dag.py for tasks to queue
[2025-10-05T03:01:34.598+0000] {logging_mixin.py:190} INFO - [2025-10-05T03:01:34.593+0000] {dagbag.py:588} INFO - Filling up the DagBag from /opt/airflow/dags/device_config_dag.py
[2025-10-05T03:01:39.212+0000] {processor.py:925} INFO - DAG(s) 'device_config_pipeline' retrieved from /opt/airflow/dags/device_config_dag.py
[2025-10-05T03:01:41.343+0000] {logging_mixin.py:190} INFO - [2025-10-05T03:01:41.330+0000] {dag.py:3239} INFO - Sync 1 DAGs
[2025-10-05T03:01:41.590+0000] {processor.py:208} INFO - Processing /opt/airflow/dags/device_config_dag.py took 7.035 seconds
[2025-10-05T03:02:23.529+0000] {processor.py:186} INFO - Started process (PID=2581) to work on /opt/airflow/dags/device_config_dag.py
[2025-10-05T03:02:23.534+0000] {processor.py:914} INFO - Processing file /opt/airflow/dags/device_config_dag.py for tasks to queue
[2025-10-05T03:02:23.550+0000] {logging_mixin.py:190} INFO - [2025-10-05T03:02:23.543+0000] {dagbag.py:588} INFO - Filling up the DagBag from /opt/airflow/dags/device_config_dag.py
[2025-10-05T07:57:48.609+0000] {logging_mixin.py:190} INFO - [2025-10-05T07:57:48.114+0000] {timeout.py:68} ERROR - Process timed out, PID: 2581
[2025-10-05T07:57:49.009+0000] {logging_mixin.py:190} INFO - [2025-10-05T07:57:48.760+0000] {dagbag.py:387} ERROR - Failed to import: /opt/airflow/dags/device_config_dag.py
Traceback (most recent call last):
  File "/home/airflow/.local/lib/python3.12/site-packages/airflow/models/dagbag.py", line 383, in parse
    loader.exec_module(new_module)
  File "<frozen importlib._bootstrap_external>", line 999, in exec_module
  File "<frozen importlib._bootstrap>", line 488, in _call_with_frames_removed
  File "/opt/airflow/dags/device_config_dag.py", line 4, in <module>
    from tasks.ingest import Ingestion
  File "/opt/airflow/dags/tasks/ingest.py", line 4, in <module>
    import pandas as pd
  File "/home/airflow/.local/lib/python3.12/site-packages/pandas/__init__.py", line 46, in <module>
    from pandas.core.api import (
  File "/home/airflow/.local/lib/python3.12/site-packages/pandas/core/api.py", line 28, in <module>
    from pandas.core.arrays import Categorical
  File "/home/airflow/.local/lib/python3.12/site-packages/pandas/core/arrays/__init__.py", line 1, in <module>
    from pandas.core.arrays.arrow import ArrowExtensionArray
  File "/home/airflow/.local/lib/python3.12/site-packages/pandas/core/arrays/arrow/__init__.py", line 1, in <module>
    from pandas.core.arrays.arrow.array import ArrowExtensionArray
  File "/home/airflow/.local/lib/python3.12/site-packages/pandas/core/arrays/arrow/array.py", line 52, in <module>
    from pandas.core.arrays._arrow_string_mixins import ArrowStringArrayMixin
  File "/home/airflow/.local/lib/python3.12/site-packages/pandas/core/arrays/_arrow_string_mixins.py", line 11, in <module>
    import pyarrow.compute as pc
  File "/home/airflow/.local/lib/python3.12/site-packages/pyarrow/compute.py", line 18, in <module>
    from pyarrow._compute import (  # noqa
  File "pyarrow/_compute.pyx", line 1513, in init pyarrow._compute
  File "pyarrow/_compute.pyx", line 837, in pyarrow._compute._min_count_doc
  File "/home/airflow/.local/lib/python3.12/site-packages/airflow/utils/timeout.py", line 69, in handle_timeout
    raise AirflowTaskTimeout(self.error_message)
airflow.exceptions.AirflowTaskTimeout: DagBag import timeout for /opt/airflow/dags/device_config_dag.py after 30.0s.
Please take a look at these docs to improve your DAG import time:
* https://airflow.apache.org/docs/apache-airflow/2.10.4/best-practices.html#top-level-python-code
* https://airflow.apache.org/docs/apache-airflow/2.10.4/best-practices.html#reducing-dag-complexity, PID: 2581
[2025-10-05T07:57:49.211+0000] {processor.py:927} WARNING - No viable dags retrieved from /opt/airflow/dags/device_config_dag.py
[2025-10-05T07:57:59.689+0000] {processor.py:211} ERROR - Got an exception! Propagating...
Traceback (most recent call last):
  File "/home/airflow/.local/lib/python3.12/site-packages/sqlalchemy/engine/base.py", line 3371, in _wrap_pool_connect
    return fn()
           ^^^^
  File "/home/airflow/.local/lib/python3.12/site-packages/sqlalchemy/pool/base.py", line 327, in connect
    return _ConnectionFairy._checkout(self)
           ^^^^^^^^^^^^^^^^^^^^^^^^^^^^^^^^
  File "/home/airflow/.local/lib/python3.12/site-packages/sqlalchemy/pool/base.py", line 894, in _checkout
    fairy = _ConnectionRecord.checkout(pool)
            ^^^^^^^^^^^^^^^^^^^^^^^^^^^^^^^^
  File "/home/airflow/.local/lib/python3.12/site-packages/sqlalchemy/pool/base.py", line 493, in checkout
    rec = pool._do_get()
          ^^^^^^^^^^^^^^
  File "/home/airflow/.local/lib/python3.12/site-packages/sqlalchemy/pool/impl.py", line 145, in _do_get
    with util.safe_reraise():
         ^^^^^^^^^^^^^^^^^^^
  File "/home/airflow/.local/lib/python3.12/site-packages/sqlalchemy/util/langhelpers.py", line 70, in __exit__
    compat.raise_(
  File "/home/airflow/.local/lib/python3.12/site-packages/sqlalchemy/util/compat.py", line 211, in raise_
    raise exception
  File "/home/airflow/.local/lib/python3.12/site-packages/sqlalchemy/pool/impl.py", line 143, in _do_get
    return self._create_connection()
           ^^^^^^^^^^^^^^^^^^^^^^^^^
  File "/home/airflow/.local/lib/python3.12/site-packages/sqlalchemy/pool/base.py", line 273, in _create_connection
    return _ConnectionRecord(self)
           ^^^^^^^^^^^^^^^^^^^^^^^
  File "/home/airflow/.local/lib/python3.12/site-packages/sqlalchemy/pool/base.py", line 388, in __init__
    self.__connect()
  File "/home/airflow/.local/lib/python3.12/site-packages/sqlalchemy/pool/base.py", line 690, in __connect
    with util.safe_reraise():
         ^^^^^^^^^^^^^^^^^^^
  File "/home/airflow/.local/lib/python3.12/site-packages/sqlalchemy/util/langhelpers.py", line 70, in __exit__
    compat.raise_(
  File "/home/airflow/.local/lib/python3.12/site-packages/sqlalchemy/util/compat.py", line 211, in raise_
    raise exception
  File "/home/airflow/.local/lib/python3.12/site-packages/sqlalchemy/pool/base.py", line 686, in __connect
    self.dbapi_connection = connection = pool._invoke_creator(self)
                                         ^^^^^^^^^^^^^^^^^^^^^^^^^^
  File "/home/airflow/.local/lib/python3.12/site-packages/sqlalchemy/engine/create.py", line 574, in connect
    return dialect.connect(*cargs, **cparams)
           ^^^^^^^^^^^^^^^^^^^^^^^^^^^^^^^^^^
  File "/home/airflow/.local/lib/python3.12/site-packages/sqlalchemy/engine/default.py", line 598, in connect
    return self.dbapi.connect(*cargs, **cparams)
           ^^^^^^^^^^^^^^^^^^^^^^^^^^^^^^^^^^^^^
  File "/home/airflow/.local/lib/python3.12/site-packages/psycopg2/__init__.py", line 122, in connect
    conn = _connect(dsn, connection_factory=connection_factory, **kwasync)
           ^^^^^^^^^^^^^^^^^^^^^^^^^^^^^^^^^^^^^^^^^^^^^^^^^^^^^^^^^^^^^^^
psycopg2.OperationalError: could not translate host name "postgres" to address: Temporary failure in name resolution


The above exception was the direct cause of the following exception:

Traceback (most recent call last):
  File "/home/airflow/.local/lib/python3.12/site-packages/airflow/dag_processing/processor.py", line 207, in _run_file_processor
    _handle_dag_file_processing()
  File "/home/airflow/.local/lib/python3.12/site-packages/airflow/dag_processing/processor.py", line 188, in _handle_dag_file_processing
    result: tuple[int, int, int] = dag_file_processor.process_file(
                                   ^^^^^^^^^^^^^^^^^^^^^^^^^^^^^^^^
  File "/home/airflow/.local/lib/python3.12/site-packages/airflow/utils/session.py", line 97, in wrapper
    return func(*args, session=session, **kwargs)
           ^^^^^^^^^^^^^^^^^^^^^^^^^^^^^^^^^^^^^^
  File "/home/airflow/.local/lib/python3.12/site-packages/airflow/dag_processing/processor.py", line 928, in process_file
    DagFileProcessor.update_import_errors(
  File "/home/airflow/.local/lib/python3.12/site-packages/airflow/api_internal/internal_api_call.py", line 166, in wrapper
    return func(*args, **kwargs)
           ^^^^^^^^^^^^^^^^^^^^^
  File "/home/airflow/.local/lib/python3.12/site-packages/airflow/utils/session.py", line 97, in wrapper
    return func(*args, session=session, **kwargs)
           ^^^^^^^^^^^^^^^^^^^^^^^^^^^^^^^^^^^^^^
  File "/home/airflow/.local/lib/python3.12/site-packages/airflow/dag_processing/processor.py", line 648, in update_import_errors
    existing_import_error_files = [x.filename for x in session.query(ParseImportError.filename).all()]
                                                       ^^^^^^^^^^^^^^^^^^^^^^^^^^^^^^^^^^^^^^^^^^^^^^
  File "/home/airflow/.local/lib/python3.12/site-packages/sqlalchemy/orm/query.py", line 2773, in all
    return self._iter().all()
           ^^^^^^^^^^^^
  File "/home/airflow/.local/lib/python3.12/site-packages/sqlalchemy/orm/query.py", line 2916, in _iter
    result = self.session.execute(
             ^^^^^^^^^^^^^^^^^^^^^
  File "/home/airflow/.local/lib/python3.12/site-packages/sqlalchemy/orm/session.py", line 1716, in execute
    conn = self._connection_for_bind(bind)
           ^^^^^^^^^^^^^^^^^^^^^^^^^^^^^^^
  File "/home/airflow/.local/lib/python3.12/site-packages/sqlalchemy/orm/session.py", line 1555, in _connection_for_bind
    return self._transaction._connection_for_bind(
           ^^^^^^^^^^^^^^^^^^^^^^^^^^^^^^^^^^^^^^^
  File "/home/airflow/.local/lib/python3.12/site-packages/sqlalchemy/orm/session.py", line 750, in _connection_for_bind
    conn = bind.connect()
           ^^^^^^^^^^^^^^
  File "/home/airflow/.local/lib/python3.12/site-packages/sqlalchemy/future/engine.py", line 412, in connect
    return super(Engine, self).connect()
           ^^^^^^^^^^^^^^^^^^^^^^^^^^^^^
  File "/home/airflow/.local/lib/python3.12/site-packages/sqlalchemy/engine/base.py", line 3325, in connect
    return self._connection_cls(self, close_with_result=close_with_result)
           ^^^^^^^^^^^^^^^^^^^^^^^^^^^^^^^^^^^^^^^^^^^^^^^^^^^^^^^^^^^^^^^
  File "/home/airflow/.local/lib/python3.12/site-packages/sqlalchemy/engine/base.py", line 96, in __init__
    else engine.raw_connection()
         ^^^^^^^^^^^^^^^^^^^^^^^
  File "/home/airflow/.local/lib/python3.12/site-packages/sqlalchemy/engine/base.py", line 3404, in raw_connection
    return self._wrap_pool_connect(self.pool.connect, _connection)
           ^^^^^^^^^^^^^^^^^^^^^^^^^^^^^^^^^^^^^^^^^^^^^^^^^^^^^^^
  File "/home/airflow/.local/lib/python3.12/site-packages/sqlalchemy/engine/base.py", line 3374, in _wrap_pool_connect
    Connection._handle_dbapi_exception_noconnection(
  File "/home/airflow/.local/lib/python3.12/site-packages/sqlalchemy/engine/base.py", line 2208, in _handle_dbapi_exception_noconnection
    util.raise_(
  File "/home/airflow/.local/lib/python3.12/site-packages/sqlalchemy/util/compat.py", line 211, in raise_
    raise exception
  File "/home/airflow/.local/lib/python3.12/site-packages/sqlalchemy/engine/base.py", line 3371, in _wrap_pool_connect
    return fn()
           ^^^^
  File "/home/airflow/.local/lib/python3.12/site-packages/sqlalchemy/pool/base.py", line 327, in connect
    return _ConnectionFairy._checkout(self)
           ^^^^^^^^^^^^^^^^^^^^^^^^^^^^^^^^
  File "/home/airflow/.local/lib/python3.12/site-packages/sqlalchemy/pool/base.py", line 894, in _checkout
    fairy = _ConnectionRecord.checkout(pool)
            ^^^^^^^^^^^^^^^^^^^^^^^^^^^^^^^^
  File "/home/airflow/.local/lib/python3.12/site-packages/sqlalchemy/pool/base.py", line 493, in checkout
    rec = pool._do_get()
          ^^^^^^^^^^^^^^
  File "/home/airflow/.local/lib/python3.12/site-packages/sqlalchemy/pool/impl.py", line 145, in _do_get
    with util.safe_reraise():
         ^^^^^^^^^^^^^^^^^^^
  File "/home/airflow/.local/lib/python3.12/site-packages/sqlalchemy/util/langhelpers.py", line 70, in __exit__
    compat.raise_(
  File "/home/airflow/.local/lib/python3.12/site-packages/sqlalchemy/util/compat.py", line 211, in raise_
    raise exception
  File "/home/airflow/.local/lib/python3.12/site-packages/sqlalchemy/pool/impl.py", line 143, in _do_get
    return self._create_connection()
           ^^^^^^^^^^^^^^^^^^^^^^^^^
  File "/home/airflow/.local/lib/python3.12/site-packages/sqlalchemy/pool/base.py", line 273, in _create_connection
    return _ConnectionRecord(self)
           ^^^^^^^^^^^^^^^^^^^^^^^
  File "/home/airflow/.local/lib/python3.12/site-packages/sqlalchemy/pool/base.py", line 388, in __init__
    self.__connect()
  File "/home/airflow/.local/lib/python3.12/site-packages/sqlalchemy/pool/base.py", line 690, in __connect
    with util.safe_reraise():
         ^^^^^^^^^^^^^^^^^^^
  File "/home/airflow/.local/lib/python3.12/site-packages/sqlalchemy/util/langhelpers.py", line 70, in __exit__
    compat.raise_(
  File "/home/airflow/.local/lib/python3.12/site-packages/sqlalchemy/util/compat.py", line 211, in raise_
    raise exception
  File "/home/airflow/.local/lib/python3.12/site-packages/sqlalchemy/pool/base.py", line 686, in __connect
    self.dbapi_connection = connection = pool._invoke_creator(self)
                                         ^^^^^^^^^^^^^^^^^^^^^^^^^^
  File "/home/airflow/.local/lib/python3.12/site-packages/sqlalchemy/engine/create.py", line 574, in connect
    return dialect.connect(*cargs, **cparams)
           ^^^^^^^^^^^^^^^^^^^^^^^^^^^^^^^^^^
  File "/home/airflow/.local/lib/python3.12/site-packages/sqlalchemy/engine/default.py", line 598, in connect
    return self.dbapi.connect(*cargs, **cparams)
           ^^^^^^^^^^^^^^^^^^^^^^^^^^^^^^^^^^^^^
  File "/home/airflow/.local/lib/python3.12/site-packages/psycopg2/__init__.py", line 122, in connect
    conn = _connect(dsn, connection_factory=connection_factory, **kwasync)
           ^^^^^^^^^^^^^^^^^^^^^^^^^^^^^^^^^^^^^^^^^^^^^^^^^^^^^^^^^^^^^^^
sqlalchemy.exc.OperationalError: (psycopg2.OperationalError) could not translate host name "postgres" to address: Temporary failure in name resolution

(Background on this error at: https://sqlalche.me/e/14/e3q8)
