[2025-10-05T00:00:29.006+0000] {processor.py:186} INFO - Started process (PID=1124) to work on /opt/airflow/dags/telemetry_processing_dag.py
[2025-10-05T00:00:29.008+0000] {processor.py:914} INFO - Processing file /opt/airflow/dags/telemetry_processing_dag.py for tasks to queue
[2025-10-05T00:00:29.011+0000] {logging_mixin.py:190} INFO - [2025-10-05T00:00:29.010+0000] {dagbag.py:588} INFO - Filling up the DagBag from /opt/airflow/dags/telemetry_processing_dag.py
[2025-10-05T00:00:30.325+0000] {logging_mixin.py:190} INFO - [2025-10-05T00:00:30.308+0000] {dagbag.py:387} ERROR - Failed to import: /opt/airflow/dags/telemetry_processing_dag.py
Traceback (most recent call last):
  File "/home/airflow/.local/lib/python3.12/site-packages/airflow/models/dagbag.py", line 383, in parse
    loader.exec_module(new_module)
  File "<frozen importlib._bootstrap_external>", line 999, in exec_module
  File "<frozen importlib._bootstrap>", line 488, in _call_with_frames_removed
  File "/opt/airflow/dags/telemetry_processing_dag.py", line 10, in <module>
    from tasks.load import IcebergStorage
  File "/opt/airflow/dags/tasks/load.py", line 7, in <module>
    from dags.tasks.config.settings import ICEBERG_STORAGE, BYTES_SIZE, TARGET_FILE_SIZE_MB
ImportError: cannot import name 'ICEBERG_STORAGE' from 'dags.tasks.config.settings' (/opt/airflow/dags/tasks/config/settings.py)
[2025-10-05T00:00:30.329+0000] {processor.py:927} WARNING - No viable dags retrieved from /opt/airflow/dags/telemetry_processing_dag.py
[2025-10-05T00:00:30.362+0000] {processor.py:208} INFO - Processing /opt/airflow/dags/telemetry_processing_dag.py took 1.370 seconds
[2025-10-05T00:01:01.109+0000] {processor.py:186} INFO - Started process (PID=1150) to work on /opt/airflow/dags/telemetry_processing_dag.py
[2025-10-05T00:01:01.120+0000] {processor.py:914} INFO - Processing file /opt/airflow/dags/telemetry_processing_dag.py for tasks to queue
[2025-10-05T00:01:01.128+0000] {logging_mixin.py:190} INFO - [2025-10-05T00:01:01.127+0000] {dagbag.py:588} INFO - Filling up the DagBag from /opt/airflow/dags/telemetry_processing_dag.py
[2025-10-05T00:01:03.143+0000] {logging_mixin.py:190} INFO - [2025-10-05T00:01:03.073+0000] {dagbag.py:387} ERROR - Failed to import: /opt/airflow/dags/telemetry_processing_dag.py
Traceback (most recent call last):
  File "/home/airflow/.local/lib/python3.12/site-packages/airflow/models/dagbag.py", line 383, in parse
    loader.exec_module(new_module)
  File "<frozen importlib._bootstrap_external>", line 999, in exec_module
  File "<frozen importlib._bootstrap>", line 488, in _call_with_frames_removed
  File "/opt/airflow/dags/telemetry_processing_dag.py", line 10, in <module>
    from tasks.load import IcebergStorage
  File "/opt/airflow/dags/tasks/load.py", line 7, in <module>
    from dags.tasks.config.settings import ICEBERG_STORAGE, BYTES_SIZE, TARGET_FILE_SIZE_MB
ImportError: cannot import name 'ICEBERG_STORAGE' from 'dags.tasks.config.settings' (/opt/airflow/dags/tasks/config/settings.py)
[2025-10-05T00:01:03.154+0000] {processor.py:927} WARNING - No viable dags retrieved from /opt/airflow/dags/telemetry_processing_dag.py
[2025-10-05T00:01:03.556+0000] {processor.py:208} INFO - Processing /opt/airflow/dags/telemetry_processing_dag.py took 2.487 seconds
[2025-10-05T00:01:34.096+0000] {processor.py:186} INFO - Started process (PID=1177) to work on /opt/airflow/dags/telemetry_processing_dag.py
[2025-10-05T00:01:34.098+0000] {processor.py:914} INFO - Processing file /opt/airflow/dags/telemetry_processing_dag.py for tasks to queue
[2025-10-05T00:01:34.102+0000] {logging_mixin.py:190} INFO - [2025-10-05T00:01:34.101+0000] {dagbag.py:588} INFO - Filling up the DagBag from /opt/airflow/dags/telemetry_processing_dag.py
[2025-10-05T00:01:35.271+0000] {logging_mixin.py:190} INFO - [2025-10-05T00:01:35.252+0000] {dagbag.py:387} ERROR - Failed to import: /opt/airflow/dags/telemetry_processing_dag.py
Traceback (most recent call last):
  File "/home/airflow/.local/lib/python3.12/site-packages/airflow/models/dagbag.py", line 383, in parse
    loader.exec_module(new_module)
  File "<frozen importlib._bootstrap_external>", line 999, in exec_module
  File "<frozen importlib._bootstrap>", line 488, in _call_with_frames_removed
  File "/opt/airflow/dags/telemetry_processing_dag.py", line 10, in <module>
    from tasks.load import IcebergStorage
  File "/opt/airflow/dags/tasks/load.py", line 7, in <module>
    from dags.tasks.config.settings import ICEBERG_STORAGE, BYTES_SIZE, TARGET_FILE_SIZE_MB
ImportError: cannot import name 'ICEBERG_STORAGE' from 'dags.tasks.config.settings' (/opt/airflow/dags/tasks/config/settings.py)
[2025-10-05T00:01:35.275+0000] {processor.py:927} WARNING - No viable dags retrieved from /opt/airflow/dags/telemetry_processing_dag.py
[2025-10-05T00:01:35.314+0000] {processor.py:208} INFO - Processing /opt/airflow/dags/telemetry_processing_dag.py took 1.239 seconds
[2025-10-05T00:02:06.375+0000] {processor.py:186} INFO - Started process (PID=1212) to work on /opt/airflow/dags/telemetry_processing_dag.py
[2025-10-05T00:02:06.379+0000] {processor.py:914} INFO - Processing file /opt/airflow/dags/telemetry_processing_dag.py for tasks to queue
[2025-10-05T00:02:06.383+0000] {logging_mixin.py:190} INFO - [2025-10-05T00:02:06.382+0000] {dagbag.py:588} INFO - Filling up the DagBag from /opt/airflow/dags/telemetry_processing_dag.py
[2025-10-05T00:02:07.497+0000] {logging_mixin.py:190} INFO - [2025-10-05T00:02:07.479+0000] {dagbag.py:387} ERROR - Failed to import: /opt/airflow/dags/telemetry_processing_dag.py
Traceback (most recent call last):
  File "/home/airflow/.local/lib/python3.12/site-packages/airflow/models/dagbag.py", line 383, in parse
    loader.exec_module(new_module)
  File "<frozen importlib._bootstrap_external>", line 999, in exec_module
  File "<frozen importlib._bootstrap>", line 488, in _call_with_frames_removed
  File "/opt/airflow/dags/telemetry_processing_dag.py", line 10, in <module>
    from tasks.load import IcebergStorage
  File "/opt/airflow/dags/tasks/load.py", line 7, in <module>
    from dags.tasks.config.settings import ICEBERG_STORAGE, BYTES_SIZE, TARGET_FILE_SIZE_MB
ImportError: cannot import name 'ICEBERG_STORAGE' from 'dags.tasks.config.settings' (/opt/airflow/dags/tasks/config/settings.py)
[2025-10-05T00:02:07.503+0000] {processor.py:927} WARNING - No viable dags retrieved from /opt/airflow/dags/telemetry_processing_dag.py
[2025-10-05T00:02:07.543+0000] {processor.py:208} INFO - Processing /opt/airflow/dags/telemetry_processing_dag.py took 1.187 seconds
[2025-10-05T00:02:38.383+0000] {processor.py:186} INFO - Started process (PID=1239) to work on /opt/airflow/dags/telemetry_processing_dag.py
[2025-10-05T00:02:38.386+0000] {processor.py:914} INFO - Processing file /opt/airflow/dags/telemetry_processing_dag.py for tasks to queue
[2025-10-05T00:02:38.389+0000] {logging_mixin.py:190} INFO - [2025-10-05T00:02:38.388+0000] {dagbag.py:588} INFO - Filling up the DagBag from /opt/airflow/dags/telemetry_processing_dag.py
[2025-10-05T00:02:39.468+0000] {logging_mixin.py:190} INFO - [2025-10-05T00:02:39.453+0000] {dagbag.py:387} ERROR - Failed to import: /opt/airflow/dags/telemetry_processing_dag.py
Traceback (most recent call last):
  File "/home/airflow/.local/lib/python3.12/site-packages/airflow/models/dagbag.py", line 383, in parse
    loader.exec_module(new_module)
  File "<frozen importlib._bootstrap_external>", line 999, in exec_module
  File "<frozen importlib._bootstrap>", line 488, in _call_with_frames_removed
  File "/opt/airflow/dags/telemetry_processing_dag.py", line 10, in <module>
    from tasks.load import IcebergStorage
  File "/opt/airflow/dags/tasks/load.py", line 7, in <module>
    from dags.tasks.config.settings import ICEBERG_STORAGE, BYTES_SIZE, TARGET_FILE_SIZE_MB
ImportError: cannot import name 'ICEBERG_STORAGE' from 'dags.tasks.config.settings' (/opt/airflow/dags/tasks/config/settings.py)
[2025-10-05T00:02:39.473+0000] {processor.py:927} WARNING - No viable dags retrieved from /opt/airflow/dags/telemetry_processing_dag.py
[2025-10-05T00:02:39.534+0000] {processor.py:208} INFO - Processing /opt/airflow/dags/telemetry_processing_dag.py took 1.167 seconds
[2025-10-05T00:03:10.092+0000] {processor.py:186} INFO - Started process (PID=1266) to work on /opt/airflow/dags/telemetry_processing_dag.py
[2025-10-05T00:03:10.094+0000] {processor.py:914} INFO - Processing file /opt/airflow/dags/telemetry_processing_dag.py for tasks to queue
[2025-10-05T00:03:10.097+0000] {logging_mixin.py:190} INFO - [2025-10-05T00:03:10.097+0000] {dagbag.py:588} INFO - Filling up the DagBag from /opt/airflow/dags/telemetry_processing_dag.py
[2025-10-05T00:03:10.908+0000] {logging_mixin.py:190} INFO - [2025-10-05T00:03:10.893+0000] {dagbag.py:387} ERROR - Failed to import: /opt/airflow/dags/telemetry_processing_dag.py
Traceback (most recent call last):
  File "/home/airflow/.local/lib/python3.12/site-packages/airflow/models/dagbag.py", line 383, in parse
    loader.exec_module(new_module)
  File "<frozen importlib._bootstrap_external>", line 999, in exec_module
  File "<frozen importlib._bootstrap>", line 488, in _call_with_frames_removed
  File "/opt/airflow/dags/telemetry_processing_dag.py", line 10, in <module>
    from tasks.load import IcebergStorage
  File "/opt/airflow/dags/tasks/load.py", line 7, in <module>
    from dags.tasks.config.settings import ICEBERG_STORAGE, BYTES_SIZE, TARGET_FILE_SIZE_MB
ImportError: cannot import name 'ICEBERG_STORAGE' from 'dags.tasks.config.settings' (/opt/airflow/dags/tasks/config/settings.py)
[2025-10-05T00:03:10.913+0000] {processor.py:927} WARNING - No viable dags retrieved from /opt/airflow/dags/telemetry_processing_dag.py
[2025-10-05T00:03:10.947+0000] {processor.py:208} INFO - Processing /opt/airflow/dags/telemetry_processing_dag.py took 0.867 seconds
[2025-10-05T00:03:41.300+0000] {processor.py:186} INFO - Started process (PID=1293) to work on /opt/airflow/dags/telemetry_processing_dag.py
[2025-10-05T00:03:41.303+0000] {processor.py:914} INFO - Processing file /opt/airflow/dags/telemetry_processing_dag.py for tasks to queue
[2025-10-05T00:03:41.309+0000] {logging_mixin.py:190} INFO - [2025-10-05T00:03:41.308+0000] {dagbag.py:588} INFO - Filling up the DagBag from /opt/airflow/dags/telemetry_processing_dag.py
[2025-10-05T00:03:42.600+0000] {logging_mixin.py:190} INFO - [2025-10-05T00:03:42.579+0000] {dagbag.py:387} ERROR - Failed to import: /opt/airflow/dags/telemetry_processing_dag.py
Traceback (most recent call last):
  File "/home/airflow/.local/lib/python3.12/site-packages/airflow/models/dagbag.py", line 383, in parse
    loader.exec_module(new_module)
  File "<frozen importlib._bootstrap_external>", line 999, in exec_module
  File "<frozen importlib._bootstrap>", line 488, in _call_with_frames_removed
  File "/opt/airflow/dags/telemetry_processing_dag.py", line 10, in <module>
    from tasks.load import IcebergStorage
  File "/opt/airflow/dags/tasks/load.py", line 7, in <module>
    from dags.tasks.config.settings import ICEBERG_STORAGE, BYTES_SIZE, TARGET_FILE_SIZE_MB
ImportError: cannot import name 'ICEBERG_STORAGE' from 'dags.tasks.config.settings' (/opt/airflow/dags/tasks/config/settings.py)
[2025-10-05T00:03:42.607+0000] {processor.py:927} WARNING - No viable dags retrieved from /opt/airflow/dags/telemetry_processing_dag.py
[2025-10-05T00:03:42.647+0000] {processor.py:208} INFO - Processing /opt/airflow/dags/telemetry_processing_dag.py took 1.363 seconds
[2025-10-05T00:04:12.785+0000] {processor.py:186} INFO - Started process (PID=1320) to work on /opt/airflow/dags/telemetry_processing_dag.py
[2025-10-05T00:04:12.787+0000] {processor.py:914} INFO - Processing file /opt/airflow/dags/telemetry_processing_dag.py for tasks to queue
[2025-10-05T00:04:12.790+0000] {logging_mixin.py:190} INFO - [2025-10-05T00:04:12.789+0000] {dagbag.py:588} INFO - Filling up the DagBag from /opt/airflow/dags/telemetry_processing_dag.py
[2025-10-05T00:04:13.699+0000] {logging_mixin.py:190} INFO - [2025-10-05T00:04:13.683+0000] {dagbag.py:387} ERROR - Failed to import: /opt/airflow/dags/telemetry_processing_dag.py
Traceback (most recent call last):
  File "/home/airflow/.local/lib/python3.12/site-packages/airflow/models/dagbag.py", line 383, in parse
    loader.exec_module(new_module)
  File "<frozen importlib._bootstrap_external>", line 999, in exec_module
  File "<frozen importlib._bootstrap>", line 488, in _call_with_frames_removed
  File "/opt/airflow/dags/telemetry_processing_dag.py", line 10, in <module>
    from tasks.load import IcebergStorage
  File "/opt/airflow/dags/tasks/load.py", line 7, in <module>
    from dags.tasks.config.settings import ICEBERG_STORAGE, BYTES_SIZE, TARGET_FILE_SIZE_MB
ImportError: cannot import name 'ICEBERG_STORAGE' from 'dags.tasks.config.settings' (/opt/airflow/dags/tasks/config/settings.py)
[2025-10-05T00:04:13.703+0000] {processor.py:927} WARNING - No viable dags retrieved from /opt/airflow/dags/telemetry_processing_dag.py
[2025-10-05T00:04:13.769+0000] {processor.py:208} INFO - Processing /opt/airflow/dags/telemetry_processing_dag.py took 0.999 seconds
[2025-10-05T00:04:43.966+0000] {processor.py:186} INFO - Started process (PID=1347) to work on /opt/airflow/dags/telemetry_processing_dag.py
[2025-10-05T00:04:43.968+0000] {processor.py:914} INFO - Processing file /opt/airflow/dags/telemetry_processing_dag.py for tasks to queue
[2025-10-05T00:04:43.971+0000] {logging_mixin.py:190} INFO - [2025-10-05T00:04:43.971+0000] {dagbag.py:588} INFO - Filling up the DagBag from /opt/airflow/dags/telemetry_processing_dag.py
[2025-10-05T00:04:45.153+0000] {logging_mixin.py:190} INFO - [2025-10-05T00:04:45.136+0000] {dagbag.py:387} ERROR - Failed to import: /opt/airflow/dags/telemetry_processing_dag.py
Traceback (most recent call last):
  File "/home/airflow/.local/lib/python3.12/site-packages/airflow/models/dagbag.py", line 383, in parse
    loader.exec_module(new_module)
  File "<frozen importlib._bootstrap_external>", line 999, in exec_module
  File "<frozen importlib._bootstrap>", line 488, in _call_with_frames_removed
  File "/opt/airflow/dags/telemetry_processing_dag.py", line 10, in <module>
    from tasks.load import IcebergStorage
  File "/opt/airflow/dags/tasks/load.py", line 7, in <module>
    from dags.tasks.config.settings import ICEBERG_STORAGE, BYTES_SIZE, TARGET_FILE_SIZE_MB
ImportError: cannot import name 'ICEBERG_STORAGE' from 'dags.tasks.config.settings' (/opt/airflow/dags/tasks/config/settings.py)
[2025-10-05T00:04:45.159+0000] {processor.py:927} WARNING - No viable dags retrieved from /opt/airflow/dags/telemetry_processing_dag.py
[2025-10-05T00:04:45.198+0000] {processor.py:208} INFO - Processing /opt/airflow/dags/telemetry_processing_dag.py took 1.246 seconds
[2025-10-05T00:05:15.839+0000] {processor.py:186} INFO - Started process (PID=1374) to work on /opt/airflow/dags/telemetry_processing_dag.py
[2025-10-05T00:05:15.841+0000] {processor.py:914} INFO - Processing file /opt/airflow/dags/telemetry_processing_dag.py for tasks to queue
[2025-10-05T00:05:15.845+0000] {logging_mixin.py:190} INFO - [2025-10-05T00:05:15.844+0000] {dagbag.py:588} INFO - Filling up the DagBag from /opt/airflow/dags/telemetry_processing_dag.py
[2025-10-05T00:05:16.955+0000] {logging_mixin.py:190} INFO - [2025-10-05T00:05:16.933+0000] {dagbag.py:387} ERROR - Failed to import: /opt/airflow/dags/telemetry_processing_dag.py
Traceback (most recent call last):
  File "/home/airflow/.local/lib/python3.12/site-packages/airflow/models/dagbag.py", line 383, in parse
    loader.exec_module(new_module)
  File "<frozen importlib._bootstrap_external>", line 999, in exec_module
  File "<frozen importlib._bootstrap>", line 488, in _call_with_frames_removed
  File "/opt/airflow/dags/telemetry_processing_dag.py", line 10, in <module>
    from tasks.load import IcebergStorage
  File "/opt/airflow/dags/tasks/load.py", line 7, in <module>
    from dags.tasks.config.settings import ICEBERG_STORAGE, BYTES_SIZE, TARGET_FILE_SIZE_MB
ImportError: cannot import name 'ICEBERG_STORAGE' from 'dags.tasks.config.settings' (/opt/airflow/dags/tasks/config/settings.py)
[2025-10-05T00:05:16.962+0000] {processor.py:927} WARNING - No viable dags retrieved from /opt/airflow/dags/telemetry_processing_dag.py
[2025-10-05T00:05:17.025+0000] {processor.py:208} INFO - Processing /opt/airflow/dags/telemetry_processing_dag.py took 1.203 seconds
[2025-10-05T00:05:47.243+0000] {processor.py:186} INFO - Started process (PID=1401) to work on /opt/airflow/dags/telemetry_processing_dag.py
[2025-10-05T00:05:47.245+0000] {processor.py:914} INFO - Processing file /opt/airflow/dags/telemetry_processing_dag.py for tasks to queue
[2025-10-05T00:05:47.248+0000] {logging_mixin.py:190} INFO - [2025-10-05T00:05:47.248+0000] {dagbag.py:588} INFO - Filling up the DagBag from /opt/airflow/dags/telemetry_processing_dag.py
[2025-10-05T00:05:48.336+0000] {logging_mixin.py:190} INFO - [2025-10-05T00:05:48.318+0000] {dagbag.py:387} ERROR - Failed to import: /opt/airflow/dags/telemetry_processing_dag.py
Traceback (most recent call last):
  File "/home/airflow/.local/lib/python3.12/site-packages/airflow/models/dagbag.py", line 383, in parse
    loader.exec_module(new_module)
  File "<frozen importlib._bootstrap_external>", line 999, in exec_module
  File "<frozen importlib._bootstrap>", line 488, in _call_with_frames_removed
  File "/opt/airflow/dags/telemetry_processing_dag.py", line 10, in <module>
    from tasks.load import IcebergStorage
  File "/opt/airflow/dags/tasks/load.py", line 7, in <module>
    from dags.tasks.config.settings import ICEBERG_STORAGE, BYTES_SIZE, TARGET_FILE_SIZE_MB
ImportError: cannot import name 'ICEBERG_STORAGE' from 'dags.tasks.config.settings' (/opt/airflow/dags/tasks/config/settings.py)
[2025-10-05T00:05:48.372+0000] {processor.py:927} WARNING - No viable dags retrieved from /opt/airflow/dags/telemetry_processing_dag.py
[2025-10-05T00:05:48.412+0000] {processor.py:208} INFO - Processing /opt/airflow/dags/telemetry_processing_dag.py took 1.184 seconds
[2025-10-05T00:06:18.560+0000] {processor.py:186} INFO - Started process (PID=1428) to work on /opt/airflow/dags/telemetry_processing_dag.py
[2025-10-05T00:06:18.564+0000] {processor.py:914} INFO - Processing file /opt/airflow/dags/telemetry_processing_dag.py for tasks to queue
[2025-10-05T00:06:18.569+0000] {logging_mixin.py:190} INFO - [2025-10-05T00:06:18.568+0000] {dagbag.py:588} INFO - Filling up the DagBag from /opt/airflow/dags/telemetry_processing_dag.py
[2025-10-05T00:06:19.557+0000] {logging_mixin.py:190} INFO - [2025-10-05T00:06:19.538+0000] {dagbag.py:387} ERROR - Failed to import: /opt/airflow/dags/telemetry_processing_dag.py
Traceback (most recent call last):
  File "/home/airflow/.local/lib/python3.12/site-packages/airflow/models/dagbag.py", line 383, in parse
    loader.exec_module(new_module)
  File "<frozen importlib._bootstrap_external>", line 999, in exec_module
  File "<frozen importlib._bootstrap>", line 488, in _call_with_frames_removed
  File "/opt/airflow/dags/telemetry_processing_dag.py", line 10, in <module>
    from tasks.load import IcebergStorage
  File "/opt/airflow/dags/tasks/load.py", line 7, in <module>
    from dags.tasks.config.settings import ICEBERG_STORAGE, BYTES_SIZE, TARGET_FILE_SIZE_MB
ImportError: cannot import name 'ICEBERG_STORAGE' from 'dags.tasks.config.settings' (/opt/airflow/dags/tasks/config/settings.py)
[2025-10-05T00:06:19.566+0000] {processor.py:927} WARNING - No viable dags retrieved from /opt/airflow/dags/telemetry_processing_dag.py
[2025-10-05T00:06:19.605+0000] {processor.py:208} INFO - Processing /opt/airflow/dags/telemetry_processing_dag.py took 1.062 seconds
[2025-10-05T00:06:50.026+0000] {processor.py:186} INFO - Started process (PID=1455) to work on /opt/airflow/dags/telemetry_processing_dag.py
[2025-10-05T00:06:50.029+0000] {processor.py:914} INFO - Processing file /opt/airflow/dags/telemetry_processing_dag.py for tasks to queue
[2025-10-05T00:06:50.033+0000] {logging_mixin.py:190} INFO - [2025-10-05T00:06:50.033+0000] {dagbag.py:588} INFO - Filling up the DagBag from /opt/airflow/dags/telemetry_processing_dag.py
[2025-10-05T00:06:50.976+0000] {logging_mixin.py:190} INFO - [2025-10-05T00:06:50.960+0000] {dagbag.py:387} ERROR - Failed to import: /opt/airflow/dags/telemetry_processing_dag.py
Traceback (most recent call last):
  File "/home/airflow/.local/lib/python3.12/site-packages/airflow/models/dagbag.py", line 383, in parse
    loader.exec_module(new_module)
  File "<frozen importlib._bootstrap_external>", line 999, in exec_module
  File "<frozen importlib._bootstrap>", line 488, in _call_with_frames_removed
  File "/opt/airflow/dags/telemetry_processing_dag.py", line 10, in <module>
    from tasks.load import IcebergStorage
  File "/opt/airflow/dags/tasks/load.py", line 7, in <module>
    from dags.tasks.config.settings import ICEBERG_STORAGE, BYTES_SIZE, TARGET_FILE_SIZE_MB
ImportError: cannot import name 'ICEBERG_STORAGE' from 'dags.tasks.config.settings' (/opt/airflow/dags/tasks/config/settings.py)
[2025-10-05T00:06:50.980+0000] {processor.py:927} WARNING - No viable dags retrieved from /opt/airflow/dags/telemetry_processing_dag.py
[2025-10-05T00:06:51.016+0000] {processor.py:208} INFO - Processing /opt/airflow/dags/telemetry_processing_dag.py took 1.007 seconds
[2025-10-05T00:07:22.122+0000] {processor.py:186} INFO - Started process (PID=1482) to work on /opt/airflow/dags/telemetry_processing_dag.py
[2025-10-05T00:07:22.125+0000] {processor.py:914} INFO - Processing file /opt/airflow/dags/telemetry_processing_dag.py for tasks to queue
[2025-10-05T00:07:22.129+0000] {logging_mixin.py:190} INFO - [2025-10-05T00:07:22.128+0000] {dagbag.py:588} INFO - Filling up the DagBag from /opt/airflow/dags/telemetry_processing_dag.py
[2025-10-05T00:07:23.629+0000] {logging_mixin.py:190} INFO - [2025-10-05T00:07:23.587+0000] {dagbag.py:387} ERROR - Failed to import: /opt/airflow/dags/telemetry_processing_dag.py
Traceback (most recent call last):
  File "/home/airflow/.local/lib/python3.12/site-packages/airflow/models/dagbag.py", line 383, in parse
    loader.exec_module(new_module)
  File "<frozen importlib._bootstrap_external>", line 999, in exec_module
  File "<frozen importlib._bootstrap>", line 488, in _call_with_frames_removed
  File "/opt/airflow/dags/telemetry_processing_dag.py", line 10, in <module>
    from tasks.load import IcebergStorage
  File "/opt/airflow/dags/tasks/load.py", line 7, in <module>
    from dags.tasks.config.settings import ICEBERG_STORAGE, BYTES_SIZE, TARGET_FILE_SIZE_MB
ImportError: cannot import name 'ICEBERG_STORAGE' from 'dags.tasks.config.settings' (/opt/airflow/dags/tasks/config/settings.py)
[2025-10-05T00:07:23.635+0000] {processor.py:927} WARNING - No viable dags retrieved from /opt/airflow/dags/telemetry_processing_dag.py
[2025-10-05T00:07:23.733+0000] {processor.py:208} INFO - Processing /opt/airflow/dags/telemetry_processing_dag.py took 1.666 seconds
[2025-10-05T00:07:53.540+0000] {processor.py:186} INFO - Started process (PID=1509) to work on /opt/airflow/dags/telemetry_processing_dag.py
[2025-10-05T00:07:53.543+0000] {processor.py:914} INFO - Processing file /opt/airflow/dags/telemetry_processing_dag.py for tasks to queue
[2025-10-05T00:07:53.547+0000] {logging_mixin.py:190} INFO - [2025-10-05T00:07:53.546+0000] {dagbag.py:588} INFO - Filling up the DagBag from /opt/airflow/dags/telemetry_processing_dag.py
[2025-10-05T00:07:54.728+0000] {logging_mixin.py:190} INFO - [2025-10-05T00:07:54.686+0000] {dagbag.py:387} ERROR - Failed to import: /opt/airflow/dags/telemetry_processing_dag.py
Traceback (most recent call last):
  File "/home/airflow/.local/lib/python3.12/site-packages/airflow/models/dagbag.py", line 383, in parse
    loader.exec_module(new_module)
  File "<frozen importlib._bootstrap_external>", line 999, in exec_module
  File "<frozen importlib._bootstrap>", line 488, in _call_with_frames_removed
  File "/opt/airflow/dags/telemetry_processing_dag.py", line 10, in <module>
    from tasks.load import IcebergStorage
  File "/opt/airflow/dags/tasks/load.py", line 7, in <module>
    from dags.tasks.config.settings import ICEBERG_STORAGE, BYTES_SIZE, TARGET_FILE_SIZE_MB
ImportError: cannot import name 'ICEBERG_STORAGE' from 'dags.tasks.config.settings' (/opt/airflow/dags/tasks/config/settings.py)
[2025-10-05T00:07:54.736+0000] {processor.py:927} WARNING - No viable dags retrieved from /opt/airflow/dags/telemetry_processing_dag.py
[2025-10-05T00:07:54.903+0000] {processor.py:208} INFO - Processing /opt/airflow/dags/telemetry_processing_dag.py took 1.383 seconds
[2025-10-05T00:08:25.888+0000] {processor.py:186} INFO - Started process (PID=1536) to work on /opt/airflow/dags/telemetry_processing_dag.py
[2025-10-05T00:08:25.891+0000] {processor.py:914} INFO - Processing file /opt/airflow/dags/telemetry_processing_dag.py for tasks to queue
[2025-10-05T00:08:25.896+0000] {logging_mixin.py:190} INFO - [2025-10-05T00:08:25.895+0000] {dagbag.py:588} INFO - Filling up the DagBag from /opt/airflow/dags/telemetry_processing_dag.py
[2025-10-05T00:08:27.036+0000] {logging_mixin.py:190} INFO - [2025-10-05T00:08:27.011+0000] {dagbag.py:387} ERROR - Failed to import: /opt/airflow/dags/telemetry_processing_dag.py
Traceback (most recent call last):
  File "/home/airflow/.local/lib/python3.12/site-packages/airflow/models/dagbag.py", line 383, in parse
    loader.exec_module(new_module)
  File "<frozen importlib._bootstrap_external>", line 999, in exec_module
  File "<frozen importlib._bootstrap>", line 488, in _call_with_frames_removed
  File "/opt/airflow/dags/telemetry_processing_dag.py", line 10, in <module>
    from tasks.load import IcebergStorage
  File "/opt/airflow/dags/tasks/load.py", line 7, in <module>
    from dags.tasks.config.settings import ICEBERG_STORAGE, BYTES_SIZE, TARGET_FILE_SIZE_MB
ImportError: cannot import name 'ICEBERG_STORAGE' from 'dags.tasks.config.settings' (/opt/airflow/dags/tasks/config/settings.py)
[2025-10-05T00:08:27.042+0000] {processor.py:927} WARNING - No viable dags retrieved from /opt/airflow/dags/telemetry_processing_dag.py
[2025-10-05T00:08:27.090+0000] {processor.py:208} INFO - Processing /opt/airflow/dags/telemetry_processing_dag.py took 1.219 seconds
[2025-10-05T00:08:57.451+0000] {processor.py:186} INFO - Started process (PID=1563) to work on /opt/airflow/dags/telemetry_processing_dag.py
[2025-10-05T00:08:57.456+0000] {processor.py:914} INFO - Processing file /opt/airflow/dags/telemetry_processing_dag.py for tasks to queue
[2025-10-05T00:08:57.462+0000] {logging_mixin.py:190} INFO - [2025-10-05T00:08:57.461+0000] {dagbag.py:588} INFO - Filling up the DagBag from /opt/airflow/dags/telemetry_processing_dag.py
[2025-10-05T00:08:58.563+0000] {logging_mixin.py:190} INFO - [2025-10-05T00:08:58.546+0000] {dagbag.py:387} ERROR - Failed to import: /opt/airflow/dags/telemetry_processing_dag.py
Traceback (most recent call last):
  File "/home/airflow/.local/lib/python3.12/site-packages/airflow/models/dagbag.py", line 383, in parse
    loader.exec_module(new_module)
  File "<frozen importlib._bootstrap_external>", line 999, in exec_module
  File "<frozen importlib._bootstrap>", line 488, in _call_with_frames_removed
  File "/opt/airflow/dags/telemetry_processing_dag.py", line 10, in <module>
    from tasks.load import IcebergStorage
  File "/opt/airflow/dags/tasks/load.py", line 7, in <module>
    from dags.tasks.config.settings import ICEBERG_STORAGE, BYTES_SIZE, TARGET_FILE_SIZE_MB
ImportError: cannot import name 'ICEBERG_STORAGE' from 'dags.tasks.config.settings' (/opt/airflow/dags/tasks/config/settings.py)
[2025-10-05T00:08:58.570+0000] {processor.py:927} WARNING - No viable dags retrieved from /opt/airflow/dags/telemetry_processing_dag.py
[2025-10-05T00:08:58.610+0000] {processor.py:208} INFO - Processing /opt/airflow/dags/telemetry_processing_dag.py took 1.202 seconds
[2025-10-05T00:09:28.812+0000] {processor.py:186} INFO - Started process (PID=1590) to work on /opt/airflow/dags/telemetry_processing_dag.py
[2025-10-05T00:09:28.815+0000] {processor.py:914} INFO - Processing file /opt/airflow/dags/telemetry_processing_dag.py for tasks to queue
[2025-10-05T00:09:28.818+0000] {logging_mixin.py:190} INFO - [2025-10-05T00:09:28.817+0000] {dagbag.py:588} INFO - Filling up the DagBag from /opt/airflow/dags/telemetry_processing_dag.py
[2025-10-05T00:09:29.886+0000] {logging_mixin.py:190} INFO - [2025-10-05T00:09:29.870+0000] {dagbag.py:387} ERROR - Failed to import: /opt/airflow/dags/telemetry_processing_dag.py
Traceback (most recent call last):
  File "/home/airflow/.local/lib/python3.12/site-packages/airflow/models/dagbag.py", line 383, in parse
    loader.exec_module(new_module)
  File "<frozen importlib._bootstrap_external>", line 999, in exec_module
  File "<frozen importlib._bootstrap>", line 488, in _call_with_frames_removed
  File "/opt/airflow/dags/telemetry_processing_dag.py", line 10, in <module>
    from tasks.load import IcebergStorage
  File "/opt/airflow/dags/tasks/load.py", line 7, in <module>
    from dags.tasks.config.settings import ICEBERG_STORAGE, BYTES_SIZE, TARGET_FILE_SIZE_MB
ImportError: cannot import name 'ICEBERG_STORAGE' from 'dags.tasks.config.settings' (/opt/airflow/dags/tasks/config/settings.py)
[2025-10-05T00:09:29.891+0000] {processor.py:927} WARNING - No viable dags retrieved from /opt/airflow/dags/telemetry_processing_dag.py
[2025-10-05T00:09:29.996+0000] {processor.py:208} INFO - Processing /opt/airflow/dags/telemetry_processing_dag.py took 1.201 seconds
[2025-10-05T00:10:00.557+0000] {processor.py:186} INFO - Started process (PID=1617) to work on /opt/airflow/dags/telemetry_processing_dag.py
[2025-10-05T00:10:00.560+0000] {processor.py:914} INFO - Processing file /opt/airflow/dags/telemetry_processing_dag.py for tasks to queue
[2025-10-05T00:10:00.564+0000] {logging_mixin.py:190} INFO - [2025-10-05T00:10:00.563+0000] {dagbag.py:588} INFO - Filling up the DagBag from /opt/airflow/dags/telemetry_processing_dag.py
[2025-10-05T00:10:01.462+0000] {logging_mixin.py:190} INFO - [2025-10-05T00:10:01.439+0000] {dagbag.py:387} ERROR - Failed to import: /opt/airflow/dags/telemetry_processing_dag.py
Traceback (most recent call last):
  File "/home/airflow/.local/lib/python3.12/site-packages/airflow/models/dagbag.py", line 383, in parse
    loader.exec_module(new_module)
  File "<frozen importlib._bootstrap_external>", line 999, in exec_module
  File "<frozen importlib._bootstrap>", line 488, in _call_with_frames_removed
  File "/opt/airflow/dags/telemetry_processing_dag.py", line 10, in <module>
    from tasks.load import IcebergStorage
  File "/opt/airflow/dags/tasks/load.py", line 7, in <module>
    from dags.tasks.config.settings import ICEBERG_STORAGE, BYTES_SIZE, TARGET_FILE_SIZE_MB
ImportError: cannot import name 'ICEBERG_STORAGE' from 'dags.tasks.config.settings' (/opt/airflow/dags/tasks/config/settings.py)
[2025-10-05T00:10:01.468+0000] {processor.py:927} WARNING - No viable dags retrieved from /opt/airflow/dags/telemetry_processing_dag.py
[2025-10-05T00:10:01.549+0000] {processor.py:208} INFO - Processing /opt/airflow/dags/telemetry_processing_dag.py took 1.009 seconds
[2025-10-05T00:10:31.789+0000] {processor.py:186} INFO - Started process (PID=1644) to work on /opt/airflow/dags/telemetry_processing_dag.py
[2025-10-05T00:10:31.792+0000] {processor.py:914} INFO - Processing file /opt/airflow/dags/telemetry_processing_dag.py for tasks to queue
[2025-10-05T00:10:31.796+0000] {logging_mixin.py:190} INFO - [2025-10-05T00:10:31.796+0000] {dagbag.py:588} INFO - Filling up the DagBag from /opt/airflow/dags/telemetry_processing_dag.py
[2025-10-05T00:10:32.850+0000] {logging_mixin.py:190} INFO - [2025-10-05T00:10:32.828+0000] {dagbag.py:387} ERROR - Failed to import: /opt/airflow/dags/telemetry_processing_dag.py
Traceback (most recent call last):
  File "/home/airflow/.local/lib/python3.12/site-packages/airflow/models/dagbag.py", line 383, in parse
    loader.exec_module(new_module)
  File "<frozen importlib._bootstrap_external>", line 999, in exec_module
  File "<frozen importlib._bootstrap>", line 488, in _call_with_frames_removed
  File "/opt/airflow/dags/telemetry_processing_dag.py", line 10, in <module>
    from tasks.load import IcebergStorage
  File "/opt/airflow/dags/tasks/load.py", line 7, in <module>
    from dags.tasks.config.settings import ICEBERG_STORAGE, BYTES_SIZE, TARGET_FILE_SIZE_MB
ImportError: cannot import name 'ICEBERG_STORAGE' from 'dags.tasks.config.settings' (/opt/airflow/dags/tasks/config/settings.py)
[2025-10-05T00:10:32.855+0000] {processor.py:927} WARNING - No viable dags retrieved from /opt/airflow/dags/telemetry_processing_dag.py
[2025-10-05T00:10:32.903+0000] {processor.py:208} INFO - Processing /opt/airflow/dags/telemetry_processing_dag.py took 1.134 seconds
[2025-10-05T00:11:03.269+0000] {processor.py:186} INFO - Started process (PID=1671) to work on /opt/airflow/dags/telemetry_processing_dag.py
[2025-10-05T00:11:03.273+0000] {processor.py:914} INFO - Processing file /opt/airflow/dags/telemetry_processing_dag.py for tasks to queue
[2025-10-05T00:11:03.278+0000] {logging_mixin.py:190} INFO - [2025-10-05T00:11:03.276+0000] {dagbag.py:588} INFO - Filling up the DagBag from /opt/airflow/dags/telemetry_processing_dag.py
[2025-10-05T00:11:04.232+0000] {logging_mixin.py:190} INFO - [2025-10-05T00:11:04.217+0000] {dagbag.py:387} ERROR - Failed to import: /opt/airflow/dags/telemetry_processing_dag.py
Traceback (most recent call last):
  File "/home/airflow/.local/lib/python3.12/site-packages/airflow/models/dagbag.py", line 383, in parse
    loader.exec_module(new_module)
  File "<frozen importlib._bootstrap_external>", line 999, in exec_module
  File "<frozen importlib._bootstrap>", line 488, in _call_with_frames_removed
  File "/opt/airflow/dags/telemetry_processing_dag.py", line 10, in <module>
    from tasks.load import IcebergStorage
  File "/opt/airflow/dags/tasks/load.py", line 7, in <module>
    from dags.tasks.config.settings import ICEBERG_STORAGE, BYTES_SIZE, TARGET_FILE_SIZE_MB
ImportError: cannot import name 'ICEBERG_STORAGE' from 'dags.tasks.config.settings' (/opt/airflow/dags/tasks/config/settings.py)
[2025-10-05T00:11:04.237+0000] {processor.py:927} WARNING - No viable dags retrieved from /opt/airflow/dags/telemetry_processing_dag.py
[2025-10-05T00:11:04.293+0000] {processor.py:208} INFO - Processing /opt/airflow/dags/telemetry_processing_dag.py took 1.046 seconds
[2025-10-05T00:11:34.521+0000] {processor.py:186} INFO - Started process (PID=1698) to work on /opt/airflow/dags/telemetry_processing_dag.py
[2025-10-05T00:11:34.524+0000] {processor.py:914} INFO - Processing file /opt/airflow/dags/telemetry_processing_dag.py for tasks to queue
[2025-10-05T00:11:34.527+0000] {logging_mixin.py:190} INFO - [2025-10-05T00:11:34.526+0000] {dagbag.py:588} INFO - Filling up the DagBag from /opt/airflow/dags/telemetry_processing_dag.py
[2025-10-05T00:11:36.017+0000] {logging_mixin.py:190} INFO - [2025-10-05T00:11:35.998+0000] {dagbag.py:387} ERROR - Failed to import: /opt/airflow/dags/telemetry_processing_dag.py
Traceback (most recent call last):
  File "/home/airflow/.local/lib/python3.12/site-packages/airflow/models/dagbag.py", line 383, in parse
    loader.exec_module(new_module)
  File "<frozen importlib._bootstrap_external>", line 999, in exec_module
  File "<frozen importlib._bootstrap>", line 488, in _call_with_frames_removed
  File "/opt/airflow/dags/telemetry_processing_dag.py", line 10, in <module>
    from tasks.load import IcebergStorage
  File "/opt/airflow/dags/tasks/load.py", line 7, in <module>
    from dags.tasks.config.settings import ICEBERG_STORAGE, BYTES_SIZE, TARGET_FILE_SIZE_MB
ImportError: cannot import name 'ICEBERG_STORAGE' from 'dags.tasks.config.settings' (/opt/airflow/dags/tasks/config/settings.py)
[2025-10-05T00:11:36.024+0000] {processor.py:927} WARNING - No viable dags retrieved from /opt/airflow/dags/telemetry_processing_dag.py
[2025-10-05T00:11:36.060+0000] {processor.py:208} INFO - Processing /opt/airflow/dags/telemetry_processing_dag.py took 1.553 seconds
[2025-10-05T00:12:06.337+0000] {processor.py:186} INFO - Started process (PID=1725) to work on /opt/airflow/dags/telemetry_processing_dag.py
[2025-10-05T00:12:06.341+0000] {processor.py:914} INFO - Processing file /opt/airflow/dags/telemetry_processing_dag.py for tasks to queue
[2025-10-05T00:12:06.344+0000] {logging_mixin.py:190} INFO - [2025-10-05T00:12:06.343+0000] {dagbag.py:588} INFO - Filling up the DagBag from /opt/airflow/dags/telemetry_processing_dag.py
[2025-10-05T00:12:07.412+0000] {logging_mixin.py:190} INFO - [2025-10-05T00:12:07.394+0000] {dagbag.py:387} ERROR - Failed to import: /opt/airflow/dags/telemetry_processing_dag.py
Traceback (most recent call last):
  File "/home/airflow/.local/lib/python3.12/site-packages/airflow/models/dagbag.py", line 383, in parse
    loader.exec_module(new_module)
  File "<frozen importlib._bootstrap_external>", line 999, in exec_module
  File "<frozen importlib._bootstrap>", line 488, in _call_with_frames_removed
  File "/opt/airflow/dags/telemetry_processing_dag.py", line 10, in <module>
    from tasks.load import IcebergStorage
  File "/opt/airflow/dags/tasks/load.py", line 7, in <module>
    from dags.tasks.config.settings import ICEBERG_STORAGE, BYTES_SIZE, TARGET_FILE_SIZE_MB
ImportError: cannot import name 'ICEBERG_STORAGE' from 'dags.tasks.config.settings' (/opt/airflow/dags/tasks/config/settings.py)
[2025-10-05T00:12:07.416+0000] {processor.py:927} WARNING - No viable dags retrieved from /opt/airflow/dags/telemetry_processing_dag.py
[2025-10-05T00:12:07.459+0000] {processor.py:208} INFO - Processing /opt/airflow/dags/telemetry_processing_dag.py took 1.139 seconds
[2025-10-05T00:12:37.639+0000] {processor.py:186} INFO - Started process (PID=1752) to work on /opt/airflow/dags/telemetry_processing_dag.py
[2025-10-05T00:12:37.643+0000] {processor.py:914} INFO - Processing file /opt/airflow/dags/telemetry_processing_dag.py for tasks to queue
[2025-10-05T00:12:37.647+0000] {logging_mixin.py:190} INFO - [2025-10-05T00:12:37.646+0000] {dagbag.py:588} INFO - Filling up the DagBag from /opt/airflow/dags/telemetry_processing_dag.py
[2025-10-05T00:12:38.744+0000] {logging_mixin.py:190} INFO - [2025-10-05T00:12:38.727+0000] {dagbag.py:387} ERROR - Failed to import: /opt/airflow/dags/telemetry_processing_dag.py
Traceback (most recent call last):
  File "/home/airflow/.local/lib/python3.12/site-packages/airflow/models/dagbag.py", line 383, in parse
    loader.exec_module(new_module)
  File "<frozen importlib._bootstrap_external>", line 999, in exec_module
  File "<frozen importlib._bootstrap>", line 488, in _call_with_frames_removed
  File "/opt/airflow/dags/telemetry_processing_dag.py", line 10, in <module>
    from tasks.load import IcebergStorage
  File "/opt/airflow/dags/tasks/load.py", line 7, in <module>
    from dags.tasks.config.settings import ICEBERG_STORAGE, BYTES_SIZE, TARGET_FILE_SIZE_MB
ImportError: cannot import name 'ICEBERG_STORAGE' from 'dags.tasks.config.settings' (/opt/airflow/dags/tasks/config/settings.py)
[2025-10-05T00:12:38.748+0000] {processor.py:927} WARNING - No viable dags retrieved from /opt/airflow/dags/telemetry_processing_dag.py
[2025-10-05T00:12:38.790+0000] {processor.py:208} INFO - Processing /opt/airflow/dags/telemetry_processing_dag.py took 1.169 seconds
[2025-10-05T00:13:09.327+0000] {processor.py:186} INFO - Started process (PID=1779) to work on /opt/airflow/dags/telemetry_processing_dag.py
[2025-10-05T00:13:09.330+0000] {processor.py:914} INFO - Processing file /opt/airflow/dags/telemetry_processing_dag.py for tasks to queue
[2025-10-05T00:13:09.333+0000] {logging_mixin.py:190} INFO - [2025-10-05T00:13:09.333+0000] {dagbag.py:588} INFO - Filling up the DagBag from /opt/airflow/dags/telemetry_processing_dag.py
[2025-10-05T00:13:10.320+0000] {logging_mixin.py:190} INFO - [2025-10-05T00:13:10.305+0000] {dagbag.py:387} ERROR - Failed to import: /opt/airflow/dags/telemetry_processing_dag.py
Traceback (most recent call last):
  File "/home/airflow/.local/lib/python3.12/site-packages/airflow/models/dagbag.py", line 383, in parse
    loader.exec_module(new_module)
  File "<frozen importlib._bootstrap_external>", line 999, in exec_module
  File "<frozen importlib._bootstrap>", line 488, in _call_with_frames_removed
  File "/opt/airflow/dags/telemetry_processing_dag.py", line 10, in <module>
    from tasks.load import IcebergStorage
  File "/opt/airflow/dags/tasks/load.py", line 7, in <module>
    from dags.tasks.config.settings import ICEBERG_STORAGE, BYTES_SIZE, TARGET_FILE_SIZE_MB
ImportError: cannot import name 'ICEBERG_STORAGE' from 'dags.tasks.config.settings' (/opt/airflow/dags/tasks/config/settings.py)
[2025-10-05T00:13:10.324+0000] {processor.py:927} WARNING - No viable dags retrieved from /opt/airflow/dags/telemetry_processing_dag.py
[2025-10-05T00:13:10.388+0000] {processor.py:208} INFO - Processing /opt/airflow/dags/telemetry_processing_dag.py took 1.077 seconds
[2025-10-05T00:13:41.674+0000] {processor.py:186} INFO - Started process (PID=1806) to work on /opt/airflow/dags/telemetry_processing_dag.py
[2025-10-05T00:13:41.691+0000] {processor.py:914} INFO - Processing file /opt/airflow/dags/telemetry_processing_dag.py for tasks to queue
[2025-10-05T00:13:41.730+0000] {logging_mixin.py:190} INFO - [2025-10-05T00:13:41.727+0000] {dagbag.py:588} INFO - Filling up the DagBag from /opt/airflow/dags/telemetry_processing_dag.py
[2025-10-05T00:13:43.925+0000] {logging_mixin.py:190} INFO - [2025-10-05T00:13:43.905+0000] {dagbag.py:387} ERROR - Failed to import: /opt/airflow/dags/telemetry_processing_dag.py
Traceback (most recent call last):
  File "/home/airflow/.local/lib/python3.12/site-packages/airflow/models/dagbag.py", line 383, in parse
    loader.exec_module(new_module)
  File "<frozen importlib._bootstrap_external>", line 999, in exec_module
  File "<frozen importlib._bootstrap>", line 488, in _call_with_frames_removed
  File "/opt/airflow/dags/telemetry_processing_dag.py", line 10, in <module>
    from tasks.load import IcebergStorage
  File "/opt/airflow/dags/tasks/load.py", line 7, in <module>
    from dags.tasks.config.settings import ICEBERG_STORAGE, BYTES_SIZE, TARGET_FILE_SIZE_MB
ImportError: cannot import name 'ICEBERG_STORAGE' from 'dags.tasks.config.settings' (/opt/airflow/dags/tasks/config/settings.py)
[2025-10-05T00:13:43.931+0000] {processor.py:927} WARNING - No viable dags retrieved from /opt/airflow/dags/telemetry_processing_dag.py
[2025-10-05T00:13:43.974+0000] {processor.py:208} INFO - Processing /opt/airflow/dags/telemetry_processing_dag.py took 2.653 seconds
[2025-10-05T00:14:14.584+0000] {processor.py:186} INFO - Started process (PID=1833) to work on /opt/airflow/dags/telemetry_processing_dag.py
[2025-10-05T00:14:14.587+0000] {processor.py:914} INFO - Processing file /opt/airflow/dags/telemetry_processing_dag.py for tasks to queue
[2025-10-05T00:14:14.590+0000] {logging_mixin.py:190} INFO - [2025-10-05T00:14:14.589+0000] {dagbag.py:588} INFO - Filling up the DagBag from /opt/airflow/dags/telemetry_processing_dag.py
[2025-10-05T00:14:15.906+0000] {logging_mixin.py:190} INFO - [2025-10-05T00:14:15.822+0000] {dagbag.py:387} ERROR - Failed to import: /opt/airflow/dags/telemetry_processing_dag.py
Traceback (most recent call last):
  File "/home/airflow/.local/lib/python3.12/site-packages/airflow/models/dagbag.py", line 383, in parse
    loader.exec_module(new_module)
  File "<frozen importlib._bootstrap_external>", line 999, in exec_module
  File "<frozen importlib._bootstrap>", line 488, in _call_with_frames_removed
  File "/opt/airflow/dags/telemetry_processing_dag.py", line 10, in <module>
    from tasks.load import IcebergStorage
  File "/opt/airflow/dags/tasks/load.py", line 7, in <module>
    from dags.tasks.config.settings import ICEBERG_STORAGE, BYTES_SIZE, TARGET_FILE_SIZE_MB
ImportError: cannot import name 'ICEBERG_STORAGE' from 'dags.tasks.config.settings' (/opt/airflow/dags/tasks/config/settings.py)
[2025-10-05T00:14:15.914+0000] {processor.py:927} WARNING - No viable dags retrieved from /opt/airflow/dags/telemetry_processing_dag.py
[2025-10-05T00:14:15.951+0000] {processor.py:208} INFO - Processing /opt/airflow/dags/telemetry_processing_dag.py took 1.384 seconds
[2025-10-05T00:14:46.195+0000] {processor.py:186} INFO - Started process (PID=1853) to work on /opt/airflow/dags/telemetry_processing_dag.py
[2025-10-05T00:14:46.202+0000] {processor.py:914} INFO - Processing file /opt/airflow/dags/telemetry_processing_dag.py for tasks to queue
[2025-10-05T00:14:46.208+0000] {logging_mixin.py:190} INFO - [2025-10-05T00:14:46.207+0000] {dagbag.py:588} INFO - Filling up the DagBag from /opt/airflow/dags/telemetry_processing_dag.py
[2025-10-05T00:14:48.326+0000] {logging_mixin.py:190} INFO - [2025-10-05T00:14:48.299+0000] {dagbag.py:387} ERROR - Failed to import: /opt/airflow/dags/telemetry_processing_dag.py
Traceback (most recent call last):
  File "/home/airflow/.local/lib/python3.12/site-packages/airflow/models/dagbag.py", line 383, in parse
    loader.exec_module(new_module)
  File "<frozen importlib._bootstrap_external>", line 999, in exec_module
  File "<frozen importlib._bootstrap>", line 488, in _call_with_frames_removed
  File "/opt/airflow/dags/telemetry_processing_dag.py", line 10, in <module>
    from tasks.load import IcebergStorage
  File "/opt/airflow/dags/tasks/load.py", line 7, in <module>
    from dags.tasks.config.settings import ICEBERG_STORAGE, BYTES_SIZE, TARGET_FILE_SIZE_MB
ImportError: cannot import name 'ICEBERG_STORAGE' from 'dags.tasks.config.settings' (/opt/airflow/dags/tasks/config/settings.py)
[2025-10-05T00:14:48.335+0000] {processor.py:927} WARNING - No viable dags retrieved from /opt/airflow/dags/telemetry_processing_dag.py
[2025-10-05T00:14:48.470+0000] {processor.py:208} INFO - Processing /opt/airflow/dags/telemetry_processing_dag.py took 2.296 seconds
[2025-10-05T00:15:18.873+0000] {processor.py:186} INFO - Started process (PID=1880) to work on /opt/airflow/dags/telemetry_processing_dag.py
[2025-10-05T00:15:18.876+0000] {processor.py:914} INFO - Processing file /opt/airflow/dags/telemetry_processing_dag.py for tasks to queue
[2025-10-05T00:15:18.882+0000] {logging_mixin.py:190} INFO - [2025-10-05T00:15:18.881+0000] {dagbag.py:588} INFO - Filling up the DagBag from /opt/airflow/dags/telemetry_processing_dag.py
[2025-10-05T00:15:19.880+0000] {logging_mixin.py:190} INFO - [2025-10-05T00:15:19.842+0000] {dagbag.py:387} ERROR - Failed to import: /opt/airflow/dags/telemetry_processing_dag.py
Traceback (most recent call last):
  File "/home/airflow/.local/lib/python3.12/site-packages/airflow/models/dagbag.py", line 383, in parse
    loader.exec_module(new_module)
  File "<frozen importlib._bootstrap_external>", line 999, in exec_module
  File "<frozen importlib._bootstrap>", line 488, in _call_with_frames_removed
  File "/opt/airflow/dags/telemetry_processing_dag.py", line 10, in <module>
    from tasks.load import IcebergStorage
  File "/opt/airflow/dags/tasks/load.py", line 7, in <module>
    from dags.tasks.config.settings import ICEBERG_STORAGE, BYTES_SIZE, TARGET_FILE_SIZE_MB
ImportError: cannot import name 'ICEBERG_STORAGE' from 'dags.tasks.config.settings' (/opt/airflow/dags/tasks/config/settings.py)
[2025-10-05T00:15:19.886+0000] {processor.py:927} WARNING - No viable dags retrieved from /opt/airflow/dags/telemetry_processing_dag.py
[2025-10-05T00:15:19.933+0000] {processor.py:208} INFO - Processing /opt/airflow/dags/telemetry_processing_dag.py took 1.078 seconds
[2025-10-05T00:15:50.412+0000] {processor.py:186} INFO - Started process (PID=1907) to work on /opt/airflow/dags/telemetry_processing_dag.py
[2025-10-05T00:15:50.421+0000] {processor.py:914} INFO - Processing file /opt/airflow/dags/telemetry_processing_dag.py for tasks to queue
[2025-10-05T00:15:50.426+0000] {logging_mixin.py:190} INFO - [2025-10-05T00:15:50.425+0000] {dagbag.py:588} INFO - Filling up the DagBag from /opt/airflow/dags/telemetry_processing_dag.py
[2025-10-05T00:15:52.840+0000] {logging_mixin.py:190} INFO - [2025-10-05T00:15:52.788+0000] {dagbag.py:387} ERROR - Failed to import: /opt/airflow/dags/telemetry_processing_dag.py
Traceback (most recent call last):
  File "/home/airflow/.local/lib/python3.12/site-packages/airflow/models/dagbag.py", line 383, in parse
    loader.exec_module(new_module)
  File "<frozen importlib._bootstrap_external>", line 999, in exec_module
  File "<frozen importlib._bootstrap>", line 488, in _call_with_frames_removed
  File "/opt/airflow/dags/telemetry_processing_dag.py", line 10, in <module>
    from tasks.load import IcebergStorage
  File "/opt/airflow/dags/tasks/load.py", line 7, in <module>
    from dags.tasks.config.settings import ICEBERG_STORAGE, BYTES_SIZE, TARGET_FILE_SIZE_MB
ImportError: cannot import name 'ICEBERG_STORAGE' from 'dags.tasks.config.settings' (/opt/airflow/dags/tasks/config/settings.py)
[2025-10-05T00:15:52.849+0000] {processor.py:927} WARNING - No viable dags retrieved from /opt/airflow/dags/telemetry_processing_dag.py
[2025-10-05T00:15:53.083+0000] {processor.py:208} INFO - Processing /opt/airflow/dags/telemetry_processing_dag.py took 4.472 seconds
[2025-10-05T00:16:23.419+0000] {processor.py:186} INFO - Started process (PID=1933) to work on /opt/airflow/dags/telemetry_processing_dag.py
[2025-10-05T00:16:23.421+0000] {processor.py:914} INFO - Processing file /opt/airflow/dags/telemetry_processing_dag.py for tasks to queue
[2025-10-05T00:16:23.426+0000] {logging_mixin.py:190} INFO - [2025-10-05T00:16:23.424+0000] {dagbag.py:588} INFO - Filling up the DagBag from /opt/airflow/dags/telemetry_processing_dag.py
[2025-10-05T00:16:25.168+0000] {logging_mixin.py:190} INFO - [2025-10-05T00:16:25.138+0000] {dagbag.py:387} ERROR - Failed to import: /opt/airflow/dags/telemetry_processing_dag.py
Traceback (most recent call last):
  File "/home/airflow/.local/lib/python3.12/site-packages/airflow/models/dagbag.py", line 383, in parse
    loader.exec_module(new_module)
  File "<frozen importlib._bootstrap_external>", line 999, in exec_module
  File "<frozen importlib._bootstrap>", line 488, in _call_with_frames_removed
  File "/opt/airflow/dags/telemetry_processing_dag.py", line 10, in <module>
    from tasks.load import IcebergStorage
  File "/opt/airflow/dags/tasks/load.py", line 7, in <module>
    from dags.tasks.config.settings import ICEBERG_STORAGE, BYTES_SIZE, TARGET_FILE_SIZE_MB
ImportError: cannot import name 'ICEBERG_STORAGE' from 'dags.tasks.config.settings' (/opt/airflow/dags/tasks/config/settings.py)
[2025-10-05T00:16:25.175+0000] {processor.py:927} WARNING - No viable dags retrieved from /opt/airflow/dags/telemetry_processing_dag.py
[2025-10-05T00:16:25.250+0000] {processor.py:208} INFO - Processing /opt/airflow/dags/telemetry_processing_dag.py took 1.863 seconds
[2025-10-05T00:16:56.024+0000] {processor.py:186} INFO - Started process (PID=1960) to work on /opt/airflow/dags/telemetry_processing_dag.py
[2025-10-05T00:16:56.029+0000] {processor.py:914} INFO - Processing file /opt/airflow/dags/telemetry_processing_dag.py for tasks to queue
[2025-10-05T00:16:56.035+0000] {logging_mixin.py:190} INFO - [2025-10-05T00:16:56.033+0000] {dagbag.py:588} INFO - Filling up the DagBag from /opt/airflow/dags/telemetry_processing_dag.py
[2025-10-05T00:16:58.387+0000] {logging_mixin.py:190} INFO - [2025-10-05T00:16:58.361+0000] {dagbag.py:387} ERROR - Failed to import: /opt/airflow/dags/telemetry_processing_dag.py
Traceback (most recent call last):
  File "/home/airflow/.local/lib/python3.12/site-packages/airflow/models/dagbag.py", line 383, in parse
    loader.exec_module(new_module)
  File "<frozen importlib._bootstrap_external>", line 999, in exec_module
  File "<frozen importlib._bootstrap>", line 488, in _call_with_frames_removed
  File "/opt/airflow/dags/telemetry_processing_dag.py", line 10, in <module>
    from tasks.load import IcebergStorage
  File "/opt/airflow/dags/tasks/load.py", line 7, in <module>
    from dags.tasks.config.settings import ICEBERG_STORAGE, BYTES_SIZE, TARGET_FILE_SIZE_MB
ImportError: cannot import name 'ICEBERG_STORAGE' from 'dags.tasks.config.settings' (/opt/airflow/dags/tasks/config/settings.py)
[2025-10-05T00:16:58.393+0000] {processor.py:927} WARNING - No viable dags retrieved from /opt/airflow/dags/telemetry_processing_dag.py
[2025-10-05T00:16:58.478+0000] {processor.py:208} INFO - Processing /opt/airflow/dags/telemetry_processing_dag.py took 2.484 seconds
[2025-10-05T00:17:29.234+0000] {processor.py:186} INFO - Started process (PID=1987) to work on /opt/airflow/dags/telemetry_processing_dag.py
[2025-10-05T00:17:29.237+0000] {processor.py:914} INFO - Processing file /opt/airflow/dags/telemetry_processing_dag.py for tasks to queue
[2025-10-05T00:17:29.241+0000] {logging_mixin.py:190} INFO - [2025-10-05T00:17:29.240+0000] {dagbag.py:588} INFO - Filling up the DagBag from /opt/airflow/dags/telemetry_processing_dag.py
[2025-10-05T00:17:30.402+0000] {logging_mixin.py:190} INFO - [2025-10-05T00:17:30.387+0000] {dagbag.py:387} ERROR - Failed to import: /opt/airflow/dags/telemetry_processing_dag.py
Traceback (most recent call last):
  File "/home/airflow/.local/lib/python3.12/site-packages/airflow/models/dagbag.py", line 383, in parse
    loader.exec_module(new_module)
  File "<frozen importlib._bootstrap_external>", line 999, in exec_module
  File "<frozen importlib._bootstrap>", line 488, in _call_with_frames_removed
  File "/opt/airflow/dags/telemetry_processing_dag.py", line 10, in <module>
    from tasks.load import IcebergStorage
  File "/opt/airflow/dags/tasks/load.py", line 7, in <module>
    from dags.tasks.config.settings import ICEBERG_STORAGE, BYTES_SIZE, TARGET_FILE_SIZE_MB
ImportError: cannot import name 'ICEBERG_STORAGE' from 'dags.tasks.config.settings' (/opt/airflow/dags/tasks/config/settings.py)
[2025-10-05T00:17:30.406+0000] {processor.py:927} WARNING - No viable dags retrieved from /opt/airflow/dags/telemetry_processing_dag.py
[2025-10-05T00:17:30.463+0000] {processor.py:208} INFO - Processing /opt/airflow/dags/telemetry_processing_dag.py took 1.249 seconds
[2025-10-05T00:18:00.583+0000] {processor.py:186} INFO - Started process (PID=2013) to work on /opt/airflow/dags/telemetry_processing_dag.py
[2025-10-05T00:18:00.586+0000] {processor.py:914} INFO - Processing file /opt/airflow/dags/telemetry_processing_dag.py for tasks to queue
[2025-10-05T00:18:00.590+0000] {logging_mixin.py:190} INFO - [2025-10-05T00:18:00.589+0000] {dagbag.py:588} INFO - Filling up the DagBag from /opt/airflow/dags/telemetry_processing_dag.py
[2025-10-05T00:18:01.902+0000] {logging_mixin.py:190} INFO - [2025-10-05T00:18:01.872+0000] {dagbag.py:387} ERROR - Failed to import: /opt/airflow/dags/telemetry_processing_dag.py
Traceback (most recent call last):
  File "/home/airflow/.local/lib/python3.12/site-packages/airflow/models/dagbag.py", line 383, in parse
    loader.exec_module(new_module)
  File "<frozen importlib._bootstrap_external>", line 999, in exec_module
  File "<frozen importlib._bootstrap>", line 488, in _call_with_frames_removed
  File "/opt/airflow/dags/telemetry_processing_dag.py", line 10, in <module>
    from tasks.load import IcebergStorage
  File "/opt/airflow/dags/tasks/load.py", line 7, in <module>
    from dags.tasks.config.settings import ICEBERG_STORAGE, BYTES_SIZE, TARGET_FILE_SIZE_MB
ImportError: cannot import name 'ICEBERG_STORAGE' from 'dags.tasks.config.settings' (/opt/airflow/dags/tasks/config/settings.py)
[2025-10-05T00:18:01.909+0000] {processor.py:927} WARNING - No viable dags retrieved from /opt/airflow/dags/telemetry_processing_dag.py
[2025-10-05T00:18:01.985+0000] {processor.py:208} INFO - Processing /opt/airflow/dags/telemetry_processing_dag.py took 1.417 seconds
[2025-10-05T00:18:32.377+0000] {processor.py:186} INFO - Started process (PID=2040) to work on /opt/airflow/dags/telemetry_processing_dag.py
[2025-10-05T00:18:32.387+0000] {processor.py:914} INFO - Processing file /opt/airflow/dags/telemetry_processing_dag.py for tasks to queue
[2025-10-05T00:18:32.396+0000] {logging_mixin.py:190} INFO - [2025-10-05T00:18:32.394+0000] {dagbag.py:588} INFO - Filling up the DagBag from /opt/airflow/dags/telemetry_processing_dag.py
[2025-10-05T00:18:34.514+0000] {logging_mixin.py:190} INFO - [2025-10-05T00:18:34.493+0000] {dagbag.py:387} ERROR - Failed to import: /opt/airflow/dags/telemetry_processing_dag.py
Traceback (most recent call last):
  File "/home/airflow/.local/lib/python3.12/site-packages/airflow/models/dagbag.py", line 383, in parse
    loader.exec_module(new_module)
  File "<frozen importlib._bootstrap_external>", line 999, in exec_module
  File "<frozen importlib._bootstrap>", line 488, in _call_with_frames_removed
  File "/opt/airflow/dags/telemetry_processing_dag.py", line 10, in <module>
    from tasks.load import IcebergStorage
  File "/opt/airflow/dags/tasks/load.py", line 7, in <module>
    from dags.tasks.config.settings import ICEBERG_STORAGE, BYTES_SIZE, TARGET_FILE_SIZE_MB
ImportError: cannot import name 'ICEBERG_STORAGE' from 'dags.tasks.config.settings' (/opt/airflow/dags/tasks/config/settings.py)
[2025-10-05T00:18:34.520+0000] {processor.py:927} WARNING - No viable dags retrieved from /opt/airflow/dags/telemetry_processing_dag.py
[2025-10-05T00:18:34.594+0000] {processor.py:208} INFO - Processing /opt/airflow/dags/telemetry_processing_dag.py took 2.242 seconds
[2025-10-05T00:19:05.007+0000] {processor.py:186} INFO - Started process (PID=2068) to work on /opt/airflow/dags/telemetry_processing_dag.py
[2025-10-05T00:19:05.010+0000] {processor.py:914} INFO - Processing file /opt/airflow/dags/telemetry_processing_dag.py for tasks to queue
[2025-10-05T00:19:05.015+0000] {logging_mixin.py:190} INFO - [2025-10-05T00:19:05.013+0000] {dagbag.py:588} INFO - Filling up the DagBag from /opt/airflow/dags/telemetry_processing_dag.py
[2025-10-05T00:19:06.803+0000] {logging_mixin.py:190} INFO - [2025-10-05T00:19:06.787+0000] {dagbag.py:387} ERROR - Failed to import: /opt/airflow/dags/telemetry_processing_dag.py
Traceback (most recent call last):
  File "/home/airflow/.local/lib/python3.12/site-packages/airflow/models/dagbag.py", line 383, in parse
    loader.exec_module(new_module)
  File "<frozen importlib._bootstrap_external>", line 999, in exec_module
  File "<frozen importlib._bootstrap>", line 488, in _call_with_frames_removed
  File "/opt/airflow/dags/telemetry_processing_dag.py", line 10, in <module>
    from tasks.load import IcebergStorage
  File "/opt/airflow/dags/tasks/load.py", line 7, in <module>
    from dags.tasks.config.settings import ICEBERG_STORAGE, BYTES_SIZE, TARGET_FILE_SIZE_MB
ImportError: cannot import name 'ICEBERG_STORAGE' from 'dags.tasks.config.settings' (/opt/airflow/dags/tasks/config/settings.py)
[2025-10-05T00:19:06.810+0000] {processor.py:927} WARNING - No viable dags retrieved from /opt/airflow/dags/telemetry_processing_dag.py
[2025-10-05T00:19:06.883+0000] {processor.py:208} INFO - Processing /opt/airflow/dags/telemetry_processing_dag.py took 1.895 seconds
[2025-10-05T00:19:38.061+0000] {processor.py:186} INFO - Started process (PID=2095) to work on /opt/airflow/dags/telemetry_processing_dag.py
[2025-10-05T00:19:38.063+0000] {processor.py:914} INFO - Processing file /opt/airflow/dags/telemetry_processing_dag.py for tasks to queue
[2025-10-05T00:19:38.066+0000] {logging_mixin.py:190} INFO - [2025-10-05T00:19:38.065+0000] {dagbag.py:588} INFO - Filling up the DagBag from /opt/airflow/dags/telemetry_processing_dag.py
[2025-10-05T00:19:39.216+0000] {logging_mixin.py:190} INFO - [2025-10-05T00:19:39.194+0000] {dagbag.py:387} ERROR - Failed to import: /opt/airflow/dags/telemetry_processing_dag.py
Traceback (most recent call last):
  File "/home/airflow/.local/lib/python3.12/site-packages/airflow/models/dagbag.py", line 383, in parse
    loader.exec_module(new_module)
  File "<frozen importlib._bootstrap_external>", line 999, in exec_module
  File "<frozen importlib._bootstrap>", line 488, in _call_with_frames_removed
  File "/opt/airflow/dags/telemetry_processing_dag.py", line 10, in <module>
    from tasks.load import IcebergStorage
  File "/opt/airflow/dags/tasks/load.py", line 7, in <module>
    from dags.tasks.config.settings import ICEBERG_STORAGE, BYTES_SIZE, TARGET_FILE_SIZE_MB
ImportError: cannot import name 'ICEBERG_STORAGE' from 'dags.tasks.config.settings' (/opt/airflow/dags/tasks/config/settings.py)
[2025-10-05T00:19:39.223+0000] {processor.py:927} WARNING - No viable dags retrieved from /opt/airflow/dags/telemetry_processing_dag.py
[2025-10-05T00:19:39.283+0000] {processor.py:208} INFO - Processing /opt/airflow/dags/telemetry_processing_dag.py took 1.240 seconds
[2025-10-05T00:20:09.685+0000] {processor.py:186} INFO - Started process (PID=2122) to work on /opt/airflow/dags/telemetry_processing_dag.py
[2025-10-05T00:20:09.687+0000] {processor.py:914} INFO - Processing file /opt/airflow/dags/telemetry_processing_dag.py for tasks to queue
[2025-10-05T00:20:09.690+0000] {logging_mixin.py:190} INFO - [2025-10-05T00:20:09.689+0000] {dagbag.py:588} INFO - Filling up the DagBag from /opt/airflow/dags/telemetry_processing_dag.py
[2025-10-05T00:20:10.607+0000] {logging_mixin.py:190} INFO - [2025-10-05T00:20:10.593+0000] {dagbag.py:387} ERROR - Failed to import: /opt/airflow/dags/telemetry_processing_dag.py
Traceback (most recent call last):
  File "/home/airflow/.local/lib/python3.12/site-packages/airflow/models/dagbag.py", line 383, in parse
    loader.exec_module(new_module)
  File "<frozen importlib._bootstrap_external>", line 999, in exec_module
  File "<frozen importlib._bootstrap>", line 488, in _call_with_frames_removed
  File "/opt/airflow/dags/telemetry_processing_dag.py", line 10, in <module>
    from tasks.load import IcebergStorage
  File "/opt/airflow/dags/tasks/load.py", line 7, in <module>
    from dags.tasks.config.settings import ICEBERG_STORAGE, BYTES_SIZE, TARGET_FILE_SIZE_MB
ImportError: cannot import name 'ICEBERG_STORAGE' from 'dags.tasks.config.settings' (/opt/airflow/dags/tasks/config/settings.py)
[2025-10-05T00:20:10.611+0000] {processor.py:927} WARNING - No viable dags retrieved from /opt/airflow/dags/telemetry_processing_dag.py
[2025-10-05T00:20:10.668+0000] {processor.py:208} INFO - Processing /opt/airflow/dags/telemetry_processing_dag.py took 0.998 seconds
[2025-10-05T00:20:41.136+0000] {processor.py:186} INFO - Started process (PID=2149) to work on /opt/airflow/dags/telemetry_processing_dag.py
[2025-10-05T00:20:41.139+0000] {processor.py:914} INFO - Processing file /opt/airflow/dags/telemetry_processing_dag.py for tasks to queue
[2025-10-05T00:20:41.144+0000] {logging_mixin.py:190} INFO - [2025-10-05T00:20:41.142+0000] {dagbag.py:588} INFO - Filling up the DagBag from /opt/airflow/dags/telemetry_processing_dag.py
[2025-10-05T00:20:43.274+0000] {logging_mixin.py:190} INFO - [2025-10-05T00:20:43.250+0000] {dagbag.py:387} ERROR - Failed to import: /opt/airflow/dags/telemetry_processing_dag.py
Traceback (most recent call last):
  File "/home/airflow/.local/lib/python3.12/site-packages/airflow/models/dagbag.py", line 383, in parse
    loader.exec_module(new_module)
  File "<frozen importlib._bootstrap_external>", line 999, in exec_module
  File "<frozen importlib._bootstrap>", line 488, in _call_with_frames_removed
  File "/opt/airflow/dags/telemetry_processing_dag.py", line 10, in <module>
    from tasks.load import IcebergStorage
  File "/opt/airflow/dags/tasks/load.py", line 7, in <module>
    from dags.tasks.config.settings import ICEBERG_STORAGE, BYTES_SIZE, TARGET_FILE_SIZE_MB
ImportError: cannot import name 'ICEBERG_STORAGE' from 'dags.tasks.config.settings' (/opt/airflow/dags/tasks/config/settings.py)
[2025-10-05T00:20:43.279+0000] {processor.py:927} WARNING - No viable dags retrieved from /opt/airflow/dags/telemetry_processing_dag.py
[2025-10-05T00:20:43.483+0000] {processor.py:208} INFO - Processing /opt/airflow/dags/telemetry_processing_dag.py took 2.366 seconds
[2025-10-05T00:21:14.056+0000] {processor.py:186} INFO - Started process (PID=2176) to work on /opt/airflow/dags/telemetry_processing_dag.py
[2025-10-05T00:21:14.059+0000] {processor.py:914} INFO - Processing file /opt/airflow/dags/telemetry_processing_dag.py for tasks to queue
[2025-10-05T00:21:14.063+0000] {logging_mixin.py:190} INFO - [2025-10-05T00:21:14.062+0000] {dagbag.py:588} INFO - Filling up the DagBag from /opt/airflow/dags/telemetry_processing_dag.py
[2025-10-05T00:21:16.441+0000] {logging_mixin.py:190} INFO - [2025-10-05T00:21:16.420+0000] {dagbag.py:387} ERROR - Failed to import: /opt/airflow/dags/telemetry_processing_dag.py
Traceback (most recent call last):
  File "/home/airflow/.local/lib/python3.12/site-packages/airflow/models/dagbag.py", line 383, in parse
    loader.exec_module(new_module)
  File "<frozen importlib._bootstrap_external>", line 999, in exec_module
  File "<frozen importlib._bootstrap>", line 488, in _call_with_frames_removed
  File "/opt/airflow/dags/telemetry_processing_dag.py", line 10, in <module>
    from tasks.load import IcebergStorage
  File "/opt/airflow/dags/tasks/load.py", line 7, in <module>
    from dags.tasks.config.settings import ICEBERG_STORAGE, BYTES_SIZE, TARGET_FILE_SIZE_MB
ImportError: cannot import name 'ICEBERG_STORAGE' from 'dags.tasks.config.settings' (/opt/airflow/dags/tasks/config/settings.py)
[2025-10-05T00:21:16.451+0000] {processor.py:927} WARNING - No viable dags retrieved from /opt/airflow/dags/telemetry_processing_dag.py
[2025-10-05T00:21:16.527+0000] {processor.py:208} INFO - Processing /opt/airflow/dags/telemetry_processing_dag.py took 2.501 seconds
[2025-10-05T00:21:46.944+0000] {processor.py:186} INFO - Started process (PID=2203) to work on /opt/airflow/dags/telemetry_processing_dag.py
[2025-10-05T00:21:46.947+0000] {processor.py:914} INFO - Processing file /opt/airflow/dags/telemetry_processing_dag.py for tasks to queue
[2025-10-05T00:21:46.952+0000] {logging_mixin.py:190} INFO - [2025-10-05T00:21:46.950+0000] {dagbag.py:588} INFO - Filling up the DagBag from /opt/airflow/dags/telemetry_processing_dag.py
[2025-10-05T00:21:48.227+0000] {logging_mixin.py:190} INFO - [2025-10-05T00:21:48.200+0000] {dagbag.py:387} ERROR - Failed to import: /opt/airflow/dags/telemetry_processing_dag.py
Traceback (most recent call last):
  File "/home/airflow/.local/lib/python3.12/site-packages/airflow/models/dagbag.py", line 383, in parse
    loader.exec_module(new_module)
  File "<frozen importlib._bootstrap_external>", line 999, in exec_module
  File "<frozen importlib._bootstrap>", line 488, in _call_with_frames_removed
  File "/opt/airflow/dags/telemetry_processing_dag.py", line 10, in <module>
    from tasks.load import IcebergStorage
  File "/opt/airflow/dags/tasks/load.py", line 7, in <module>
    from dags.tasks.config.settings import ICEBERG_STORAGE, BYTES_SIZE, TARGET_FILE_SIZE_MB
ImportError: cannot import name 'ICEBERG_STORAGE' from 'dags.tasks.config.settings' (/opt/airflow/dags/tasks/config/settings.py)
[2025-10-05T00:21:48.237+0000] {processor.py:927} WARNING - No viable dags retrieved from /opt/airflow/dags/telemetry_processing_dag.py
[2025-10-05T00:21:48.337+0000] {processor.py:208} INFO - Processing /opt/airflow/dags/telemetry_processing_dag.py took 1.416 seconds
[2025-10-05T00:22:18.566+0000] {processor.py:186} INFO - Started process (PID=2229) to work on /opt/airflow/dags/telemetry_processing_dag.py
[2025-10-05T00:22:18.570+0000] {processor.py:914} INFO - Processing file /opt/airflow/dags/telemetry_processing_dag.py for tasks to queue
[2025-10-05T00:22:18.575+0000] {logging_mixin.py:190} INFO - [2025-10-05T00:22:18.574+0000] {dagbag.py:588} INFO - Filling up the DagBag from /opt/airflow/dags/telemetry_processing_dag.py
[2025-10-05T00:22:20.739+0000] {processor.py:925} INFO - DAG(s) 'core_telemetry_pipeline' retrieved from /opt/airflow/dags/telemetry_processing_dag.py
[2025-10-05T00:22:22.244+0000] {logging_mixin.py:190} INFO - [2025-10-05T00:22:22.237+0000] {dag.py:3239} INFO - Sync 1 DAGs
[2025-10-05T00:22:30.733+0000] {processor.py:208} INFO - Processing /opt/airflow/dags/telemetry_processing_dag.py took 14.139 seconds
[2025-10-05T00:23:02.332+0000] {processor.py:186} INFO - Started process (PID=2261) to work on /opt/airflow/dags/telemetry_processing_dag.py
[2025-10-05T00:23:02.361+0000] {processor.py:914} INFO - Processing file /opt/airflow/dags/telemetry_processing_dag.py for tasks to queue
[2025-10-05T00:23:02.411+0000] {logging_mixin.py:190} INFO - [2025-10-05T00:23:02.383+0000] {dagbag.py:588} INFO - Filling up the DagBag from /opt/airflow/dags/telemetry_processing_dag.py
[2025-10-05T00:26:48.111+0000] {logging_mixin.py:190} INFO - [2025-10-05T00:26:48.104+0000] {timeout.py:68} ERROR - Process timed out, PID: 2261
[2025-10-05T00:26:48.441+0000] {logging_mixin.py:190} INFO - [2025-10-05T00:26:48.115+0000] {dagbag.py:387} ERROR - Failed to import: /opt/airflow/dags/telemetry_processing_dag.py
Traceback (most recent call last):
  File "/home/airflow/.local/lib/python3.12/site-packages/airflow/models/dagbag.py", line 383, in parse
    loader.exec_module(new_module)
  File "<frozen importlib._bootstrap_external>", line 999, in exec_module
  File "<frozen importlib._bootstrap>", line 488, in _call_with_frames_removed
  File "/opt/airflow/dags/telemetry_processing_dag.py", line 7, in <module>
    from tasks.ingest import Ingestion
  File "/opt/airflow/dags/tasks/ingest.py", line 4, in <module>
    import pandas as pd
  File "/home/airflow/.local/lib/python3.12/site-packages/pandas/__init__.py", line 23, in <module>
    from pandas.compat import (
  File "/home/airflow/.local/lib/python3.12/site-packages/pandas/compat/__init__.py", line 27, in <module>
    from pandas.compat.pyarrow import (
  File "/home/airflow/.local/lib/python3.12/site-packages/pandas/compat/pyarrow.py", line 8, in <module>
    import pyarrow as pa
  File "/home/airflow/.local/lib/python3.12/site-packages/pyarrow/__init__.py", line 65, in <module>
    import pyarrow.lib as _lib
  File "<frozen importlib._bootstrap>", line 645, in parent
  File "/home/airflow/.local/lib/python3.12/site-packages/airflow/utils/timeout.py", line 69, in handle_timeout
    raise AirflowTaskTimeout(self.error_message)
airflow.exceptions.AirflowTaskTimeout: DagBag import timeout for /opt/airflow/dags/telemetry_processing_dag.py after 30.0s.
Please take a look at these docs to improve your DAG import time:
* https://airflow.apache.org/docs/apache-airflow/2.10.4/best-practices.html#top-level-python-code
* https://airflow.apache.org/docs/apache-airflow/2.10.4/best-practices.html#reducing-dag-complexity, PID: 2261
[2025-10-05T00:26:48.472+0000] {processor.py:927} WARNING - No viable dags retrieved from /opt/airflow/dags/telemetry_processing_dag.py
[2025-10-05T00:27:19.424+0000] {processor.py:186} INFO - Started process (PID=2274) to work on /opt/airflow/dags/telemetry_processing_dag.py
[2025-10-05T00:27:19.427+0000] {processor.py:914} INFO - Processing file /opt/airflow/dags/telemetry_processing_dag.py for tasks to queue
[2025-10-05T00:27:19.430+0000] {logging_mixin.py:190} INFO - [2025-10-05T00:27:19.430+0000] {dagbag.py:588} INFO - Filling up the DagBag from /opt/airflow/dags/telemetry_processing_dag.py
[2025-10-05T00:27:21.263+0000] {processor.py:925} INFO - DAG(s) 'core_telemetry_pipeline' retrieved from /opt/airflow/dags/telemetry_processing_dag.py
[2025-10-05T00:27:21.784+0000] {logging_mixin.py:190} INFO - [2025-10-05T00:27:21.777+0000] {dag.py:3239} INFO - Sync 1 DAGs
[2025-10-05T00:27:22.171+0000] {processor.py:208} INFO - Processing /opt/airflow/dags/telemetry_processing_dag.py took 4.212 seconds
[2025-10-05T00:27:52.573+0000] {processor.py:186} INFO - Started process (PID=2301) to work on /opt/airflow/dags/telemetry_processing_dag.py
[2025-10-05T00:27:52.576+0000] {processor.py:914} INFO - Processing file /opt/airflow/dags/telemetry_processing_dag.py for tasks to queue
[2025-10-05T00:27:52.580+0000] {logging_mixin.py:190} INFO - [2025-10-05T00:27:52.580+0000] {dagbag.py:588} INFO - Filling up the DagBag from /opt/airflow/dags/telemetry_processing_dag.py
[2025-10-05T00:27:56.492+0000] {processor.py:925} INFO - DAG(s) 'core_telemetry_pipeline' retrieved from /opt/airflow/dags/telemetry_processing_dag.py
[2025-10-05T00:27:57.382+0000] {logging_mixin.py:190} INFO - [2025-10-05T00:27:57.364+0000] {dag.py:3239} INFO - Sync 1 DAGs
[2025-10-05T00:28:05.782+0000] {processor.py:208} INFO - Processing /opt/airflow/dags/telemetry_processing_dag.py took 13.232 seconds
[2025-10-05T00:28:36.715+0000] {processor.py:186} INFO - Started process (PID=2336) to work on /opt/airflow/dags/telemetry_processing_dag.py
[2025-10-05T00:28:36.724+0000] {processor.py:914} INFO - Processing file /opt/airflow/dags/telemetry_processing_dag.py for tasks to queue
[2025-10-05T00:28:36.754+0000] {logging_mixin.py:190} INFO - [2025-10-05T00:28:36.750+0000] {dagbag.py:588} INFO - Filling up the DagBag from /opt/airflow/dags/telemetry_processing_dag.py
[2025-10-05T00:28:42.514+0000] {processor.py:925} INFO - DAG(s) 'core_telemetry_pipeline' retrieved from /opt/airflow/dags/telemetry_processing_dag.py
[2025-10-05T00:28:43.157+0000] {logging_mixin.py:190} INFO - [2025-10-05T00:28:43.138+0000] {dag.py:3239} INFO - Sync 1 DAGs
[2025-10-05T00:28:43.389+0000] {processor.py:208} INFO - Processing /opt/airflow/dags/telemetry_processing_dag.py took 7.144 seconds
[2025-10-05T00:29:14.070+0000] {processor.py:186} INFO - Started process (PID=2363) to work on /opt/airflow/dags/telemetry_processing_dag.py
[2025-10-05T00:29:14.074+0000] {processor.py:914} INFO - Processing file /opt/airflow/dags/telemetry_processing_dag.py for tasks to queue
[2025-10-05T00:29:14.092+0000] {logging_mixin.py:190} INFO - [2025-10-05T00:29:14.078+0000] {dagbag.py:588} INFO - Filling up the DagBag from /opt/airflow/dags/telemetry_processing_dag.py
[2025-10-05T00:29:18.650+0000] {processor.py:925} INFO - DAG(s) 'core_telemetry_pipeline' retrieved from /opt/airflow/dags/telemetry_processing_dag.py
[2025-10-05T00:29:19.523+0000] {logging_mixin.py:190} INFO - [2025-10-05T00:29:19.512+0000] {dag.py:3239} INFO - Sync 1 DAGs
[2025-10-05T00:29:19.833+0000] {processor.py:208} INFO - Processing /opt/airflow/dags/telemetry_processing_dag.py took 6.705 seconds
[2025-10-05T00:29:50.613+0000] {processor.py:186} INFO - Started process (PID=2392) to work on /opt/airflow/dags/telemetry_processing_dag.py
[2025-10-05T00:29:50.622+0000] {processor.py:914} INFO - Processing file /opt/airflow/dags/telemetry_processing_dag.py for tasks to queue
[2025-10-05T00:29:50.634+0000] {logging_mixin.py:190} INFO - [2025-10-05T00:29:50.627+0000] {dagbag.py:588} INFO - Filling up the DagBag from /opt/airflow/dags/telemetry_processing_dag.py
[2025-10-05T00:29:56.500+0000] {processor.py:925} INFO - DAG(s) 'core_telemetry_pipeline' retrieved from /opt/airflow/dags/telemetry_processing_dag.py
[2025-10-05T00:29:57.058+0000] {logging_mixin.py:190} INFO - [2025-10-05T00:29:57.048+0000] {dag.py:3239} INFO - Sync 1 DAGs
[2025-10-05T00:29:58.019+0000] {processor.py:208} INFO - Processing /opt/airflow/dags/telemetry_processing_dag.py took 7.465 seconds
[2025-10-05T00:30:28.798+0000] {processor.py:186} INFO - Started process (PID=2426) to work on /opt/airflow/dags/telemetry_processing_dag.py
[2025-10-05T00:30:28.809+0000] {processor.py:914} INFO - Processing file /opt/airflow/dags/telemetry_processing_dag.py for tasks to queue
[2025-10-05T00:30:28.829+0000] {logging_mixin.py:190} INFO - [2025-10-05T00:30:28.813+0000] {dagbag.py:588} INFO - Filling up the DagBag from /opt/airflow/dags/telemetry_processing_dag.py
[2025-10-05T00:30:32.352+0000] {processor.py:925} INFO - DAG(s) 'core_telemetry_pipeline' retrieved from /opt/airflow/dags/telemetry_processing_dag.py
[2025-10-05T00:30:32.772+0000] {logging_mixin.py:190} INFO - [2025-10-05T00:30:32.763+0000] {dag.py:3239} INFO - Sync 1 DAGs
[2025-10-05T00:30:32.954+0000] {processor.py:208} INFO - Processing /opt/airflow/dags/telemetry_processing_dag.py took 4.212 seconds
[2025-10-05T00:31:03.565+0000] {processor.py:186} INFO - Started process (PID=2453) to work on /opt/airflow/dags/telemetry_processing_dag.py
[2025-10-05T00:31:03.568+0000] {processor.py:914} INFO - Processing file /opt/airflow/dags/telemetry_processing_dag.py for tasks to queue
[2025-10-05T00:31:03.577+0000] {logging_mixin.py:190} INFO - [2025-10-05T00:31:03.572+0000] {dagbag.py:588} INFO - Filling up the DagBag from /opt/airflow/dags/telemetry_processing_dag.py
[2025-10-05T00:31:07.253+0000] {processor.py:925} INFO - DAG(s) 'core_telemetry_pipeline' retrieved from /opt/airflow/dags/telemetry_processing_dag.py
[2025-10-05T00:31:06.664+0000] {logging_mixin.py:190} INFO - [2025-10-05T00:31:06.656+0000] {dag.py:3239} INFO - Sync 1 DAGs
[2025-10-05T00:31:06.806+0000] {processor.py:208} INFO - Processing /opt/airflow/dags/telemetry_processing_dag.py took 4.224 seconds
[2025-10-05T00:31:35.997+0000] {processor.py:186} INFO - Started process (PID=2480) to work on /opt/airflow/dags/telemetry_processing_dag.py
[2025-10-05T00:31:36.002+0000] {processor.py:914} INFO - Processing file /opt/airflow/dags/telemetry_processing_dag.py for tasks to queue
[2025-10-05T00:31:36.014+0000] {logging_mixin.py:190} INFO - [2025-10-05T00:31:36.007+0000] {dagbag.py:588} INFO - Filling up the DagBag from /opt/airflow/dags/telemetry_processing_dag.py
[2025-10-05T00:31:41.958+0000] {processor.py:925} INFO - DAG(s) 'core_telemetry_pipeline' retrieved from /opt/airflow/dags/telemetry_processing_dag.py
[2025-10-05T00:31:42.672+0000] {logging_mixin.py:190} INFO - [2025-10-05T00:31:42.657+0000] {dag.py:3239} INFO - Sync 1 DAGs
[2025-10-05T00:31:42.863+0000] {processor.py:208} INFO - Processing /opt/airflow/dags/telemetry_processing_dag.py took 6.931 seconds
[2025-10-05T02:49:32.589+0000] {processor.py:186} INFO - Started process (PID=2497) to work on /opt/airflow/dags/telemetry_processing_dag.py
[2025-10-05T02:49:32.602+0000] {processor.py:914} INFO - Processing file /opt/airflow/dags/telemetry_processing_dag.py for tasks to queue
[2025-10-05T02:49:32.709+0000] {logging_mixin.py:190} INFO - [2025-10-05T02:49:32.685+0000] {dagbag.py:588} INFO - Filling up the DagBag from /opt/airflow/dags/telemetry_processing_dag.py
[2025-10-05T02:49:39.798+0000] {processor.py:925} INFO - DAG(s) 'core_telemetry_pipeline' retrieved from /opt/airflow/dags/telemetry_processing_dag.py
[2025-10-05T02:49:40.267+0000] {logging_mixin.py:190} INFO - [2025-10-05T02:49:40.253+0000] {dag.py:3239} INFO - Sync 1 DAGs
[2025-10-05T02:49:52.106+0000] {processor.py:208} INFO - Processing /opt/airflow/dags/telemetry_processing_dag.py took 20.520 seconds
[2025-10-05T02:50:22.835+0000] {processor.py:186} INFO - Started process (PID=2524) to work on /opt/airflow/dags/telemetry_processing_dag.py
[2025-10-05T02:50:22.839+0000] {processor.py:914} INFO - Processing file /opt/airflow/dags/telemetry_processing_dag.py for tasks to queue
[2025-10-05T02:50:22.844+0000] {logging_mixin.py:190} INFO - [2025-10-05T02:50:22.843+0000] {dagbag.py:588} INFO - Filling up the DagBag from /opt/airflow/dags/telemetry_processing_dag.py
[2025-10-05T02:50:27.984+0000] {processor.py:925} INFO - DAG(s) 'core_telemetry_pipeline' retrieved from /opt/airflow/dags/telemetry_processing_dag.py
[2025-10-05T02:51:26.039+0000] {processor.py:211} ERROR - Got an exception! Propagating...
Traceback (most recent call last):
  File "/home/airflow/.local/lib/python3.12/site-packages/sqlalchemy/engine/base.py", line 3371, in _wrap_pool_connect
    return fn()
           ^^^^
  File "/home/airflow/.local/lib/python3.12/site-packages/sqlalchemy/pool/base.py", line 327, in connect
    return _ConnectionFairy._checkout(self)
           ^^^^^^^^^^^^^^^^^^^^^^^^^^^^^^^^
  File "/home/airflow/.local/lib/python3.12/site-packages/sqlalchemy/pool/base.py", line 894, in _checkout
    fairy = _ConnectionRecord.checkout(pool)
            ^^^^^^^^^^^^^^^^^^^^^^^^^^^^^^^^
  File "/home/airflow/.local/lib/python3.12/site-packages/sqlalchemy/pool/base.py", line 493, in checkout
    rec = pool._do_get()
          ^^^^^^^^^^^^^^
  File "/home/airflow/.local/lib/python3.12/site-packages/sqlalchemy/pool/impl.py", line 145, in _do_get
    with util.safe_reraise():
         ^^^^^^^^^^^^^^^^^^^
  File "/home/airflow/.local/lib/python3.12/site-packages/sqlalchemy/util/langhelpers.py", line 70, in __exit__
    compat.raise_(
  File "/home/airflow/.local/lib/python3.12/site-packages/sqlalchemy/util/compat.py", line 211, in raise_
    raise exception
  File "/home/airflow/.local/lib/python3.12/site-packages/sqlalchemy/pool/impl.py", line 143, in _do_get
    return self._create_connection()
           ^^^^^^^^^^^^^^^^^^^^^^^^^
  File "/home/airflow/.local/lib/python3.12/site-packages/sqlalchemy/pool/base.py", line 273, in _create_connection
    return _ConnectionRecord(self)
           ^^^^^^^^^^^^^^^^^^^^^^^
  File "/home/airflow/.local/lib/python3.12/site-packages/sqlalchemy/pool/base.py", line 388, in __init__
    self.__connect()
  File "/home/airflow/.local/lib/python3.12/site-packages/sqlalchemy/pool/base.py", line 690, in __connect
    with util.safe_reraise():
         ^^^^^^^^^^^^^^^^^^^
  File "/home/airflow/.local/lib/python3.12/site-packages/sqlalchemy/util/langhelpers.py", line 70, in __exit__
    compat.raise_(
  File "/home/airflow/.local/lib/python3.12/site-packages/sqlalchemy/util/compat.py", line 211, in raise_
    raise exception
  File "/home/airflow/.local/lib/python3.12/site-packages/sqlalchemy/pool/base.py", line 686, in __connect
    self.dbapi_connection = connection = pool._invoke_creator(self)
                                         ^^^^^^^^^^^^^^^^^^^^^^^^^^
  File "/home/airflow/.local/lib/python3.12/site-packages/sqlalchemy/engine/create.py", line 574, in connect
    return dialect.connect(*cargs, **cparams)
           ^^^^^^^^^^^^^^^^^^^^^^^^^^^^^^^^^^
  File "/home/airflow/.local/lib/python3.12/site-packages/sqlalchemy/engine/default.py", line 598, in connect
    return self.dbapi.connect(*cargs, **cparams)
           ^^^^^^^^^^^^^^^^^^^^^^^^^^^^^^^^^^^^^
  File "/home/airflow/.local/lib/python3.12/site-packages/psycopg2/__init__.py", line 122, in connect
    conn = _connect(dsn, connection_factory=connection_factory, **kwasync)
           ^^^^^^^^^^^^^^^^^^^^^^^^^^^^^^^^^^^^^^^^^^^^^^^^^^^^^^^^^^^^^^^
psycopg2.OperationalError: could not translate host name "postgres" to address: Temporary failure in name resolution


The above exception was the direct cause of the following exception:

Traceback (most recent call last):
  File "/home/airflow/.local/lib/python3.12/site-packages/airflow/dag_processing/processor.py", line 207, in _run_file_processor
    _handle_dag_file_processing()
  File "/home/airflow/.local/lib/python3.12/site-packages/airflow/dag_processing/processor.py", line 188, in _handle_dag_file_processing
    result: tuple[int, int, int] = dag_file_processor.process_file(
                                   ^^^^^^^^^^^^^^^^^^^^^^^^^^^^^^^^
  File "/home/airflow/.local/lib/python3.12/site-packages/airflow/utils/session.py", line 97, in wrapper
    return func(*args, session=session, **kwargs)
           ^^^^^^^^^^^^^^^^^^^^^^^^^^^^^^^^^^^^^^
  File "/home/airflow/.local/lib/python3.12/site-packages/airflow/dag_processing/processor.py", line 942, in process_file
    serialize_errors = DagFileProcessor.save_dag_to_db(
                       ^^^^^^^^^^^^^^^^^^^^^^^^^^^^^^^^
  File "/home/airflow/.local/lib/python3.12/site-packages/airflow/api_internal/internal_api_call.py", line 166, in wrapper
    return func(*args, **kwargs)
           ^^^^^^^^^^^^^^^^^^^^^
  File "/home/airflow/.local/lib/python3.12/site-packages/airflow/utils/session.py", line 97, in wrapper
    return func(*args, session=session, **kwargs)
           ^^^^^^^^^^^^^^^^^^^^^^^^^^^^^^^^^^^^^^
  File "/home/airflow/.local/lib/python3.12/site-packages/airflow/dag_processing/processor.py", line 982, in save_dag_to_db
    import_errors = DagBag._sync_to_db(dags=dags, processor_subdir=dag_directory, session=session)
                    ^^^^^^^^^^^^^^^^^^^^^^^^^^^^^^^^^^^^^^^^^^^^^^^^^^^^^^^^^^^^^^^^^^^^^^^^^^^^^^
  File "/home/airflow/.local/lib/python3.12/site-packages/airflow/utils/session.py", line 94, in wrapper
    return func(*args, **kwargs)
           ^^^^^^^^^^^^^^^^^^^^^
  File "/home/airflow/.local/lib/python3.12/site-packages/airflow/models/dagbag.py", line 708, in _sync_to_db
    for attempt in run_with_db_retries(logger=log):
                   ^^^^^^^^^^^^^^^^^^^^^^^^^^^^^^^
  File "/home/airflow/.local/lib/python3.12/site-packages/tenacity/__init__.py", line 443, in __iter__
    do = self.iter(retry_state=retry_state)
         ^^^^^^^^^^^^^^^^^^^^^^^^^^^^^^^^^^
  File "/home/airflow/.local/lib/python3.12/site-packages/tenacity/__init__.py", line 376, in iter
    result = action(retry_state)
             ^^^^^^^^^^^^^^^^^^^
  File "/home/airflow/.local/lib/python3.12/site-packages/tenacity/__init__.py", line 418, in exc_check
    raise retry_exc.reraise()
          ^^^^^^^^^^^^^^^^^^^
  File "/home/airflow/.local/lib/python3.12/site-packages/tenacity/__init__.py", line 185, in reraise
    raise self.last_attempt.result()
          ^^^^^^^^^^^^^^^^^^^^^^^^^^
  File "/usr/local/lib/python3.12/concurrent/futures/_base.py", line 449, in result
    return self.__get_result()
           ^^^^^^^^^^^^^^^^^^^
  File "/usr/local/lib/python3.12/concurrent/futures/_base.py", line 401, in __get_result
    raise self._exception
  File "/home/airflow/.local/lib/python3.12/site-packages/airflow/models/dagbag.py", line 721, in _sync_to_db
    _serialize_dag_capturing_errors(dag, session, processor_subdir)
  File "/home/airflow/.local/lib/python3.12/site-packages/airflow/models/dagbag.py", line 686, in _serialize_dag_capturing_errors
    dag_was_updated = SerializedDagModel.write_dag(
                      ^^^^^^^^^^^^^^^^^^^^^^^^^^^^^
  File "/home/airflow/.local/lib/python3.12/site-packages/airflow/utils/session.py", line 94, in wrapper
    return func(*args, **kwargs)
           ^^^^^^^^^^^^^^^^^^^^^
  File "/home/airflow/.local/lib/python3.12/site-packages/airflow/models/serialized_dag.py", line 160, in write_dag
    if session.scalar(
       ^^^^^^^^^^^^^^^
  File "/home/airflow/.local/lib/python3.12/site-packages/sqlalchemy/orm/session.py", line 1747, in scalar
    return self.execute(
           ^^^^^^^^^^^^^
  File "/home/airflow/.local/lib/python3.12/site-packages/sqlalchemy/orm/session.py", line 1716, in execute
    conn = self._connection_for_bind(bind)
           ^^^^^^^^^^^^^^^^^^^^^^^^^^^^^^^
  File "/home/airflow/.local/lib/python3.12/site-packages/sqlalchemy/orm/session.py", line 1555, in _connection_for_bind
    return self._transaction._connection_for_bind(
           ^^^^^^^^^^^^^^^^^^^^^^^^^^^^^^^^^^^^^^^
  File "/home/airflow/.local/lib/python3.12/site-packages/sqlalchemy/orm/session.py", line 750, in _connection_for_bind
    conn = bind.connect()
           ^^^^^^^^^^^^^^
  File "/home/airflow/.local/lib/python3.12/site-packages/sqlalchemy/future/engine.py", line 412, in connect
    return super(Engine, self).connect()
           ^^^^^^^^^^^^^^^^^^^^^^^^^^^^^
  File "/home/airflow/.local/lib/python3.12/site-packages/sqlalchemy/engine/base.py", line 3325, in connect
    return self._connection_cls(self, close_with_result=close_with_result)
           ^^^^^^^^^^^^^^^^^^^^^^^^^^^^^^^^^^^^^^^^^^^^^^^^^^^^^^^^^^^^^^^
  File "/home/airflow/.local/lib/python3.12/site-packages/sqlalchemy/engine/base.py", line 96, in __init__
    else engine.raw_connection()
         ^^^^^^^^^^^^^^^^^^^^^^^
  File "/home/airflow/.local/lib/python3.12/site-packages/sqlalchemy/engine/base.py", line 3404, in raw_connection
    return self._wrap_pool_connect(self.pool.connect, _connection)
           ^^^^^^^^^^^^^^^^^^^^^^^^^^^^^^^^^^^^^^^^^^^^^^^^^^^^^^^
  File "/home/airflow/.local/lib/python3.12/site-packages/sqlalchemy/engine/base.py", line 3374, in _wrap_pool_connect
    Connection._handle_dbapi_exception_noconnection(
  File "/home/airflow/.local/lib/python3.12/site-packages/sqlalchemy/engine/base.py", line 2208, in _handle_dbapi_exception_noconnection
    util.raise_(
  File "/home/airflow/.local/lib/python3.12/site-packages/sqlalchemy/util/compat.py", line 211, in raise_
    raise exception
  File "/home/airflow/.local/lib/python3.12/site-packages/sqlalchemy/engine/base.py", line 3371, in _wrap_pool_connect
    return fn()
           ^^^^
  File "/home/airflow/.local/lib/python3.12/site-packages/sqlalchemy/pool/base.py", line 327, in connect
    return _ConnectionFairy._checkout(self)
           ^^^^^^^^^^^^^^^^^^^^^^^^^^^^^^^^
  File "/home/airflow/.local/lib/python3.12/site-packages/sqlalchemy/pool/base.py", line 894, in _checkout
    fairy = _ConnectionRecord.checkout(pool)
            ^^^^^^^^^^^^^^^^^^^^^^^^^^^^^^^^
  File "/home/airflow/.local/lib/python3.12/site-packages/sqlalchemy/pool/base.py", line 493, in checkout
    rec = pool._do_get()
          ^^^^^^^^^^^^^^
  File "/home/airflow/.local/lib/python3.12/site-packages/sqlalchemy/pool/impl.py", line 145, in _do_get
    with util.safe_reraise():
         ^^^^^^^^^^^^^^^^^^^
  File "/home/airflow/.local/lib/python3.12/site-packages/sqlalchemy/util/langhelpers.py", line 70, in __exit__
    compat.raise_(
  File "/home/airflow/.local/lib/python3.12/site-packages/sqlalchemy/util/compat.py", line 211, in raise_
    raise exception
  File "/home/airflow/.local/lib/python3.12/site-packages/sqlalchemy/pool/impl.py", line 143, in _do_get
    return self._create_connection()
           ^^^^^^^^^^^^^^^^^^^^^^^^^
  File "/home/airflow/.local/lib/python3.12/site-packages/sqlalchemy/pool/base.py", line 273, in _create_connection
    return _ConnectionRecord(self)
           ^^^^^^^^^^^^^^^^^^^^^^^
  File "/home/airflow/.local/lib/python3.12/site-packages/sqlalchemy/pool/base.py", line 388, in __init__
    self.__connect()
  File "/home/airflow/.local/lib/python3.12/site-packages/sqlalchemy/pool/base.py", line 690, in __connect
    with util.safe_reraise():
         ^^^^^^^^^^^^^^^^^^^
  File "/home/airflow/.local/lib/python3.12/site-packages/sqlalchemy/util/langhelpers.py", line 70, in __exit__
    compat.raise_(
  File "/home/airflow/.local/lib/python3.12/site-packages/sqlalchemy/util/compat.py", line 211, in raise_
    raise exception
  File "/home/airflow/.local/lib/python3.12/site-packages/sqlalchemy/pool/base.py", line 686, in __connect
    self.dbapi_connection = connection = pool._invoke_creator(self)
                                         ^^^^^^^^^^^^^^^^^^^^^^^^^^
  File "/home/airflow/.local/lib/python3.12/site-packages/sqlalchemy/engine/create.py", line 574, in connect
    return dialect.connect(*cargs, **cparams)
           ^^^^^^^^^^^^^^^^^^^^^^^^^^^^^^^^^^
  File "/home/airflow/.local/lib/python3.12/site-packages/sqlalchemy/engine/default.py", line 598, in connect
    return self.dbapi.connect(*cargs, **cparams)
           ^^^^^^^^^^^^^^^^^^^^^^^^^^^^^^^^^^^^^
  File "/home/airflow/.local/lib/python3.12/site-packages/psycopg2/__init__.py", line 122, in connect
    conn = _connect(dsn, connection_factory=connection_factory, **kwasync)
           ^^^^^^^^^^^^^^^^^^^^^^^^^^^^^^^^^^^^^^^^^^^^^^^^^^^^^^^^^^^^^^^
sqlalchemy.exc.OperationalError: (psycopg2.OperationalError) could not translate host name "postgres" to address: Temporary failure in name resolution

(Background on this error at: https://sqlalche.me/e/14/e3q8)
[2025-10-05T03:01:30.892+0000] {processor.py:186} INFO - Started process (PID=2544) to work on /opt/airflow/dags/telemetry_processing_dag.py
[2025-10-05T03:01:30.901+0000] {processor.py:914} INFO - Processing file /opt/airflow/dags/telemetry_processing_dag.py for tasks to queue
[2025-10-05T03:01:30.910+0000] {logging_mixin.py:190} INFO - [2025-10-05T03:01:30.908+0000] {dagbag.py:588} INFO - Filling up the DagBag from /opt/airflow/dags/telemetry_processing_dag.py
[2025-10-05T03:01:34.588+0000] {processor.py:925} INFO - DAG(s) 'core_telemetry_pipeline' retrieved from /opt/airflow/dags/telemetry_processing_dag.py
[2025-10-05T03:01:40.240+0000] {logging_mixin.py:190} INFO - [2025-10-05T03:01:40.214+0000] {dag.py:3239} INFO - Sync 1 DAGs
[2025-10-05T03:01:40.638+0000] {processor.py:208} INFO - Processing /opt/airflow/dags/telemetry_processing_dag.py took 9.854 seconds
[2025-10-05T03:02:11.397+0000] {processor.py:186} INFO - Started process (PID=2580) to work on /opt/airflow/dags/telemetry_processing_dag.py
[2025-10-05T03:02:11.410+0000] {processor.py:914} INFO - Processing file /opt/airflow/dags/telemetry_processing_dag.py for tasks to queue
[2025-10-05T03:02:11.420+0000] {logging_mixin.py:190} INFO - [2025-10-05T03:02:11.414+0000] {dagbag.py:588} INFO - Filling up the DagBag from /opt/airflow/dags/telemetry_processing_dag.py
[2025-10-05T03:03:02.173+0000] {logging_mixin.py:190} INFO - [2025-10-05T03:02:39.914+0000] {timeout.py:68} ERROR - Process timed out, PID: 2580
[2025-10-05T07:57:46.487+0000] {logging_mixin.py:190} INFO - [2025-10-05T07:52:23.186+0000] {dagbag.py:387} ERROR - Failed to import: /opt/airflow/dags/telemetry_processing_dag.py
Traceback (most recent call last):
  File "/home/airflow/.local/lib/python3.12/site-packages/airflow/models/dagbag.py", line 383, in parse
    loader.exec_module(new_module)
  File "<frozen importlib._bootstrap_external>", line 999, in exec_module
  File "<frozen importlib._bootstrap>", line 488, in _call_with_frames_removed
  File "/opt/airflow/dags/telemetry_processing_dag.py", line 7, in <module>
    from tasks.ingest import Ingestion
  File "/opt/airflow/dags/tasks/ingest.py", line 4, in <module>
    import pandas as pd
  File "/home/airflow/.local/lib/python3.12/site-packages/pandas/__init__.py", line 46, in <module>
    from pandas.core.api import (
  File "/home/airflow/.local/lib/python3.12/site-packages/pandas/core/api.py", line 47, in <module>
    from pandas.core.groupby import (
  File "/home/airflow/.local/lib/python3.12/site-packages/pandas/core/groupby/__init__.py", line 1, in <module>
    from pandas.core.groupby.generic import (
  File "/home/airflow/.local/lib/python3.12/site-packages/pandas/core/groupby/generic.py", line 67, in <module>
    from pandas.core.frame import DataFrame
  File "/home/airflow/.local/lib/python3.12/site-packages/pandas/core/frame.py", line 142, in <module>
    from pandas.core.generic import (
  File "/home/airflow/.local/lib/python3.12/site-packages/pandas/core/generic.py", line 178, in <module>
    from pandas.core.methods.describe import describe_ndframe
  File "/home/airflow/.local/lib/python3.12/site-packages/pandas/core/methods/describe.py", line 41, in <module>
    from pandas.io.formats.format import format_percentiles
  File "/home/airflow/.local/lib/python3.12/site-packages/pandas/io/formats/format.py", line 91, in <module>
    from pandas.io.common import (
  File "/home/airflow/.local/lib/python3.12/site-packages/pandas/io/common.py", line 168, in <module>
    @overload
     ^^^^^^^^
  File "/usr/local/lib/python3.12/typing.py", line 2506, in overload
    def overload(func):
    
  File "/home/airflow/.local/lib/python3.12/site-packages/airflow/utils/timeout.py", line 69, in handle_timeout
    raise AirflowTaskTimeout(self.error_message)
airflow.exceptions.AirflowTaskTimeout: DagBag import timeout for /opt/airflow/dags/telemetry_processing_dag.py after 30.0s.
Please take a look at these docs to improve your DAG import time:
* https://airflow.apache.org/docs/apache-airflow/2.10.4/best-practices.html#top-level-python-code
* https://airflow.apache.org/docs/apache-airflow/2.10.4/best-practices.html#reducing-dag-complexity, PID: 2580
[2025-10-05T07:57:47.528+0000] {processor.py:927} WARNING - No viable dags retrieved from /opt/airflow/dags/telemetry_processing_dag.py
[2025-10-05T07:57:58.010+0000] {processor.py:211} ERROR - Got an exception! Propagating...
Traceback (most recent call last):
  File "/home/airflow/.local/lib/python3.12/site-packages/sqlalchemy/engine/base.py", line 3371, in _wrap_pool_connect
    return fn()
           ^^^^
  File "/home/airflow/.local/lib/python3.12/site-packages/sqlalchemy/pool/base.py", line 327, in connect
    return _ConnectionFairy._checkout(self)
           ^^^^^^^^^^^^^^^^^^^^^^^^^^^^^^^^
  File "/home/airflow/.local/lib/python3.12/site-packages/sqlalchemy/pool/base.py", line 894, in _checkout
    fairy = _ConnectionRecord.checkout(pool)
            ^^^^^^^^^^^^^^^^^^^^^^^^^^^^^^^^
  File "/home/airflow/.local/lib/python3.12/site-packages/sqlalchemy/pool/base.py", line 493, in checkout
    rec = pool._do_get()
          ^^^^^^^^^^^^^^
  File "/home/airflow/.local/lib/python3.12/site-packages/sqlalchemy/pool/impl.py", line 145, in _do_get
    with util.safe_reraise():
         ^^^^^^^^^^^^^^^^^^^
  File "/home/airflow/.local/lib/python3.12/site-packages/sqlalchemy/util/langhelpers.py", line 70, in __exit__
    compat.raise_(
  File "/home/airflow/.local/lib/python3.12/site-packages/sqlalchemy/util/compat.py", line 211, in raise_
    raise exception
  File "/home/airflow/.local/lib/python3.12/site-packages/sqlalchemy/pool/impl.py", line 143, in _do_get
    return self._create_connection()
           ^^^^^^^^^^^^^^^^^^^^^^^^^
  File "/home/airflow/.local/lib/python3.12/site-packages/sqlalchemy/pool/base.py", line 273, in _create_connection
    return _ConnectionRecord(self)
           ^^^^^^^^^^^^^^^^^^^^^^^
  File "/home/airflow/.local/lib/python3.12/site-packages/sqlalchemy/pool/base.py", line 388, in __init__
    self.__connect()
  File "/home/airflow/.local/lib/python3.12/site-packages/sqlalchemy/pool/base.py", line 690, in __connect
    with util.safe_reraise():
         ^^^^^^^^^^^^^^^^^^^
  File "/home/airflow/.local/lib/python3.12/site-packages/sqlalchemy/util/langhelpers.py", line 70, in __exit__
    compat.raise_(
  File "/home/airflow/.local/lib/python3.12/site-packages/sqlalchemy/util/compat.py", line 211, in raise_
    raise exception
  File "/home/airflow/.local/lib/python3.12/site-packages/sqlalchemy/pool/base.py", line 686, in __connect
    self.dbapi_connection = connection = pool._invoke_creator(self)
                                         ^^^^^^^^^^^^^^^^^^^^^^^^^^
  File "/home/airflow/.local/lib/python3.12/site-packages/sqlalchemy/engine/create.py", line 574, in connect
    return dialect.connect(*cargs, **cparams)
           ^^^^^^^^^^^^^^^^^^^^^^^^^^^^^^^^^^
  File "/home/airflow/.local/lib/python3.12/site-packages/sqlalchemy/engine/default.py", line 598, in connect
    return self.dbapi.connect(*cargs, **cparams)
           ^^^^^^^^^^^^^^^^^^^^^^^^^^^^^^^^^^^^^
  File "/home/airflow/.local/lib/python3.12/site-packages/psycopg2/__init__.py", line 122, in connect
    conn = _connect(dsn, connection_factory=connection_factory, **kwasync)
           ^^^^^^^^^^^^^^^^^^^^^^^^^^^^^^^^^^^^^^^^^^^^^^^^^^^^^^^^^^^^^^^
psycopg2.OperationalError: could not translate host name "postgres" to address: Temporary failure in name resolution


The above exception was the direct cause of the following exception:

Traceback (most recent call last):
  File "/home/airflow/.local/lib/python3.12/site-packages/airflow/dag_processing/processor.py", line 207, in _run_file_processor
    _handle_dag_file_processing()
  File "/home/airflow/.local/lib/python3.12/site-packages/airflow/dag_processing/processor.py", line 188, in _handle_dag_file_processing
    result: tuple[int, int, int] = dag_file_processor.process_file(
                                   ^^^^^^^^^^^^^^^^^^^^^^^^^^^^^^^^
  File "/home/airflow/.local/lib/python3.12/site-packages/airflow/utils/session.py", line 97, in wrapper
    return func(*args, session=session, **kwargs)
           ^^^^^^^^^^^^^^^^^^^^^^^^^^^^^^^^^^^^^^
  File "/home/airflow/.local/lib/python3.12/site-packages/airflow/dag_processing/processor.py", line 928, in process_file
    DagFileProcessor.update_import_errors(
  File "/home/airflow/.local/lib/python3.12/site-packages/airflow/api_internal/internal_api_call.py", line 166, in wrapper
    return func(*args, **kwargs)
           ^^^^^^^^^^^^^^^^^^^^^
  File "/home/airflow/.local/lib/python3.12/site-packages/airflow/utils/session.py", line 97, in wrapper
    return func(*args, session=session, **kwargs)
           ^^^^^^^^^^^^^^^^^^^^^^^^^^^^^^^^^^^^^^
  File "/home/airflow/.local/lib/python3.12/site-packages/airflow/dag_processing/processor.py", line 648, in update_import_errors
    existing_import_error_files = [x.filename for x in session.query(ParseImportError.filename).all()]
                                                       ^^^^^^^^^^^^^^^^^^^^^^^^^^^^^^^^^^^^^^^^^^^^^^
  File "/home/airflow/.local/lib/python3.12/site-packages/sqlalchemy/orm/query.py", line 2773, in all
    return self._iter().all()
           ^^^^^^^^^^^^
  File "/home/airflow/.local/lib/python3.12/site-packages/sqlalchemy/orm/query.py", line 2916, in _iter
    result = self.session.execute(
             ^^^^^^^^^^^^^^^^^^^^^
  File "/home/airflow/.local/lib/python3.12/site-packages/sqlalchemy/orm/session.py", line 1716, in execute
    conn = self._connection_for_bind(bind)
           ^^^^^^^^^^^^^^^^^^^^^^^^^^^^^^^
  File "/home/airflow/.local/lib/python3.12/site-packages/sqlalchemy/orm/session.py", line 1555, in _connection_for_bind
    return self._transaction._connection_for_bind(
           ^^^^^^^^^^^^^^^^^^^^^^^^^^^^^^^^^^^^^^^
  File "/home/airflow/.local/lib/python3.12/site-packages/sqlalchemy/orm/session.py", line 750, in _connection_for_bind
    conn = bind.connect()
           ^^^^^^^^^^^^^^
  File "/home/airflow/.local/lib/python3.12/site-packages/sqlalchemy/future/engine.py", line 412, in connect
    return super(Engine, self).connect()
           ^^^^^^^^^^^^^^^^^^^^^^^^^^^^^
  File "/home/airflow/.local/lib/python3.12/site-packages/sqlalchemy/engine/base.py", line 3325, in connect
    return self._connection_cls(self, close_with_result=close_with_result)
           ^^^^^^^^^^^^^^^^^^^^^^^^^^^^^^^^^^^^^^^^^^^^^^^^^^^^^^^^^^^^^^^
  File "/home/airflow/.local/lib/python3.12/site-packages/sqlalchemy/engine/base.py", line 96, in __init__
    else engine.raw_connection()
         ^^^^^^^^^^^^^^^^^^^^^^^
  File "/home/airflow/.local/lib/python3.12/site-packages/sqlalchemy/engine/base.py", line 3404, in raw_connection
    return self._wrap_pool_connect(self.pool.connect, _connection)
           ^^^^^^^^^^^^^^^^^^^^^^^^^^^^^^^^^^^^^^^^^^^^^^^^^^^^^^^
  File "/home/airflow/.local/lib/python3.12/site-packages/sqlalchemy/engine/base.py", line 3374, in _wrap_pool_connect
    Connection._handle_dbapi_exception_noconnection(
  File "/home/airflow/.local/lib/python3.12/site-packages/sqlalchemy/engine/base.py", line 2208, in _handle_dbapi_exception_noconnection
    util.raise_(
  File "/home/airflow/.local/lib/python3.12/site-packages/sqlalchemy/util/compat.py", line 211, in raise_
    raise exception
  File "/home/airflow/.local/lib/python3.12/site-packages/sqlalchemy/engine/base.py", line 3371, in _wrap_pool_connect
    return fn()
           ^^^^
  File "/home/airflow/.local/lib/python3.12/site-packages/sqlalchemy/pool/base.py", line 327, in connect
    return _ConnectionFairy._checkout(self)
           ^^^^^^^^^^^^^^^^^^^^^^^^^^^^^^^^
  File "/home/airflow/.local/lib/python3.12/site-packages/sqlalchemy/pool/base.py", line 894, in _checkout
    fairy = _ConnectionRecord.checkout(pool)
            ^^^^^^^^^^^^^^^^^^^^^^^^^^^^^^^^
  File "/home/airflow/.local/lib/python3.12/site-packages/sqlalchemy/pool/base.py", line 493, in checkout
    rec = pool._do_get()
          ^^^^^^^^^^^^^^
  File "/home/airflow/.local/lib/python3.12/site-packages/sqlalchemy/pool/impl.py", line 145, in _do_get
    with util.safe_reraise():
         ^^^^^^^^^^^^^^^^^^^
  File "/home/airflow/.local/lib/python3.12/site-packages/sqlalchemy/util/langhelpers.py", line 70, in __exit__
    compat.raise_(
  File "/home/airflow/.local/lib/python3.12/site-packages/sqlalchemy/util/compat.py", line 211, in raise_
    raise exception
  File "/home/airflow/.local/lib/python3.12/site-packages/sqlalchemy/pool/impl.py", line 143, in _do_get
    return self._create_connection()
           ^^^^^^^^^^^^^^^^^^^^^^^^^
  File "/home/airflow/.local/lib/python3.12/site-packages/sqlalchemy/pool/base.py", line 273, in _create_connection
    return _ConnectionRecord(self)
           ^^^^^^^^^^^^^^^^^^^^^^^
  File "/home/airflow/.local/lib/python3.12/site-packages/sqlalchemy/pool/base.py", line 388, in __init__
    self.__connect()
  File "/home/airflow/.local/lib/python3.12/site-packages/sqlalchemy/pool/base.py", line 690, in __connect
    with util.safe_reraise():
         ^^^^^^^^^^^^^^^^^^^
  File "/home/airflow/.local/lib/python3.12/site-packages/sqlalchemy/util/langhelpers.py", line 70, in __exit__
    compat.raise_(
  File "/home/airflow/.local/lib/python3.12/site-packages/sqlalchemy/util/compat.py", line 211, in raise_
    raise exception
  File "/home/airflow/.local/lib/python3.12/site-packages/sqlalchemy/pool/base.py", line 686, in __connect
    self.dbapi_connection = connection = pool._invoke_creator(self)
                                         ^^^^^^^^^^^^^^^^^^^^^^^^^^
  File "/home/airflow/.local/lib/python3.12/site-packages/sqlalchemy/engine/create.py", line 574, in connect
    return dialect.connect(*cargs, **cparams)
           ^^^^^^^^^^^^^^^^^^^^^^^^^^^^^^^^^^
  File "/home/airflow/.local/lib/python3.12/site-packages/sqlalchemy/engine/default.py", line 598, in connect
    return self.dbapi.connect(*cargs, **cparams)
           ^^^^^^^^^^^^^^^^^^^^^^^^^^^^^^^^^^^^^
  File "/home/airflow/.local/lib/python3.12/site-packages/psycopg2/__init__.py", line 122, in connect
    conn = _connect(dsn, connection_factory=connection_factory, **kwasync)
           ^^^^^^^^^^^^^^^^^^^^^^^^^^^^^^^^^^^^^^^^^^^^^^^^^^^^^^^^^^^^^^^
sqlalchemy.exc.OperationalError: (psycopg2.OperationalError) could not translate host name "postgres" to address: Temporary failure in name resolution

(Background on this error at: https://sqlalche.me/e/14/e3q8)
